<?xml version="1.0" ?>
<!-- =================================================================================== -->
<!-- |    This document was autogenerated by xacro from wheeled_robin_kinect.urdf.xacro | -->
<!-- |    EDITING THIS FILE BY HAND IS NOT RECOMMENDED                                 | -->
<!-- =================================================================================== -->
<robot name="wheeled_robin" xmlns:xacro="http://ros.org/wiki/xacro">
  <material name="Grey">
    <color rgba="0.7 0.7 0.7 1.0"/>
  </material>
  <link name="base_link">
    <!--<inertial>
	      <mass value="2" />
	      <origin xyz="0 0 0.0" />
	      <inertia ixx="0.01" ixy="0.0" ixz="0.0"
	        iyy="0.01" iyz="0.0" izz="0.5" />
	    </inertial> -->
    <visual>
      <!-- <origin xyz=" 0 0 0.07" rpy="0 0 0" /> -->
      <origin rpy="-1.5707 0 0" xyz=" 0 0 0"/>
      <geometry>
        <mesh filename="package://wheeled_robin_description/meshes/segway.stl"/>
      </geometry>
      <material name="Grey"/>
    </visual>
    <!--<collision>
	      <origin xyz="0.0 0.0 0.0308" rpy="0 0 0" />
	      <geometry>
	        <cylinder length="0.0611632" radius="0.016495"/>
	      </geometry>
	    </collision>-->
  </link>
  <link name="left_wheel_link">
    <!--<inertial>
	      <origin xyz="0 0 0"/>
	      <mass value="0.01" />
	      <inertia ixx="0.001" ixy="0.0" ixz="0.0"
	        iyy="0.001" iyz="0.0" izz="0.001" />
	    </inertial> -->
    <visual>
      <origin rpy="-1.5707 0 0" xyz="0 0 0"/>
      <geometry>
        <mesh filename="package://wheeled_robin_description/meshes/wheel.stl"/>
      </geometry>
      <material name="Grey"/>
    </visual>
    <!--<collision>
	      <origin xyz="0 0 0" rpy="0 1.5707 1.5707" />
	      <geometry>
	        <cylinder radius="0.033" length = "0.023"/>
	      </geometry>
	    </collision> -->
  </link>
  <joint name="left_wheel_joint" type="continuous">
    <!-- <origin xyz="0 0.118 0" rpy="0 0 0"/> -->
    <origin rpy="0 0 0" xyz="0 0.0925 0"/>
    <parent link="base_link"/>
    <child link="left_wheel_link"/>
    <axis xyz="0 1 0"/>
  </joint>
  <link name="right_wheel_link">
    <!--<inertial>
	      <origin xyz="0 0 0"/>
	      <mass value="0.01" />
	      <inertia ixx="0.001" ixy="0.0" ixz="0.0"
	        iyy="0.001" iyz="0.0" izz="0.001" />
	    </inertial> -->
    <visual>
      <origin rpy=" 1.5707 0 0" xyz="0 0 0"/>
      <geometry>
        <mesh filename="package://wheeled_robin_description/meshes/wheel.stl"/>
      </geometry>
      <material name="Grey"/>
    </visual>
    <!--<collision>
	      <origin xyz="0 0 0" rpy="0 1.5707 1.5707" />
	      <geometry>
	        <cylinder radius="0.033" length = "0.023"/>
	      </geometry>
	    </collision> -->
  </link>
  <joint name="right_wheel_joint" type="continuous">
    <origin rpy="0 0 0" xyz="0 -0.0925 0"/>
    <parent link="base_link"/>
    <child link="right_wheel_link"/>
    <axis xyz="0 1 0"/>
  </joint>
  <joint name="camera_joint" type="fixed">
    <origin rpy="0 0 0" xyz="0.045 0 0.54"/>
    <parent link="base_link"/>
    <child link="camera_link"/>
  </joint>
  <link name="laser_link">
    <!--<visual>
	      <geometry>
	        <box size="0 0 0.5" />
	      </geometry>
	      <material name="Green" />
	    </visual>
	    <inertial>
	      <mass value="0.001" />
	      <origin xyz="0 0 0" />
	      <inertia ixx="0.0001" ixy="0.0" ixz="0.0"
	        iyy="0.0001" iyz="0.0"
	        izz="0.0001" />
	    </inertial>-->
  </link>
  <joint name="laser_joint" type="fixed">
    <origin rpy="0 0 0" xyz="0.031 0 0.016"/>
    <parent link="camera_link"/>
    <child link="laser_link"/>
  </joint>
  <link name="camera_link">
    <!-- 	<visual>
     	<origin xyz="0 0 0" rpy="0 0 ${M_PI/2}"/>
     <geometry>
       <mesh filename="package://turtlebot_description/meshes/sensors/kinect.dae"/>
      </geometry> 
    </visual>
	  <collision>
      <origin xyz="0.0 0.0 0.0" rpy="0 0 0"/>
	    <geometry>
	      <box size="0.07271 0.27794 0.073"/>
	    </geometry>
	  </collision> -->
    <inertial>
      <mass value="0.001"/>
      <origin xyz="0 0 0"/>
      <inertia ixx="0.0001" ixy="0.0" ixz="0.0" iyy="0.0001" iyz="0.0" izz="0.0001"/>
    </inertial>
  </link>
  <joint name="camera_rgb_joint" type="fixed">
    <origin rpy="0 0 0" xyz="0.031 -0.0125 0.016"/>
    <parent link="camera_link"/>
    <child link="camera_rgb_frame"/>
  </joint>
  <link name="camera_rgb_frame">
    <inertial>
      <mass value="0.001"/>
      <origin xyz="0 0 0"/>
      <inertia ixx="0.0001" ixy="0.0" ixz="0.0" iyy="0.0001" iyz="0.0" izz="0.0001"/>
    </inertial>
  </link>
  <joint name="camera_rgb_optical_joint" type="fixed">
    <origin rpy="-1.57079632679 0 -1.57079632679" xyz="0 0 0"/>
    <parent link="camera_rgb_frame"/>
    <child link="camera_rgb_optical_frame"/>
  </joint>
  <link name="camera_rgb_optical_frame">
    <inertial>
      <mass value="0.001"/>
      <origin xyz="0 0 0"/>
      <inertia ixx="0.0001" ixy="0.0" ixz="0.0" iyy="0.0001" iyz="0.0" izz="0.0001"/>
    </inertial>
  </link>
  <joint name="camera_depth_joint" type="fixed">
    <origin rpy="0 0 0" xyz="0 0.025 0"/>
    <parent link="camera_rgb_frame"/>
    <child link="camera_depth_frame"/>
  </joint>
  <link name="camera_depth_frame">
    <inertial>
      <mass value="0.001"/>
      <origin xyz="0 0 0"/>
      <inertia ixx="0.0001" ixy="0.0" ixz="0.0" iyy="0.0001" iyz="0.0" izz="0.0001"/>
    </inertial>
  </link>
  <joint name="camera_depth_optical_joint" type="fixed">
    <origin rpy="-1.57079632679 0 -1.57079632679" xyz="0 0 0"/>
    <parent link="camera_depth_frame"/>
    <child link="camera_depth_optical_frame"/>
  </joint>
  <link name="camera_depth_optical_frame">
    <inertial>
      <mass value="0.001"/>
      <origin xyz="0 0 0"/>
      <inertia ixx="0.0001" ixy="0.0" ixz="0.0" iyy="0.0001" iyz="0.0" izz="0.0001"/>
    </inertial>
  </link>
  <!--<sensor_kinect  parent="base_link"/>-->
</robot>
