<?xml version="1.0" ?>
<!-- =================================================================================== -->
<!-- |    This document was autogenerated by xacro from rosie.urdf.xacro               | -->
<!-- |    EDITING THIS FILE BY HAND IS NOT RECOMMENDED                                 | -->
<!-- =================================================================================== -->
<robot name="rosie" xmlns:controller="http://playerstage.sourceforge.net/gazebo/xmlschema/#controller" xmlns:interface="http://playerstage.sourceforge.net/gazebo/xmlschema/#interface" xmlns:sensor="http://playerstage.sourceforge.net/gazebo/xmlschema/#sensor" xmlns:xacro="http://ros.org/wiki/xacro">
  <gazebo>
    <controller:gazebo_ros_controller_manager name="gazebo_controller_manager" plugin="libgazebo_ros_controller_manager.so">
      <alwaysOn>true</alwaysOn>
      <robotParam>robot_description</robotParam>
      <updateRate>1000.0</updateRate>
      <interface:audio name="gazebo_mechanism_control_dummy_iface"/>
    </controller:gazebo_ros_controller_manager>
  </gazebo>
  <material name="DarkGrey">
    <color rgba="0.3 0.3 0.3 1.0"/>
  </material>
  <material name="Black">
    <color rgba="0 0 0 1.0"/>
  </material>
  <material name="Orange">
    <color rgba="1.0 0.487 0 1.0"/>
  </material>
  <material name="Silver">
    <color rgba="1.0 1.0 1.0 1.0"/>
  </material>
  <material name="Grey">
    <color rgba="0.7 0.7 0.7 1.0"/>
  </material>
  <material name="Blue">
    <color rgba="0.0 0.0 0.8 1.0"/>
  </material>
  <material name="HandGray">
    <color rgba="0.953 0.996 0.694 1.0"/>
  </material>
  <material name="SickBlue">
    <color rgba="0.3058 0.5921 0.7294 1.0"/>
  </material>
  <link name="base_link">
    <inertial>
      <mass value="200.0"/>
      <origin rpy="0 0 0" xyz="0 0 0.15"/>
      <!-- The inertia matrix of the base is wrong. The specification is with
             respect to the origin of the base. It's currently not worth it for me
             to do some exact calculations -->
      <inertia ixx="0.976666666667" ixy="0" ixz="0" iyy="6.60166666667" iyz="0" izz="6.375"/>
    </inertial>
    <visual>
      <origin rpy="0 0 0" xyz="0 0 0.385"/>
      <geometry>
        <mesh filename="package://rosie_description/meshes/other/base.stl"/>
      </geometry>
      <material name="DarkGrey"/>
    </visual>
    <collision>
      <origin rpy="0 0 0" xyz="0 0 0.385"/>
      <geometry>
        <box size="0.76 0.60 0.60"/>
      </geometry>
    </collision>
  </link>
  <gazebo reference="base_link">
    <material value="kimp.material"/>
  </gazebo>
  <joint name="left_front_wheel_joint" type="fixed">
    <origin rpy="0 0 0" xyz="0.38 0.145 0.125"/>
    <parent link="base_link"/>
    <child link="base_left_front_wheel_link"/>
  </joint>
  <link name="base_left_front_wheel_link">
    <inertial>
      <mass value="3.0"/>
      <origin rpy="0 0 0" xyz="0 -0.065 0"/>
      <inertia ixx="0.01594375" ixy="0" ixz="0" iyy="0.0234375" iyz="0" izz="0.01594375"/>
    </inertial>
    <visual>
      <origin rpy="-1.57079632679 0 0" xyz="0 0.065 0"/>
      <geometry>
        <cylinder length="0.13" radius="0.125"/>
      </geometry>
      <material name="Black"/>
    </visual>
    <collision>
      <origin rpy="-1.57079632679 0 0" xyz="0 0.065 0"/>
      <geometry>
        <cylinder length="0.13" radius="0.12375"/>
      </geometry>
    </collision>
  </link>
  <gazebo reference="base_left_front_wheel_link">
    <material value="Gazebo/Black"/>
    <mu1 value="0.0"/>
    <mu2 value="0.0"/>
  </gazebo>
  <joint name="right_front_wheel_joint" type="fixed">
    <origin rpy="0 0 0" xyz="0.38 -0.145 0.125"/>
    <parent link="base_link"/>
    <child link="base_right_front_wheel_link"/>
  </joint>
  <link name="base_right_front_wheel_link">
    <inertial>
      <mass value="3.0"/>
      <origin rpy="0 0 0" xyz="0 0.065 0"/>
      <inertia ixx="0.01594375" ixy="0" ixz="0" iyy="0.0234375" iyz="0" izz="0.01594375"/>
    </inertial>
    <visual>
      <origin rpy="1.57079632679 0 0" xyz="0 -0.065 0"/>
      <geometry>
        <cylinder length="0.13" radius="0.125"/>
      </geometry>
      <material name="Black"/>
    </visual>
    <collision>
      <origin rpy="1.57079632679 0 0" xyz="0 -0.065 0"/>
      <geometry>
        <cylinder length="0.13" radius="0.12375"/>
      </geometry>
    </collision>
  </link>
  <gazebo reference="base_right_front_wheel_link">
    <material value="Gazebo/Black"/>
    <mu1 value="0.0"/>
    <mu2 value="0.0"/>
  </gazebo>
  <joint name="left_back_wheel_joint" type="fixed">
    <origin rpy="0 0 0" xyz="-0.38 0.145 0.125"/>
    <parent link="base_link"/>
    <child link="base_left_back_wheel_link"/>
  </joint>
  <link name="base_left_back_wheel_link">
    <inertial>
      <mass value="3.0"/>
      <origin rpy="0 0 0" xyz="0 -0.065 0"/>
      <inertia ixx="0.01594375" ixy="0" ixz="0" iyy="0.0234375" iyz="0" izz="0.01594375"/>
    </inertial>
    <visual>
      <origin rpy="-1.57079632679 0 0" xyz="0 0.065 0"/>
      <geometry>
        <cylinder length="0.13" radius="0.125"/>
      </geometry>
      <material name="Black"/>
    </visual>
    <collision>
      <origin rpy="-1.57079632679 0 0" xyz="0 0.065 0"/>
      <geometry>
        <cylinder length="0.13" radius="0.12375"/>
      </geometry>
    </collision>
  </link>
  <gazebo reference="base_left_back_wheel_link">
    <material value="Gazebo/Black"/>
    <mu1 value="0.0"/>
    <mu2 value="0.0"/>
  </gazebo>
  <joint name="right_back_wheel_joint" type="fixed">
    <origin rpy="0 0 0" xyz="-0.38 -0.145 0.125"/>
    <parent link="base_link"/>
    <child link="base_right_back_wheel_link"/>
  </joint>
  <link name="base_right_back_wheel_link">
    <inertial>
      <mass value="3.0"/>
      <origin rpy="0 0 0" xyz="0 0.065 0"/>
      <inertia ixx="0.01594375" ixy="0" ixz="0" iyy="0.0234375" iyz="0" izz="0.01594375"/>
    </inertial>
    <visual>
      <origin rpy="1.57079632679 0 0" xyz="0 -0.065 0"/>
      <geometry>
        <cylinder length="0.13" radius="0.125"/>
      </geometry>
      <material name="Black"/>
    </visual>
    <collision>
      <origin rpy="1.57079632679 0 0" xyz="0 -0.065 0"/>
      <geometry>
        <cylinder length="0.13" radius="0.12375"/>
      </geometry>
    </collision>
  </link>
  <gazebo reference="base_right_back_wheel_link">
    <material value="Gazebo/Black"/>
    <mu1 value="0.0"/>
    <mu2 value="0.0"/>
  </gazebo>
  <link name="gs_cam">
    </link>
  <joint name="gs_cam_joint" type="fixed">
    <parent link="base_link"/>
    <child link="gs_cam"/>
    <origin rpy="-1.57 0 -1.57" xyz="0.55 0.0 1.17"/>
  </joint>
  <joint name="laser_front_left_fixed_joint" type="fixed">
    <origin rpy="0.0 0.0 0.765" xyz="0.412 0.306 0.53"/>
    <parent link="base_link"/>
    <child link="laser_front_left"/>
  </joint>
  <link name="laser_front_left">
    <inertial>
      <origin rpy="0 0 0" xyz="0 0 0"/>
      <mass value="0.001"/>
      <inertia ixx="1.66666666667e-10" ixy="0" ixz="0" iyy="1.66666666667e-10" iyz="0" izz="1.66666666667e-10"/>
    </inertial>
    <visual>
      <geometry>
        <box size="0.001 0.001 0.001"/>
      </geometry>
    </visual>
    <collision>
      <geometry>
        <box size="0.001 0.001 0.001"/>
      </geometry>
    </collision>
  </link>
  <gazebo reference="laser_front_left">
    <sensor:ray name="laser_front_left">
      <rayCount>682</rayCount>
      <rangeCount>682</rangeCount>
      <laserCount>1</laserCount>
      <origin>0.0 0.0 0.0</origin>
      <displayRays>off</displayRays>
      <minAngle>-120</minAngle>
      <maxAngle>120</maxAngle>
      <minRange>0.02</minRange>
      <maxRange>5.60</maxRange>
      <resRange>0.01</resRange>
      <updateRate>20.0</updateRate>
      <controller:gazebo_ros_laser name="laser_front_left_controller" plugin="libgazebo_ros_laser.so">
        <gaussianNoise>0.005</gaussianNoise>
        <alwaysOn>true</alwaysOn>
        <updateRate>20.0</updateRate>
        <topicName>laser/laser_front_left</topicName>
        <frameName>laser_front_left</frameName>
        <interface:laser name="laser_front_left_iface"/>
      </controller:gazebo_ros_laser>
    </sensor:ray>
  </gazebo>
  <joint name="laser_rear_right_fixed_joint" type="fixed">
    <origin rpy="0.0 0.0 -2.358" xyz="-0.422 -0.3 0.53"/>
    <parent link="base_link"/>
    <child link="laser_rear_right"/>
  </joint>
  <link name="laser_rear_right">
    <inertial>
      <origin rpy="0 0 0" xyz="0 0 0"/>
      <mass value="0.001"/>
      <inertia ixx="1.66666666667e-10" ixy="0" ixz="0" iyy="1.66666666667e-10" iyz="0" izz="1.66666666667e-10"/>
    </inertial>
    <visual>
      <geometry>
        <box size="0.001 0.001 0.001"/>
      </geometry>
    </visual>
    <collision>
      <geometry>
        <box size="0.001 0.001 0.001"/>
      </geometry>
    </collision>
  </link>
  <gazebo reference="laser_rear_right">
    <sensor:ray name="laser_rear_right">
      <rayCount>682</rayCount>
      <rangeCount>682</rangeCount>
      <laserCount>1</laserCount>
      <origin>0.0 0.0 0.0</origin>
      <displayRays>off</displayRays>
      <minAngle>-120</minAngle>
      <maxAngle>120</maxAngle>
      <minRange>0.02</minRange>
      <maxRange>5.60</maxRange>
      <resRange>0.01</resRange>
      <updateRate>20.0</updateRate>
      <controller:gazebo_ros_laser name="laser_rear_right_controller" plugin="libgazebo_ros_laser.so">
        <gaussianNoise>0.005</gaussianNoise>
        <alwaysOn>true</alwaysOn>
        <updateRate>20.0</updateRate>
        <topicName>laser/laser_rear_right</topicName>
        <frameName>laser_rear_right</frameName>
        <interface:laser name="laser_rear_right_iface"/>
      </controller:gazebo_ros_laser>
    </sensor:ray>
  </gazebo>
  <gazebo>
    <controller:gazebo_ros_p3d name="p3d_base_controller" plugin="libgazebo_ros_p3d.so">
      <alwaysOn>true</alwaysOn>
      <updateRate>100.0</updateRate>
      <bodyName>base_link</bodyName>
      <topicName>base_pose_ground_truth</topicName>
      <gaussianNoise>0.01</gaussianNoise>
      <frameName>map</frameName>
      <xyzOffsets>0 0 0</xyzOffsets>
      <!-- initialize odometry for fake localization-->
      <rpyOffsets>0 0 0</rpyOffsets>
      <interface:position name="p3d_base_position"/>
    </controller:gazebo_ros_p3d>
  </gazebo>
  <joint name="base_torso_joint" type="fixed">
    <origin rpy="0 0 0" xyz="0.26 0 1.49"/>
    <parent link="base_link"/>
    <child link="torso_link"/>
  </joint>
  <link name="torso_link">
    <inertial>
      <mass value="5.0"/>
      <origin rpy="0 0 0" xyz="0 0 -0.4025"/>
      <inertia ixx="0.305052083333" ixy="0" ixz="0" iyy="0.135083333333" iyz="0" izz="0.370052083333"/>
    </inertial>
    <visual>
      <origin rpy="0 0 0" xyz="0 0 -0.805"/>
      <geometry>
        <mesh filename="package://rosie_description/meshes/other/torso.stl"/>
      </geometry>
      <material name="Grey"/>
    </visual>
    <collision>
      <origin rpy="0 0 0" xyz="0 0 -0.805"/>
      <geometry>
        <mesh filename="package://rosie_description/meshes/other/convex/torso_convex.stl"/>
      </geometry>
    </collision>
  </link>
  <gazebo reference="torso_link">
    <material value="kimp.material"/>
  </gazebo>
  <joint name="base_link_left_arm_base_joint" type="fixed">
    <origin rpy="0.71372 -0.84806 -2.42787" xyz="0.395 0.059 1.149"/>
    <parent link="base_link"/>
    <child link="calib_left_arm_base_link"/>
  </joint>
  <link name="calib_left_arm_base_link">
    <inertial>
      <mass value="2.0"/>
      <origin rpy="0 0 0" xyz="0 0 0.055"/>
      <inertia ixx="0.00381666666667" ixy="0" ixz="0" iyy="0.0036" iyz="0" izz="0.00381666666667"/>
    </inertial>
    <visual>
      <origin rpy="0 0 0" xyz="0 0 0"/>
      <geometry>
        <mesh filename="package://rosie_description/meshes/arm/arm_base.dae"/>
      </geometry>
      <material name="Orange"/>
    </visual>
    <collision>
      <origin rpy="0 0 0" xyz="0 0 0"/>
      <geometry>
        <mesh filename="package://rosie_description/meshes/arm/convex/arm_base_convex.stl"/>
      </geometry>
    </collision>
  </link>
  <gazebo reference="calib_left_arm_base_link">
    <material value="kuka-lwr.material"/>
  </gazebo>
  <joint name="left_arm_0_joint" type="revolute">
    <origin rpy="0 0 0" xyz="0 0 0.11"/>
    <axis xyz="0 0 1"/>
    <limit effort="204" lower="-2.96705972839" upper="2.96705972839" velocity="1.91986217719"/>
    <safety_controller k_position="100" k_velocity="2" soft_lower_limit="-2.93215314335" soft_upper_limit="2.93215314335"/>
    <dynamics damping="0.1"/>
    <parent link="calib_left_arm_base_link"/>
    <child link="left_arm_1_link"/>
  </joint>
  <link name="left_arm_1_link">
    <inertial>
      <mass value="2.0"/>
      <origin rpy="0 0 0" xyz="0 0 0.130"/>
      <inertia ixx="0.0136666666667" ixy="0" ixz="0" iyy="0.003" iyz="0" izz="0.0118666666667"/>
    </inertial>
    <visual>
      <origin rpy="0 0 3.14159265359" xyz="0 0 0"/>
      <geometry>
        <mesh filename="package://rosie_description/meshes/arm/arm_segment_a.dae"/>
      </geometry>
      <material name="Orange"/>
    </visual>
    <collision>
      <origin rpy="0 0 3.14159265359" xyz="0 0 0"/>
      <geometry>
        <mesh filename="package://rosie_description/meshes/arm/convex/arm_segment_a_convex.stl"/>
      </geometry>
    </collision>
  </link>
  <gazebo reference="left_arm_1_link">
    <material value="kuka-lwr.material"/>
  </gazebo>
  <transmission name="left_arm_0_trans" type="pr2_mechanism_model/SimpleTransmission">
    <actuator name="left_arm_0_motor"/>
    <joint name="left_arm_0_joint"/>
    <mechanicalReduction>1.0</mechanicalReduction>
  </transmission>
  <joint name="left_arm_1_joint" type="revolute">
    <origin rpy="0 0 0" xyz="0 0 0.20"/>
    <axis xyz="0 -1 0"/>
    <limit effort="306" lower="-2.09439510239" upper="2.09439510239" velocity="1.91986217719"/>
    <safety_controller k_position="100" k_velocity="2" soft_lower_limit="-2.05948851735" soft_upper_limit="2.05948851735"/>
    <dynamics damping="0.1"/>
    <parent link="left_arm_1_link"/>
    <child link="left_arm_2_link"/>
  </joint>
  <link name="left_arm_2_link">
    <inertial>
      <mass value="2.0"/>
      <origin rpy="0 0 0" xyz="0 0.06 0.07"/>
      <inertia ixx="0.0136666666667" ixy="0" ixz="0" iyy="0.003" iyz="0" izz="0.0118666666667"/>
    </inertial>
    <visual>
      <origin rpy="3.14159265359 0 3.14159265359" xyz="0 0 0.2"/>
      <geometry>
        <mesh filename="package://rosie_description/meshes/arm/arm_segment_b.dae"/>
      </geometry>
      <material name="Orange"/>
    </visual>
    <collision>
      <origin rpy="3.14159265359 0 3.14159265359" xyz="0 0 0.2"/>
      <geometry>
        <mesh filename="package://rosie_description/meshes/arm/convex/arm_segment_b_convex.stl"/>
      </geometry>
    </collision>
  </link>
  <gazebo reference="left_arm_2_link">
    <material value="kuka-lwr.material"/>
  </gazebo>
  <transmission name="left_arm_1_trans" type="pr2_mechanism_model/SimpleTransmission">
    <actuator name="left_arm_1_motor"/>
    <joint name="left_arm_1_joint"/>
    <mechanicalReduction>1.0</mechanicalReduction>
  </transmission>
  <joint name="left_arm_2_joint" type="revolute">
    <origin rpy="0 0 0" xyz="0 0 0.20"/>
    <axis xyz="0 0 1"/>
    <limit effort="204" lower="-2.96705972839" upper="2.96705972839" velocity="2.26892802759"/>
    <safety_controller k_position="100" k_velocity="2" soft_lower_limit="-2.93215314335" soft_upper_limit="2.93215314335"/>
    <dynamics damping="0.1"/>
    <parent link="left_arm_2_link"/>
    <child link="left_arm_3_link"/>
  </joint>
  <link name="left_arm_3_link">
    <inertial>
      <mass value="2.0"/>
      <origin rpy="0 0 0" xyz="0 0.06 0.130"/>
      <inertia ixx="0.0136666666667" ixy="0" ixz="0" iyy="0.003" iyz="0" izz="0.0118666666667"/>
    </inertial>
    <visual>
      <origin rpy="0 0 0" xyz="0 0 0"/>
      <geometry>
        <mesh filename="package://rosie_description/meshes/arm/arm_segment_a.dae"/>
      </geometry>
      <material name="Orange"/>
    </visual>
    <collision>
      <origin rpy="0 0 0" xyz="0 0 0"/>
      <geometry>
        <mesh filename="package://rosie_description/meshes/arm/convex/arm_segment_a_convex.stl"/>
      </geometry>
    </collision>
  </link>
  <gazebo reference="left_arm_3_link">
    <material value="kuka-lwr.material"/>
  </gazebo>
  <transmission name="left_arm_2_trans" type="pr2_mechanism_model/SimpleTransmission">
    <actuator name="left_arm_2_motor"/>
    <joint name="left_arm_2_joint"/>
    <mechanicalReduction>1.0</mechanicalReduction>
  </transmission>
  <joint name="left_arm_3_joint" type="revolute">
    <origin rpy="0 0 0" xyz="0 0 0.20"/>
    <axis xyz="0 1 0"/>
    <limit effort="306" lower="-2.09439510239" upper="2.09439510239" velocity="2.26892802759"/>
    <safety_controller k_position="100" k_velocity="2" soft_lower_limit="-2.05948851735" soft_upper_limit="2.05948851735"/>
    <dynamics damping="0.1"/>
    <parent link="left_arm_3_link"/>
    <child link="left_arm_4_link"/>
  </joint>
  <link name="left_arm_4_link">
    <inertial>
      <mass value="2.0"/>
      <origin rpy="0 0 0" xyz="0 -0.06 0.07"/>
      <inertia ixx="0.0136666666667" ixy="0" ixz="0" iyy="0.003" iyz="0" izz="0.0118666666667"/>
    </inertial>
    <visual>
      <origin rpy="0 3.14159265359 3.14159265359" xyz="0 0 0.2"/>
      <geometry>
        <mesh filename="package://rosie_description/meshes/arm/arm_segment_b.dae"/>
      </geometry>
      <material name="Orange"/>
    </visual>
    <collision>
      <origin rpy="0 3.14159265359 3.14159265359" xyz="0 0 0.2"/>
      <geometry>
        <mesh filename="package://rosie_description/meshes/arm/convex/arm_segment_b_convex.stl"/>
      </geometry>
    </collision>
  </link>
  <gazebo reference="left_arm_4_link">
    <material value="kuka-lwr.material"/>
  </gazebo>
  <transmission name="left_arm_3_trans" type="pr2_mechanism_model/SimpleTransmission">
    <actuator name="left_arm_3_motor"/>
    <joint name="left_arm_3_joint"/>
    <mechanicalReduction>1.0</mechanicalReduction>
  </transmission>
  <joint name="left_arm_4_joint" type="revolute">
    <origin rpy="0 0 0" xyz="0 0 0.20"/>
    <axis xyz="0 0 1"/>
    <limit effort="204" lower="-2.96705972839" upper="2.96705972839" velocity="2.26892802759"/>
    <safety_controller k_position="100" k_velocity="2" soft_lower_limit="-2.93215314335" soft_upper_limit="2.93215314335"/>
    <dynamics damping="0.1"/>
    <parent link="left_arm_4_link"/>
    <child link="left_arm_5_link"/>
  </joint>
  <link name="left_arm_5_link">
    <inertial>
      <mass value="2.0"/>
      <origin rpy="0 0 0" xyz="0 0 0.124"/>
      <inertia ixx="0.0126506666667" ixy="0" ixz="0" iyy="0.003" iyz="0" izz="0.0108506666667"/>
    </inertial>
    <visual>
      <origin rpy="0 0 3.14159265359" xyz="0 0 0"/>
      <geometry name="left_arm_5_geom">
        <mesh filename="package://rosie_description/meshes/arm/arm_segment_last.dae"/>
      </geometry>
      <material name="Orange"/>
    </visual>
    <collision>
      <origin rpy="0 0 3.14159265359" xyz="0 0 0"/>
      <geometry>
        <mesh filename="package://rosie_description/meshes/arm/convex/arm_segment_last_convex.stl"/>
      </geometry>
    </collision>
  </link>
  <gazebo reference="left_arm_5_link">
    <material value="kuka-lwr.material"/>
  </gazebo>
  <transmission name="left_arm_4_trans" type="pr2_mechanism_model/SimpleTransmission">
    <actuator name="left_arm_4_motor"/>
    <joint name="left_arm_4_joint"/>
    <mechanicalReduction>1.0</mechanicalReduction>
  </transmission>
  <joint name="left_arm_5_joint" type="revolute">
    <origin rpy="0 0 0" xyz="0 0 0.19"/>
    <axis xyz="0 -1 0"/>
    <limit effort="306" lower="-2.09439510239" upper="2.09439510239" velocity="3.14159265359"/>
    <safety_controller k_position="100" k_velocity="2" soft_lower_limit="-2.05948851735" soft_upper_limit="2.05948851735"/>
    <dynamics damping="0.1"/>
    <parent link="left_arm_5_link"/>
    <child link="left_arm_6_link"/>
  </joint>
  <link name="left_arm_6_link">
    <inertial>
      <mass value="2.0"/>
      <origin rpy="0 0 0" xyz="0 0 0.0625"/>
      <inertia ixx="0.00520833333333" ixy="0" ixz="0" iyy="0.00520833333333" iyz="0" izz="0.00520833333333"/>
    </inertial>
    <visual>
      <origin rpy="0 0 3.14159265359" xyz="0 0 0"/>
      <geometry>
        <mesh filename="package://rosie_description/meshes/arm/arm_wrist.dae"/>
      </geometry>
      <material name="Grey"/>
    </visual>
    <collision>
      <origin rpy="0 0 3.14159265359" xyz="0 0 0"/>
      <geometry>
        <mesh filename="package://rosie_description/meshes/arm/convex/arm_wrist_convex.stl"/>
      </geometry>
    </collision>
  </link>
  <gazebo reference="left_arm_6_link">
    <material value="kuka-lwr.material"/>
  </gazebo>
  <transmission name="left_arm_5_trans" type="pr2_mechanism_model/SimpleTransmission">
    <actuator name="left_arm_5_motor"/>
    <joint name="left_arm_5_joint"/>
    <mechanicalReduction>1.0</mechanicalReduction>
  </transmission>
  <joint name="left_arm_6_joint" type="revolute">
    <origin rpy="0 0 0" xyz="0 0 0.078"/>
    <axis xyz="0 0 1"/>
    <limit effort="204" lower="-2.96705972839" upper="2.96705972839" velocity="3.14159265359"/>
    <safety_controller k_position="100" k_velocity="2" soft_lower_limit="-2.93215314335" soft_upper_limit="2.93215314335"/>
    <dynamics damping="0.1"/>
    <parent link="left_arm_6_link"/>
    <child link="left_arm_7_link"/>
  </joint>
  <link name="left_arm_7_link">
    <inertial>
      <mass value="2.0"/>
      <origin xyz="0 0 0"/>
      <inertia ixx="0.333333333333" ixy="0" ixz="0" iyy="0.333333333333" iyz="0" izz="0.333333333333"/>
    </inertial>
    <visual>
      <origin rpy="0 0 3.92699081699" xyz="0 0 0"/>
      <geometry>
        <mesh filename="package://rosie_description/meshes/arm/arm_flanche_angle.dae"/>
      </geometry>
      <material name="Grey"/>
    </visual>
    <collision>
      <origin rpy="0 0 3.92699081699" xyz="0 0 0"/>
      <geometry>
        <mesh filename="package://rosie_description/meshes/arm/convex/arm_flanche_angle_convex.stl"/>
      </geometry>
    </collision>
  </link>
  <gazebo reference="left_arm_7_link">
    <material value="kuka-lwr.material"/>
  </gazebo>
  <transmission name="left_arm_6_trans" type="pr2_mechanism_model/SimpleTransmission">
    <actuator name="left_arm_6_motor"/>
    <joint name="left_arm_6_joint"/>
    <mechanicalReduction>1.0</mechanicalReduction>
  </transmission>
  <joint name="left_arm_hand_fixed_joint" type="fixed">
    <origin rpy="-1.57079632679 0 3.92699081699" xyz="0.075 -0.075 -0.094"/>
    <parent link="left_arm_7_link"/>
    <child link="left_arm_hand_link"/>
  </joint>
  <link name="left_arm_hand_link"/>
  <joint name="base_link_right_arm_base_joint" type="fixed">
    <origin rpy="0.71178 0.85723 -0.71169" xyz="0.385121 -0.0570121 1.15408"/>
    <parent link="base_link"/>
    <child link="calib_right_arm_base_link"/>
  </joint>
  <link name="calib_right_arm_base_link">
    <inertial>
      <mass value="2.0"/>
      <origin rpy="0 0 0" xyz="0 0 0.055"/>
      <inertia ixx="0.00381666666667" ixy="0" ixz="0" iyy="0.0036" iyz="0" izz="0.00381666666667"/>
    </inertial>
    <visual>
      <origin rpy="0 0 0" xyz="0 0 0"/>
      <geometry>
        <mesh filename="package://rosie_description/meshes/arm/arm_base.dae"/>
      </geometry>
      <material name="Orange"/>
    </visual>
    <collision>
      <origin rpy="0 0 0" xyz="0 0 0"/>
      <geometry>
        <mesh filename="package://rosie_description/meshes/arm/convex/arm_base_convex.stl"/>
      </geometry>
    </collision>
  </link>
  <gazebo reference="calib_right_arm_base_link">
    <material value="kuka-lwr.material"/>
  </gazebo>
  <joint name="right_arm_0_joint" type="revolute">
    <origin rpy="0 0 0" xyz="0 0 0.11"/>
    <axis xyz="0 0 1"/>
    <limit effort="204" lower="-2.96705972839" upper="2.96705972839" velocity="1.91986217719"/>
    <safety_controller k_position="100" k_velocity="2" soft_lower_limit="-2.93215314335" soft_upper_limit="2.93215314335"/>
    <dynamics damping="0.1"/>
    <parent link="calib_right_arm_base_link"/>
    <child link="right_arm_1_link"/>
  </joint>
  <link name="right_arm_1_link">
    <inertial>
      <mass value="2.0"/>
      <origin rpy="0 0 0" xyz="0 0 0.130"/>
      <inertia ixx="0.0136666666667" ixy="0" ixz="0" iyy="0.003" iyz="0" izz="0.0118666666667"/>
    </inertial>
    <visual>
      <origin rpy="0 0 3.14159265359" xyz="0 0 0"/>
      <geometry>
        <mesh filename="package://rosie_description/meshes/arm/arm_segment_a.dae"/>
      </geometry>
      <material name="Orange"/>
    </visual>
    <collision>
      <origin rpy="0 0 3.14159265359" xyz="0 0 0"/>
      <geometry>
        <mesh filename="package://rosie_description/meshes/arm/convex/arm_segment_a_convex.stl"/>
      </geometry>
    </collision>
  </link>
  <gazebo reference="right_arm_1_link">
    <material value="kuka-lwr.material"/>
  </gazebo>
  <transmission name="right_arm_0_trans" type="pr2_mechanism_model/SimpleTransmission">
    <actuator name="right_arm_0_motor"/>
    <joint name="right_arm_0_joint"/>
    <mechanicalReduction>1.0</mechanicalReduction>
  </transmission>
  <joint name="right_arm_1_joint" type="revolute">
    <origin rpy="0 0 0" xyz="0 0 0.20"/>
    <axis xyz="0 -1 0"/>
    <limit effort="306" lower="-2.09439510239" upper="2.09439510239" velocity="1.91986217719"/>
    <safety_controller k_position="100" k_velocity="2" soft_lower_limit="-2.05948851735" soft_upper_limit="2.05948851735"/>
    <dynamics damping="0.1"/>
    <parent link="right_arm_1_link"/>
    <child link="right_arm_2_link"/>
  </joint>
  <link name="right_arm_2_link">
    <inertial>
      <mass value="2.0"/>
      <origin rpy="0 0 0" xyz="0 0.06 0.07"/>
      <inertia ixx="0.0136666666667" ixy="0" ixz="0" iyy="0.003" iyz="0" izz="0.0118666666667"/>
    </inertial>
    <visual>
      <origin rpy="3.14159265359 0 3.14159265359" xyz="0 0 0.2"/>
      <geometry>
        <mesh filename="package://rosie_description/meshes/arm/arm_segment_b.dae"/>
      </geometry>
      <material name="Orange"/>
    </visual>
    <collision>
      <origin rpy="3.14159265359 0 3.14159265359" xyz="0 0 0.2"/>
      <geometry>
        <mesh filename="package://rosie_description/meshes/arm/convex/arm_segment_b_convex.stl"/>
      </geometry>
    </collision>
  </link>
  <gazebo reference="right_arm_2_link">
    <material value="kuka-lwr.material"/>
  </gazebo>
  <transmission name="right_arm_1_trans" type="pr2_mechanism_model/SimpleTransmission">
    <actuator name="right_arm_1_motor"/>
    <joint name="right_arm_1_joint"/>
    <mechanicalReduction>1.0</mechanicalReduction>
  </transmission>
  <joint name="right_arm_2_joint" type="revolute">
    <origin rpy="0 0 0" xyz="0 0 0.20"/>
    <axis xyz="0 0 1"/>
    <limit effort="204" lower="-2.96705972839" upper="2.96705972839" velocity="2.26892802759"/>
    <safety_controller k_position="100" k_velocity="2" soft_lower_limit="-2.93215314335" soft_upper_limit="2.93215314335"/>
    <dynamics damping="0.1"/>
    <parent link="right_arm_2_link"/>
    <child link="right_arm_3_link"/>
  </joint>
  <link name="right_arm_3_link">
    <inertial>
      <mass value="2.0"/>
      <origin rpy="0 0 0" xyz="0 0.06 0.130"/>
      <inertia ixx="0.0136666666667" ixy="0" ixz="0" iyy="0.003" iyz="0" izz="0.0118666666667"/>
    </inertial>
    <visual>
      <origin rpy="0 0 0" xyz="0 0 0"/>
      <geometry>
        <mesh filename="package://rosie_description/meshes/arm/arm_segment_a.dae"/>
      </geometry>
      <material name="Orange"/>
    </visual>
    <collision>
      <origin rpy="0 0 0" xyz="0 0 0"/>
      <geometry>
        <mesh filename="package://rosie_description/meshes/arm/convex/arm_segment_a_convex.stl"/>
      </geometry>
    </collision>
  </link>
  <gazebo reference="right_arm_3_link">
    <material value="kuka-lwr.material"/>
  </gazebo>
  <transmission name="right_arm_2_trans" type="pr2_mechanism_model/SimpleTransmission">
    <actuator name="right_arm_2_motor"/>
    <joint name="right_arm_2_joint"/>
    <mechanicalReduction>1.0</mechanicalReduction>
  </transmission>
  <joint name="right_arm_3_joint" type="revolute">
    <origin rpy="0 0 0" xyz="0 0 0.20"/>
    <axis xyz="0 1 0"/>
    <limit effort="306" lower="-2.09439510239" upper="2.09439510239" velocity="2.26892802759"/>
    <safety_controller k_position="100" k_velocity="2" soft_lower_limit="-2.05948851735" soft_upper_limit="2.05948851735"/>
    <dynamics damping="0.1"/>
    <parent link="right_arm_3_link"/>
    <child link="right_arm_4_link"/>
  </joint>
  <link name="right_arm_4_link">
    <inertial>
      <mass value="2.0"/>
      <origin rpy="0 0 0" xyz="0 -0.06 0.07"/>
      <inertia ixx="0.0136666666667" ixy="0" ixz="0" iyy="0.003" iyz="0" izz="0.0118666666667"/>
    </inertial>
    <visual>
      <origin rpy="0 3.14159265359 3.14159265359" xyz="0 0 0.2"/>
      <geometry>
        <mesh filename="package://rosie_description/meshes/arm/arm_segment_b.dae"/>
      </geometry>
      <material name="Orange"/>
    </visual>
    <collision>
      <origin rpy="0 3.14159265359 3.14159265359" xyz="0 0 0.2"/>
      <geometry>
        <mesh filename="package://rosie_description/meshes/arm/convex/arm_segment_b_convex.stl"/>
      </geometry>
    </collision>
  </link>
  <gazebo reference="right_arm_4_link">
    <material value="kuka-lwr.material"/>
  </gazebo>
  <transmission name="right_arm_3_trans" type="pr2_mechanism_model/SimpleTransmission">
    <actuator name="right_arm_3_motor"/>
    <joint name="right_arm_3_joint"/>
    <mechanicalReduction>1.0</mechanicalReduction>
  </transmission>
  <joint name="right_arm_4_joint" type="revolute">
    <origin rpy="0 0 0" xyz="0 0 0.20"/>
    <axis xyz="0 0 1"/>
    <limit effort="204" lower="-2.96705972839" upper="2.96705972839" velocity="2.26892802759"/>
    <safety_controller k_position="100" k_velocity="2" soft_lower_limit="-2.93215314335" soft_upper_limit="2.93215314335"/>
    <dynamics damping="0.1"/>
    <parent link="right_arm_4_link"/>
    <child link="right_arm_5_link"/>
  </joint>
  <link name="right_arm_5_link">
    <inertial>
      <mass value="2.0"/>
      <origin rpy="0 0 0" xyz="0 0 0.124"/>
      <inertia ixx="0.0126506666667" ixy="0" ixz="0" iyy="0.003" iyz="0" izz="0.0108506666667"/>
    </inertial>
    <visual>
      <origin rpy="0 0 3.14159265359" xyz="0 0 0"/>
      <geometry name="right_arm_5_geom">
        <mesh filename="package://rosie_description/meshes/arm/arm_segment_last.dae"/>
      </geometry>
      <material name="Orange"/>
    </visual>
    <collision>
      <origin rpy="0 0 3.14159265359" xyz="0 0 0"/>
      <geometry>
        <mesh filename="package://rosie_description/meshes/arm/convex/arm_segment_last_convex.stl"/>
      </geometry>
    </collision>
  </link>
  <gazebo reference="right_arm_5_link">
    <material value="kuka-lwr.material"/>
  </gazebo>
  <transmission name="right_arm_4_trans" type="pr2_mechanism_model/SimpleTransmission">
    <actuator name="right_arm_4_motor"/>
    <joint name="right_arm_4_joint"/>
    <mechanicalReduction>1.0</mechanicalReduction>
  </transmission>
  <joint name="right_arm_5_joint" type="revolute">
    <origin rpy="0 0 0" xyz="0 0 0.19"/>
    <axis xyz="0 -1 0"/>
    <limit effort="306" lower="-2.09439510239" upper="2.09439510239" velocity="3.14159265359"/>
    <safety_controller k_position="100" k_velocity="2" soft_lower_limit="-2.05948851735" soft_upper_limit="2.05948851735"/>
    <dynamics damping="0.1"/>
    <parent link="right_arm_5_link"/>
    <child link="right_arm_6_link"/>
  </joint>
  <link name="right_arm_6_link">
    <inertial>
      <mass value="2.0"/>
      <origin rpy="0 0 0" xyz="0 0 0.0625"/>
      <inertia ixx="0.00520833333333" ixy="0" ixz="0" iyy="0.00520833333333" iyz="0" izz="0.00520833333333"/>
    </inertial>
    <visual>
      <origin rpy="0 0 3.14159265359" xyz="0 0 0"/>
      <geometry>
        <mesh filename="package://rosie_description/meshes/arm/arm_wrist.dae"/>
      </geometry>
      <material name="Grey"/>
    </visual>
    <collision>
      <origin rpy="0 0 3.14159265359" xyz="0 0 0"/>
      <geometry>
        <mesh filename="package://rosie_description/meshes/arm/convex/arm_wrist_convex.stl"/>
      </geometry>
    </collision>
  </link>
  <gazebo reference="right_arm_6_link">
    <material value="kuka-lwr.material"/>
  </gazebo>
  <transmission name="right_arm_5_trans" type="pr2_mechanism_model/SimpleTransmission">
    <actuator name="right_arm_5_motor"/>
    <joint name="right_arm_5_joint"/>
    <mechanicalReduction>1.0</mechanicalReduction>
  </transmission>
  <joint name="right_arm_6_joint" type="revolute">
    <origin rpy="0 0 0" xyz="0 0 0.078"/>
    <axis xyz="0 0 1"/>
    <limit effort="204" lower="-2.96705972839" upper="2.96705972839" velocity="3.14159265359"/>
    <safety_controller k_position="100" k_velocity="2" soft_lower_limit="-2.93215314335" soft_upper_limit="2.93215314335"/>
    <dynamics damping="0.1"/>
    <parent link="right_arm_6_link"/>
    <child link="right_arm_7_link"/>
  </joint>
  <link name="right_arm_7_link">
    <inertial>
      <mass value="2.0"/>
      <origin xyz="0 0 0"/>
      <inertia ixx="0.333333333333" ixy="0" ixz="0" iyy="0.333333333333" iyz="0" izz="0.333333333333"/>
    </inertial>
    <visual>
      <origin rpy="0 0 2.35619449019" xyz="0 0 0"/>
      <geometry>
        <mesh filename="package://rosie_description/meshes/arm/arm_flanche_angle.dae"/>
      </geometry>
      <material name="Grey"/>
    </visual>
    <collision>
      <origin rpy="0 0 2.35619449019" xyz="0 0 0"/>
      <geometry>
        <mesh filename="package://rosie_description/meshes/arm/convex/arm_flanche_angle_convex.stl"/>
      </geometry>
    </collision>
  </link>
  <gazebo reference="right_arm_7_link">
    <material value="kuka-lwr.material"/>
  </gazebo>
  <transmission name="right_arm_6_trans" type="pr2_mechanism_model/SimpleTransmission">
    <actuator name="right_arm_6_motor"/>
    <joint name="right_arm_6_joint"/>
    <mechanicalReduction>1.0</mechanicalReduction>
  </transmission>
  <joint name="right_arm_hand_fixed_joint" type="fixed">
    <origin rpy="1.57079632679 0 5.49778714378" xyz="-0.075 -0.075 -0.094"/>
    <parent link="right_arm_7_link"/>
    <child link="right_arm_hand_link"/>
  </joint>
  <link name="right_arm_hand_link"/>
  <joint name="ptu_base_joint" type="fixed">
    <origin rpy="0.0 0.0 0.0" xyz="0.405 0.0 1.53"/>
    <parent link="base_link"/>
    <child link="measured_ptu_base"/>
  </joint>
  <link name="measured_ptu_base">
    <inertial>
      <mass value="0.1"/>
      <origin xyz="0 0 0"/>
      <inertia ixx="0.000166666666667" ixy="0" ixz="0" iyy="0.000166666666667" iyz="0" izz="0.000166666666667"/>
    </inertial>
    <visual>
      <origin rpy="0 0 0" xyz="0 0 0"/>
      <geometry>
        <box size="0.001 0.001 0.001"/>
      </geometry>
    </visual>
    <collision>
      <origin rpy="0 0 0" xyz="0 0 0"/>
      <geometry>
        <box size="0.001 0.001 0.001"/>
      </geometry>
    </collision>
  </link>
  <joint name="head_pan_joint" type="revolute">
    <origin rpy="0 0 0" xyz="0 0 0"/>
    <axis xyz="0 0 -1"/>
    <limit effort="206" lower="-1.57" upper="1.57" velocity="234.048652692"/>
    <safety_controller k_position="100" k_velocity="1.5" soft_lower_limit="-1.565" soft_upper_limit="1.565"/>
    <dynamics damping="1.0"/>
    <parent link="measured_ptu_base"/>
    <child link="head_pan_link"/>
  </joint>
  <link name="head_pan_link">
    <inertial>
      <mass value="0.9"/>
      <origin xyz="0 0 0.0755"/>
      <inertia ixx="0.002317575" ixy="0" ixz="0" iyy="0.000975" iyz="0" izz="0.002077575"/>
    </inertial>
    <visual>
      <origin rpy="0 0 0" xyz="0 0 0"/>
      <geometry>
        <mesh filename="package://rosie_description/meshes/other/ptu0.stl"/>
      </geometry>
      <material name="Grey"/>
    </visual>
    <collision>
      <origin rpy="0 0 0" xyz="0 0 0.0755"/>
      <geometry>
        <box size="0.09 0.07 0.151"/>
      </geometry>
    </collision>
  </link>
  <gazebo reference="measured_ptu_base">
    <material value="ptu.material"/>
  </gazebo>
  <transmission name="head_pan_trans" type="pr2_mechanism_model/SimpleTransmission">
    <actuator name="head_pan_motor"/>
    <joint name="head_pan_joint"/>
    <mechanicalReduction>1.0</mechanicalReduction>
  </transmission>
  <joint name="head_tilt_joint" type="revolute">
    <origin rpy="0 0 0" xyz="0 0 0.101"/>
    <axis xyz="0 1 0"/>
    <limit effort="35" lower="-1.3" upper="1.3" velocity="389.557489045"/>
    <safety_controller k_position="100" k_velocity="1.5" soft_lower_limit="-1.295" soft_upper_limit="1.295"/>
    <dynamics damping="1.0"/>
    <parent link="head_pan_link"/>
    <child link="ptu_tilt_center"/>
  </joint>
  <link name="ptu_tilt_center">
    <inertial>
      <mass value="0.9"/>
      <origin xyz="0 0 0.0535"/>
      <inertia ixx="0.001226175" ixy="0" ixz="0" iyy="0.0022875" iyz="0" izz="0.002778675"/>
    </inertial>
    <visual>
      <origin rpy="0 0 0" xyz="0 0 0"/>
      <geometry>
        <mesh filename="package://rosie_description/meshes/other/ptu1.stl"/>
      </geometry>
      <material name="Grey"/>
    </visual>
    <collision>
      <origin rpy="0 0 0" xyz="0 0 0.107"/>
      <geometry>
        <box size="0.070 0.160 0.107"/>
      </geometry>
    </collision>
  </link>
  <gazebo reference="ptu_tilt_center">
    <material value="ptu.material"/>
  </gazebo>
  <transmission name="head_tilt_trans" type="pr2_mechanism_model/SimpleTransmission">
    <actuator name="head_tilt_motor"/>
    <joint name="head_tilt_joint"/>
    <mechanicalReduction>1.0</mechanicalReduction>
  </transmission>
  <joint name="RightEyeCalc_fixed_joint" type="fixed">
    <origin rpy="4.71005 0.00426654 4.71095" xyz="0.0450085 -0.0690627 0.110697"/>
    <parent link="ptu_tilt_center"/>
    <child link="RightEyeCalc"/>
  </joint>
  <link name="RightEyeCalc">
    <inertial>
      <mass value="0.2"/>
      <origin xyz="0 0 0"/>
      <inertia ixx="0.000333333333333" ixy="0" ixz="0" iyy="0.000333333333333" iyz="0" izz="0.000333333333333"/>
    </inertial>
    <visual>
      <origin rpy="0 0 0" xyz="0 0 -0.045"/>
      <geometry>
        <box size="0.05 0.05 0.09"/>
      </geometry>
      <material name="Grey"/>
    </visual>
    <collision>
      <origin rpy="0 0 0" xyz="0 0 0"/>
      <geometry>
        <box size="0.01 0.01 0.01"/>
      </geometry>
    </collision>
  </link>
  <gazebo reference="RightEyeCalc">
    <material value="Gazebo/Red"/>
  </gazebo>
  <joint name="LeftEyeCalc_fixed_joint" type="fixed">
    <origin rpy="0.00104896 6.27783 0.00559089" xyz="-0.125335 -0.000453696 -0.000652368"/>
    <parent link="RightEyeCalc"/>
    <child link="LeftEyeCalc"/>
  </joint>
  <link name="LeftEyeCalc">
    <inertial>
      <mass value="0.2"/>
      <origin xyz="0 0 0"/>
      <inertia ixx="0.000333333333333" ixy="0" ixz="0" iyy="0.000333333333333" iyz="0" izz="0.000333333333333"/>
    </inertial>
    <visual>
      <origin rpy="0 0 0" xyz="0 0 -0.045"/>
      <geometry>
        <box size="0.05 0.05 0.09"/>
      </geometry>
      <material name="Grey"/>
    </visual>
    <collision>
      <origin rpy="0 0 0" xyz="0 0 0"/>
      <geometry>
        <box size="0.01 0.01 0.01"/>
      </geometry>
    </collision>
  </link>
  <gazebo reference="LeftEyeCalc">
    <material value="Gazebo/Red"/>
  </gazebo>
  <joint name="sr4_fixed_joint" type="fixed">
    <origin rpy="0.0208719 6.27334 3.1418" xyz="-0.0619785 0.001762617 -0.0379636"/>
    <parent link="RightEyeCalc"/>
    <child link="sr4"/>
  </joint>
  <link name="sr4">
    <inertial>
      <mass value="0.2"/>
      <origin xyz="0 0 0"/>
      <inertia ixx="0.000333333333333" ixy="0" ixz="0" iyy="0.000333333333333" iyz="0" izz="0.000333333333333"/>
    </inertial>
    <visual>
      <origin rpy="0 0 0" xyz="0 0 -0.045"/>
      <geometry>
        <box size="0.05 0.05 0.09"/>
      </geometry>
      <material name="Grey"/>
    </visual>
    <collision>
      <origin rpy="0 0 0" xyz="0 0 0"/>
      <geometry>
        <box size="0.01 0.01 0.01"/>
      </geometry>
    </collision>
  </link>
  <gazebo reference="sr4">
    <material value="Gazebo/Red"/>
  </gazebo>
  <joint name="openni_camera_fixed_joint" type="fixed">
    <origin rpy="0.0750699 4.78097 1.51834" xyz="-0.125577 -0.158735 -0.0101134"/>
    <parent link="RightEyeCalc"/>
    <child link="openni_camera"/>
  </joint>
  <link name="openni_camera">
    <inertial>
      <mass value="0.2"/>
      <origin xyz="0 0 0"/>
      <inertia ixx="0.000333333333333" ixy="0" ixz="0" iyy="0.000333333333333" iyz="0" izz="0.000333333333333"/>
    </inertial>
    <visual>
      <origin rpy="0 0 0" xyz="0 0 -0.045"/>
      <geometry>
        <box size="0.05 0.05 0.09"/>
      </geometry>
      <material name="Grey"/>
    </visual>
    <collision>
      <origin rpy="0 0 0" xyz="0 0 0"/>
      <geometry>
        <box size="0.01 0.01 0.01"/>
      </geometry>
    </collision>
  </link>
  <gazebo reference="openni_camera">
    <material value="Gazebo/Red"/>
  </gazebo>
  <joint name="RightEyeCalc_sensor_fixed_joint" type="fixed">
    <origin rpy="0 -1.57079632679 1.57079632679" xyz="0 0 0"/>
    <parent link="RightEyeCalc"/>
    <child link="RightEyeCalc_sensor"/>
  </joint>
  <link name="RightEyeCalc_sensor">
    <inertial>
      <origin rpy="0 0 0" xyz="0 0 0"/>
      <mass value="0.001"/>
      <inertia ixx="1.66666666667e-10" ixy="0" ixz="0" iyy="1.66666666667e-10" iyz="0" izz="1.66666666667e-10"/>
    </inertial>
    <visual>
      <geometry>
        <box size="0.001 0.001 0.001"/>
      </geometry>
    </visual>
    <collision>
      <geometry>
        <box size="0.001 0.001 0.001"/>
      </geometry>
    </collision>
  </link>
  <gazebo reference="RightEyeCalc_sensor">
    <sensor:camera name="RightEyeCalc_sensor_sensor">
      <imageSize>400 300</imageSize>
      <imageFormat>R8G8B8</imageFormat>
      <hfov>104</hfov>
      <nearClip>0.1</nearClip>
      <farClip>100</farClip>
      <updateRate>20.0</updateRate>
      <controller:gazebo_ros_camera name="RightEyeCalc_sensor_controller" plugin="libgazebo_ros_camera.so">
        <alwaysOn>true</alwaysOn>
        <updateRate>20.0</updateRate>
        <imageTopicName>cameras/RightEyeCalc_sensor</imageTopicName>
        <cameraInfoTopicName>cameras/RightEyeCalc_sensorInfo</cameraInfoTopicName>
        <frameName>RightEyeCalc_sensor</frameName>
        <interface:camera name="RightEyeCalc_sensor_iface"/>
      </controller:gazebo_ros_camera>
    </sensor:camera>
  </gazebo>
  <joint name="LeftEyeCalc_sensor_fixed_joint" type="fixed">
    <origin rpy="0 -1.57079632679 1.57079632679" xyz="0 0 0"/>
    <parent link="LeftEyeCalc"/>
    <child link="LeftEyeCalc_sensor"/>
  </joint>
  <link name="LeftEyeCalc_sensor">
    <inertial>
      <origin rpy="0 0 0" xyz="0 0 0"/>
      <mass value="0.001"/>
      <inertia ixx="1.66666666667e-10" ixy="0" ixz="0" iyy="1.66666666667e-10" iyz="0" izz="1.66666666667e-10"/>
    </inertial>
    <visual>
      <geometry>
        <box size="0.001 0.001 0.001"/>
      </geometry>
    </visual>
    <collision>
      <geometry>
        <box size="0.001 0.001 0.001"/>
      </geometry>
    </collision>
  </link>
  <gazebo reference="LeftEyeCalc_sensor">
    <sensor:camera name="LeftEyeCalc_sensor_sensor">
      <imageSize>400 300</imageSize>
      <imageFormat>R8G8B8</imageFormat>
      <hfov>104</hfov>
      <nearClip>0.1</nearClip>
      <farClip>100</farClip>
      <updateRate>20.0</updateRate>
      <controller:gazebo_ros_camera name="LeftEyeCalc_sensor_controller" plugin="libgazebo_ros_camera.so">
        <alwaysOn>true</alwaysOn>
        <updateRate>20.0</updateRate>
        <imageTopicName>cameras/LeftEyeCalc_sensor</imageTopicName>
        <cameraInfoTopicName>cameras/LeftEyeCalc_sensorInfo</cameraInfoTopicName>
        <frameName>LeftEyeCalc_sensor</frameName>
        <interface:camera name="LeftEyeCalc_sensor_iface"/>
      </controller:gazebo_ros_camera>
    </sensor:camera>
  </gazebo>
  <joint name="wide_stereo_frame_joint" type="fixed">
    <origin rpy="0 -1.57079632679 -1.57079632679" xyz="-0.07 -0.07 0.0"/>
    <parent link="RightEyeCalc"/>
    <child link="wide_stereo_link"/>
  </joint>
  <link name="wide_stereo_link">
    <inertial>
      <mass value="0.1"/>
      <origin rpy="0 0 0" xyz="0 0 0"/>
      <inertia ixx="0.01" ixy="0" ixz="0" iyy="0.01" iyz="0" izz="0.01"/>
      <!-- this inertia is made up for now. -->
    </inertial>
  </link>
  <joint name="wide_stereo_optical_frame_joint" type="fixed">
    <origin rpy="-1.57079632679 0.0 -1.57079632679" xyz="0 0 0"/>
    <!-- rotate frame from x-forward to z-forward camera coords -->
    <parent link="wide_stereo_link"/>
    <child link="wide_stereo_optical_frame"/>
  </joint>
  <link name="wide_stereo_optical_frame" type="camera"/>
  <joint name="wide_stereo_l_stereo_camera_frame_joint" type="fixed">
    <origin rpy="0 0 0" xyz="0 0 0"/>
    <parent link="wide_stereo_link"/>
    <child link="wide_stereo_l_stereo_camera_frame"/>
  </joint>
  <link name="wide_stereo_l_stereo_camera_frame">
    <inertial>
      <mass value="0.01"/>
      <origin xyz="0 0 0"/>
      <inertia ixx="0.001" ixy="0.0" ixz="0.0" iyy="0.001" iyz="0.0" izz="0.001"/>
    </inertial>
  </link>
  <joint name="wide_stereo_l_stereo_camera_optical_frame_joint" type="fixed">
    <origin rpy="-1.57079632679 0.0 -1.57079632679" xyz="0 0 0"/>
    <parent link="wide_stereo_l_stereo_camera_frame"/>
    <child link="wide_stereo_l_stereo_camera_optical_frame"/>
  </joint>
  <link name="wide_stereo_l_stereo_camera_optical_frame"/>
  <gazebo reference="wide_stereo_l_stereo_camera_frame">
    <sensor name="wide_stereo_l_stereo_camera_sensor" type="camera">
      <always_on>true</always_on>
      <update_rate>25.0</update_rate>
      <camera>
        <horizontal_fov>1.57079632679</horizontal_fov>
        <image>
          <format>BAYER_BGGR8</format>
          <width>640</width>
          <height>480</height>
        </image>
        <clip>
          <near>0.1</near>
          <far>100</far>
        </clip>
      </camera>
      <plugin filename="libgazebo_ros_camera.so" name="wide_stereo_l_stereo_camera_controller">
        <alwaysOn>true</alwaysOn>
        <updateRate>25.0</updateRate>
        <cameraName>wide_stereo/left</cameraName>
        <imageTopicName>image_raw</imageTopicName>
        <cameraInfoTopicName>camera_info</cameraInfoTopicName>
        <frameName>wide_stereo_optical_frame</frameName>
        <hackBaseline>0</hackBaseline>
        <CxPrime>320.5</CxPrime>
        <Cx>320.5</Cx>
        <Cy>240.5</Cy>
        <!-- image_width / (2*tan(hfov_radian /2)) -->
        <!-- 320 for wide and 772.55 for narrow stereo camera -->
        <focalLength>320</focalLength>
        <distortionK1>0.0</distortionK1>
        <distortionK2>0.0</distortionK2>
        <distortionK3>0.0</distortionK3>
        <distortionT1>0.0</distortionT1>
        <distortionT2>0.0</distortionT2>
      </plugin>
    </sensor>
    <turnGravityOff>true</turnGravityOff>
    <material>PR2/Blue</material>
  </gazebo>
  <joint name="wide_stereo_r_stereo_camera_frame_joint" type="fixed">
    <origin rpy="0.0 0.0 0.0" xyz="0.0 -0.09 0.0"/>
    <parent link="wide_stereo_l_stereo_camera_frame"/>
    <child link="wide_stereo_r_stereo_camera_frame"/>
  </joint>
  <link name="wide_stereo_r_stereo_camera_frame">
    <inertial>
      <mass value="0.01"/>
      <origin xyz="0 0 0"/>
      <inertia ixx="0.001" ixy="0.0" ixz="0.0" iyy="0.001" iyz="0.0" izz="0.001"/>
    </inertial>
  </link>
  <joint name="wide_stereo_r_stereo_camera_optical_frame_joint" type="fixed">
    <origin rpy="-1.57079632679 0.0 -1.57079632679" xyz="0 0 0"/>
    <parent link="wide_stereo_r_stereo_camera_frame"/>
    <child link="wide_stereo_r_stereo_camera_optical_frame"/>
  </joint>
  <link name="wide_stereo_r_stereo_camera_optical_frame"/>
  <gazebo reference="wide_stereo_r_stereo_camera_frame">
    <sensor name="wide_stereo_r_stereo_camera_sensor" type="camera">
      <always_on>true</always_on>
      <update_rate>25.0</update_rate>
      <camera>
        <horizontal_fov>1.57079632679</horizontal_fov>
        <image>
          <format>BAYER_BGGR8</format>
          <width>640</width>
          <height>480</height>
        </image>
        <clip>
          <near>0.1</near>
          <far>100</far>
        </clip>
      </camera>
      <plugin filename="libgazebo_ros_camera.so" name="wide_stereo_r_stereo_camera_controller">
        <alwaysOn>true</alwaysOn>
        <updateRate>25.0</updateRate>
        <cameraName>wide_stereo/right</cameraName>
        <imageTopicName>image_raw</imageTopicName>
        <cameraInfoTopicName>camera_info</cameraInfoTopicName>
        <frameName>wide_stereo_optical_frame</frameName>
        <hackBaseline>0.09</hackBaseline>
        <CxPrime>320.5</CxPrime>
        <Cx>320.5</Cx>
        <Cy>240.5</Cy>
        <!-- image_width / (2*tan(hfov_radian /2)) -->
        <!-- 320 for wide and 772.55 for narrow stereo camera -->
        <focalLength>320</focalLength>
        <distortionK1>0.0</distortionK1>
        <distortionK2>0.0</distortionK2>
        <distortionK3>0.0</distortionK3>
        <distortionT1>0.0</distortionT1>
        <distortionT2>0.0</distortionT2>
      </plugin>
    </sensor>
    <turnGravityOff>true</turnGravityOff>
    <material>PR2/Blue</material>
  </gazebo>
  <gazebo reference="wide_stereo_link">
    <material value="PR2/Blue"/>
    <turnGravityOff value="true"/>
  </gazebo>
  <gazebo reference="wide_stereo_optical_frame">
    <material value="Gazebo/White"/>
    <turnGravityOff value="true"/>
  </gazebo>
  <joint name="shoulder_tilt_fixed_joint" type="fixed">
    <origin rpy="0.000707                    -0.007788                    -0.023937" xyz="0.405376                    0.063816                    1.410532"/>
    <parent link="base_link"/>
    <child link="shoulder_tilt_base"/>
  </joint>
  <link name="shoulder_tilt_base">
    <inertial>
      <mass value="0.425"/>
      <inertia ixx="0.000347083333333" ixy="0" ixz="0" iyy="0.000347083333333" iyz="0" izz="0.000347083333333"/>
    </inertial>
    <visual>
      <origin rpy="0 0 0" xyz="0 0 0"/>
      <geometry>
        <box size="0.07 0.07 0.07"/>
      </geometry>
      <material name="Grey"/>
    </visual>
    <collision>
      <origin rpy="0 0 0" xyz="0 0 0"/>
      <geometry>
        <box size="0.07 0.07 0.07"/>
      </geometry>
    </collision>
  </link>
  <gazebo reference="shoulder_tilt_base">
    <material value="cube_light_gray"/>
  </gazebo>
  <joint name="shoulder_tilting_joint" type="revolute">
    <origin rpy="0 0 0" xyz="0 -0.070 0"/>
    <axis xyz="0 -1 0"/>
    <limit effort="206" lower="-1.3" upper="1.3" velocity="234.048652692"/>
    <parent link="shoulder_tilt_base"/>
    <child link="shoulder_tilt_end"/>
  </joint>
  <link name="shoulder_tilt_end">
    <inertial>
      <mass value="0.425"/>
      <inertia ixx="0.000347083333333" ixy="0" ixz="0" iyy="0.000347083333333" iyz="0" izz="0.000347083333333"/>
    </inertial>
    <visual>
      <origin rpy="0 0 0" xyz="0 0 0"/>
      <geometry>
        <box size="0.07 0.07 0.07"/>
      </geometry>
      <material name="Grey"/>
    </visual>
    <collision>
      <origin rpy="0 0 0" xyz="0 0 0"/>
      <geometry>
        <box size="0.07 0.07 0.07"/>
      </geometry>
    </collision>
  </link>
  <gazebo reference="shoulder_tilt_end">
    <material value="cube_light_gray"/>
  </gazebo>
  <transmission name="shoulder_tilt_trans" type="pr2_mechanism_model/SimpleTransmission">
    <actuator name="shoulder_tilt_motor"/>
    <joint name="shoulder_tilting_joint"/>
    <mechanicalReduction>1.0</mechanicalReduction>
  </transmission>
  <joint name="laser_tilt_fixed_joint" type="fixed">
    <origin xyz="0.0803 0 0.024"/>
    <parent link="shoulder_tilt_end"/>
    <child link="shoulder_tilting_laser"/>
  </joint>
  <link name="shoulder_tilting_laser">
    <inertial>
      <mass value="0.2"/>
      <inertia ixx="0.000163333333333" ixy="0" ixz="0" iyy="0.000163333333333" iyz="0" izz="0.000163333333333"/>
    </inertial>
    <visual>
      <origin rpy="0 0 0" xyz="0 0 -0.035"/>
      <geometry>
        <cylinder length="0.06" radius="0.025"/>
      </geometry>
      <material name="Black"/>
    </visual>
    <collision>
      <origin rpy="0 0 0" xyz="0 0 0"/>
      <geometry>
        <cylinder length="0.08" radius="0.025"/>
      </geometry>
    </collision>
  </link>
  <gazebo reference="shoulder_tilting_laser">
    <material value="Gazebo/Black"/>
  </gazebo>
  <joint name="shoulder_tilting_laser_sensor_fixed_joint" type="fixed">
    <origin rpy="0 0 0" xyz="0 0 0"/>
    <parent link="shoulder_tilting_laser"/>
    <child link="shoulder_tilting_laser_sensor"/>
  </joint>
  <link name="shoulder_tilting_laser_sensor">
    <inertial>
      <origin rpy="0 0 0" xyz="0 0 0"/>
      <mass value="0.001"/>
      <inertia ixx="1.66666666667e-10" ixy="0" ixz="0" iyy="1.66666666667e-10" iyz="0" izz="1.66666666667e-10"/>
    </inertial>
    <visual>
      <geometry>
        <box size="0.001 0.001 0.001"/>
      </geometry>
    </visual>
    <collision>
      <geometry>
        <box size="0.001 0.001 0.001"/>
      </geometry>
    </collision>
  </link>
  <gazebo reference="shoulder_tilting_laser_sensor">
    <sensor:ray name="shoulder_tilting_laser_sensor">
      <rayCount>640</rayCount>
      <rangeCount>640</rangeCount>
      <laserCount>1</laserCount>
      <origin>0.0 0.0 0.0</origin>
      <displayRays>off</displayRays>
      <minAngle>-80</minAngle>
      <maxAngle>80</maxAngle>
      <minRange>0.03</minRange>
      <maxRange>60.00</maxRange>
      <resRange>0.01</resRange>
      <updateRate>20.0</updateRate>
      <controller:gazebo_ros_laser name="shoulder_tilting_laser_sensor_controller" plugin="libgazebo_ros_laser.so">
        <gaussianNoise>0.005</gaussianNoise>
        <alwaysOn>true</alwaysOn>
        <updateRate>20.0</updateRate>
        <topicName>laser/shoulder_tilting_laser_sensor</topicName>
        <frameName>shoulder_tilting_laser_sensor</frameName>
        <interface:laser name="shoulder_tilting_laser_sensor_iface"/>
      </controller:gazebo_ros_laser>
    </sensor:ray>
  </gazebo>
  <joint name="right_hand_mount_joint" type="fixed">
    <parent link="right_arm_7_link"/>
    <child link="right_hand_palm"/>
    <origin rpy="1.57079632679 0 5.49778714378" xyz="-0.075 -0.075 -0.094"/>
  </joint>
  <link name="right_hand_palm">
    <inertial>
      <origin rpy="0 0 0" xyz="-0.004 0.002 0.076"/>
      <mass value="0.5"/>
      <inertia ixx="0.00141454166667" ixy="0" ixz="0" iyy="0.000900333333333" iyz="0" izz="0.00175454166667"/>
    </inertial>
    <visual>
      <origin rpy="0 0 0" xyz="0 0 0"/>
      <geometry>
        <mesh filename="package://rosie_description/meshes/hand/right_palm.dae"/>
      </geometry>
      <material name="HandGray"/>
    </visual>
    <collision>
      <origin rpy="0 0 0" xyz="0 0 0"/>
      <geometry>
        <mesh filename="package://rosie_description/meshes/hand/convex/right_palm_convex.stl"/>
      </geometry>
    </collision>
  </link>
  <link name="right_hand_thumb_base">
    <inertial>
      <origin rpy="0 0 0" xyz="-0.003 0.065 0.051"/>
      <mass value="0.1"/>
      <inertia ixx="0.000100208333333" ixy="0" ixz="0" iyy="8.74083333333e-05" iyz="0" izz="0.000153866666667"/>
    </inertial>
    <visual>
      <origin rpy="0 0 0" xyz="0 0 0"/>
      <geometry>
        <mesh filename="package://rosie_description/meshes/hand/right_thumb_base.dae"/>
      </geometry>
      <material name="HandGray"/>
    </visual>
    <collision>
      <origin rpy="0 0 0" xyz="0 0 0"/>
      <geometry>
        <mesh filename="package://rosie_description/meshes/hand/convex/right_thumb_base_convex.stl"/>
      </geometry>
    </collision>
  </link>
  <joint name="right_hand_thumb_joint" type="revolute">
    <parent link="right_hand_palm"/>
    <child link="right_hand_thumb_base"/>
    <origin rpy="0 0 0" xyz="-0.003 0.0271 0"/>
    <axis xyz="0 0 -1"/>
    <limit effort="100" lower="0" upper="1.570796" velocity="100"/>
    <!-- lowStop = 0 highStop = 90 -->
    <dynamics damping="0.005"/>
  </joint>
  <transmission name="right_hand_thumb_trans" type="pr2_mechanism_model/SimpleTransmission">
    <actuator name="right_hand_thumb_motor"/>
    <joint name="right_hand_thumb_joint"/>
    <mechanicalReduction>1.0</mechanicalReduction>
  </transmission>
  <joint name="right_hand_ring_finger_base_joint" type="revolute">
    <parent link="right_hand_palm"/>
    <child link="right_hand_ring_finger_base_link"/>
    <origin rpy="1.570796 -1.536488 1.570796" xyz="-0.0043 -0.040165 0.14543"/>
    <axis xyz="0 0 1"/>
    <limit effort="100" lower="-0.261799388" upper="0.261799388" velocity="100"/>
    <!-- lowStop = -15 , highStop = +15 -->
    <dynamics damping="0.005"/>
  </joint>
  <transmission name="right_hand_ring_finger_base_trans" type="pr2_mechanism_model/SimpleTransmission">
    <actuator name="right_hand_ring_finger_base_motor"/>
    <joint name="right_hand_ring_finger_base_joint"/>
    <mechanicalReduction>1.0</mechanicalReduction>
  </transmission>
  <link name="right_hand_ring_finger_base_link">
    <inertial>
      <origin rpy="0 0 0" xyz="0.004 0 0"/>
      <mass value="0.1"/>
      <inertia ixx="2.24083333333e-05" ixy="0" ixz="0" iyy="1.42833333333e-05" iyz="0" izz="1.85416666667e-05"/>
    </inertial>
    <visual>
      <origin rpy="0 0 0" xyz="0 0 0"/>
      <geometry>
        <mesh filename="package://rosie_description/meshes/hand/finger_base.dae"/>
      </geometry>
      <material name="HandGray"/>
    </visual>
    <collision>
      <origin rpy="0 0 0" xyz="0 0 0"/>
      <geometry>
        <mesh filename="package://rosie_description/meshes/hand/convex/finger_base_convex.stl"/>
      </geometry>
    </collision>
  </link>
  <link name="right_hand_ring_finger_proximal_link">
    <inertial>
      <origin rpy="0 0 0" xyz="0.035 -0.02 0"/>
      <mass value="0.1"/>
      <inertia ixx="6.68333333333e-05" ixy="0" ixz="0" iyy="7.00416666667e-05" iyz="0" izz="2.48083333333e-05"/>
    </inertial>
    <visual>
      <origin rpy="0 0 0" xyz="0 0 0"/>
      <geometry>
        <mesh filename="package://rosie_description/meshes/hand/finger_proximal.dae"/>
      </geometry>
      <material name="HandGray"/>
    </visual>
    <collision>
      <origin rpy="0 0 0" xyz="0 0 0"/>
      <geometry>
        <mesh filename="package://rosie_description/meshes/hand/convex/finger_proximal_convex.stl"/>
      </geometry>
    </collision>
  </link>
  <link name="right_hand_ring_finger_middle_link">
    <inertial>
      <origin rpy="0 0 0" xyz="0.015 -0.01 0"/>
      <mass value="0.1"/>
      <inertia ixx="3.00333333333e-05" ixy="0" ixz="0" iyy="2.90666666667e-05" iyz="0" izz="1.40333333333e-05"/>
    </inertial>
    <visual>
      <origin rpy="0 0 0" xyz="0 0 0"/>
      <geometry>
        <mesh filename="package://rosie_description/meshes/hand/finger_middle.dae"/>
      </geometry>
      <material name="HandGray"/>
    </visual>
    <collision>
      <origin rpy="0 0 0" xyz="0 0 0"/>
      <geometry>
        <mesh filename="package://rosie_description/meshes/hand/convex/finger_middle_convex.stl"/>
      </geometry>
    </collision>
  </link>
  <link name="right_hand_ring_finger_distal_link">
    <inertial>
      <origin rpy="0 0 0" xyz="0 0.014 0"/>
      <mass value="0.1"/>
      <inertia ixx="1.30833333333e-05" ixy="0" ixz="0" iyy="2.78416666667e-05" iyz="0" izz="2.69083333333e-05"/>
    </inertial>
    <visual>
      <origin rpy="0 0 0" xyz="0 0 0"/>
      <geometry>
        <mesh filename="package://rosie_description/meshes/hand/finger_distal.dae"/>
      </geometry>
      <material name="HandGray"/>
    </visual>
    <collision>
      <origin rpy="0 0 0" xyz="0 0 0"/>
      <geometry>
        <mesh filename="package://rosie_description/meshes/hand/convex/finger_distal_convex.stl"/>
      </geometry>
    </collision>
  </link>
  <joint name="right_hand_ring_finger_proximal_joint" type="revolute">
    <parent link="right_hand_ring_finger_base_link"/>
    <child link="right_hand_ring_finger_proximal_link"/>
    <origin rpy="1.570796 0 0" xyz="0 0 0"/>
    <axis xyz="0 0 1"/>
    <limit effort="100" lower="-0.087266463" upper="1.134464014" velocity="100"/>
    <!-- lowStop = -5 highStop = 65 -->
    <dynamics damping="0.005"/>
  </joint>
  <transmission name="right_hand_ring_finger_proximal_trans" type="pr2_mechanism_model/SimpleTransmission">
    <actuator name="right_hand_ring_finger_proximal_motor"/>
    <joint name="right_hand_ring_finger_proximal_joint"/>
    <mechanicalReduction>1.0</mechanicalReduction>
  </transmission>
  <joint name="right_hand_ring_finger_middle_joint" type="revolute">
    <parent link="right_hand_ring_finger_proximal_link"/>
    <child link="right_hand_ring_finger_middle_link"/>
    <origin rpy="0 0 0" xyz="0.0678 0 0"/>
    <axis xyz="0 0 1"/>
    <limit effort="100" lower="0.087266463" upper="1.134464014" velocity="100"/>
    <!-- lowStop = 5 highStop = 65 -->
    <dynamics damping="0.005"/>
  </joint>
  <transmission name="right_hand_ring_finger_middle_trans" type="pr2_mechanism_model/SimpleTransmission">
    <actuator name="right_hand_ring_finger_middle_motor"/>
    <joint name="right_hand_ring_finger_middle_joint"/>
    <mechanicalReduction>1.0</mechanicalReduction>
  </transmission>
  <joint name="right_hand_ring_finger_distal_joint" type="revolute">
    <parent link="right_hand_ring_finger_middle_link"/>
    <child link="right_hand_ring_finger_distal_link"/>
    <origin rpy="0 0 -1.57" xyz="0.030 0 0"/>
    <axis xyz="0 0 1"/>
    <limit effort="100" lower="0.087266463" upper="1.134464014" velocity="100"/>
    <!-- lowStop = 5 highStop = 65 -->
    <dynamics damping="0.005"/>
  </joint>
  <transmission name="right_hand_ring_finger_distal_trans" type="pr2_mechanism_model/SimpleTransmission">
    <actuator name="right_hand_ring_finger_distal_motor"/>
    <joint name="right_hand_ring_finger_distal_joint"/>
    <mechanicalReduction>1.0</mechanicalReduction>
  </transmission>
  <joint name="right_hand_middle_finger_base_joint" type="revolute">
    <parent link="right_hand_palm"/>
    <child link="right_hand_middle_finger_base_link"/>
    <origin rpy="-3.141593 -1.570796 0" xyz="-0.0043 0 0.15015"/>
    <axis xyz="0 0 1"/>
    <limit effort="100" lower="-0.261799388" upper="0.261799388" velocity="100"/>
    <!-- lowStop = -15 , highStop = +15 -->
    <dynamics damping="0.005"/>
  </joint>
  <transmission name="right_hand_middle_finger_base_trans" type="pr2_mechanism_model/SimpleTransmission">
    <actuator name="right_hand_middle_finger_base_motor"/>
    <joint name="right_hand_middle_finger_base_joint"/>
    <mechanicalReduction>1.0</mechanicalReduction>
  </transmission>
  <link name="right_hand_middle_finger_base_link">
    <inertial>
      <origin rpy="0 0 0" xyz="0.004 0 0"/>
      <mass value="0.1"/>
      <inertia ixx="2.24083333333e-05" ixy="0" ixz="0" iyy="1.42833333333e-05" iyz="0" izz="1.85416666667e-05"/>
    </inertial>
    <visual>
      <origin rpy="0 0 0" xyz="0 0 0"/>
      <geometry>
        <mesh filename="package://rosie_description/meshes/hand/finger_base.dae"/>
      </geometry>
      <material name="HandGray"/>
    </visual>
    <collision>
      <origin rpy="0 0 0" xyz="0 0 0"/>
      <geometry>
        <mesh filename="package://rosie_description/meshes/hand/convex/finger_base_convex.stl"/>
      </geometry>
    </collision>
  </link>
  <link name="right_hand_middle_finger_proximal_link">
    <inertial>
      <origin rpy="0 0 0" xyz="0.035 -0.02 0"/>
      <mass value="0.1"/>
      <inertia ixx="6.68333333333e-05" ixy="0" ixz="0" iyy="7.00416666667e-05" iyz="0" izz="2.48083333333e-05"/>
    </inertial>
    <visual>
      <origin rpy="0 0 0" xyz="0 0 0"/>
      <geometry>
        <mesh filename="package://rosie_description/meshes/hand/finger_proximal.dae"/>
      </geometry>
      <material name="HandGray"/>
    </visual>
    <collision>
      <origin rpy="0 0 0" xyz="0 0 0"/>
      <geometry>
        <mesh filename="package://rosie_description/meshes/hand/convex/finger_proximal_convex.stl"/>
      </geometry>
    </collision>
  </link>
  <link name="right_hand_middle_finger_middle_link">
    <inertial>
      <origin rpy="0 0 0" xyz="0.015 -0.01 0"/>
      <mass value="0.1"/>
      <inertia ixx="3.00333333333e-05" ixy="0" ixz="0" iyy="2.90666666667e-05" iyz="0" izz="1.40333333333e-05"/>
    </inertial>
    <visual>
      <origin rpy="0 0 0" xyz="0 0 0"/>
      <geometry>
        <mesh filename="package://rosie_description/meshes/hand/finger_middle.dae"/>
      </geometry>
      <material name="HandGray"/>
    </visual>
    <collision>
      <origin rpy="0 0 0" xyz="0 0 0"/>
      <geometry>
        <mesh filename="package://rosie_description/meshes/hand/convex/finger_middle_convex.stl"/>
      </geometry>
    </collision>
  </link>
  <link name="right_hand_middle_finger_distal_link">
    <inertial>
      <origin rpy="0 0 0" xyz="0 0.014 0"/>
      <mass value="0.1"/>
      <inertia ixx="1.30833333333e-05" ixy="0" ixz="0" iyy="2.78416666667e-05" iyz="0" izz="2.69083333333e-05"/>
    </inertial>
    <visual>
      <origin rpy="0 0 0" xyz="0 0 0"/>
      <geometry>
        <mesh filename="package://rosie_description/meshes/hand/finger_distal.dae"/>
      </geometry>
      <material name="HandGray"/>
    </visual>
    <collision>
      <origin rpy="0 0 0" xyz="0 0 0"/>
      <geometry>
        <mesh filename="package://rosie_description/meshes/hand/convex/finger_distal_convex.stl"/>
      </geometry>
    </collision>
  </link>
  <joint name="right_hand_middle_finger_proximal_joint" type="revolute">
    <parent link="right_hand_middle_finger_base_link"/>
    <child link="right_hand_middle_finger_proximal_link"/>
    <origin rpy="1.570796 0 0" xyz="0 0 0"/>
    <axis xyz="0 0 1"/>
    <limit effort="100" lower="-0.087266463" upper="1.134464014" velocity="100"/>
    <!-- lowStop = -5 highStop = 65 -->
    <dynamics damping="0.005"/>
  </joint>
  <transmission name="right_hand_middle_finger_proximal_trans" type="pr2_mechanism_model/SimpleTransmission">
    <actuator name="right_hand_middle_finger_proximal_motor"/>
    <joint name="right_hand_middle_finger_proximal_joint"/>
    <mechanicalReduction>1.0</mechanicalReduction>
  </transmission>
  <joint name="right_hand_middle_finger_middle_joint" type="revolute">
    <parent link="right_hand_middle_finger_proximal_link"/>
    <child link="right_hand_middle_finger_middle_link"/>
    <origin rpy="0 0 0" xyz="0.0678 0 0"/>
    <axis xyz="0 0 1"/>
    <limit effort="100" lower="0.087266463" upper="1.134464014" velocity="100"/>
    <!-- lowStop = 5 highStop = 65 -->
    <dynamics damping="0.005"/>
  </joint>
  <transmission name="right_hand_middle_finger_middle_trans" type="pr2_mechanism_model/SimpleTransmission">
    <actuator name="right_hand_middle_finger_middle_motor"/>
    <joint name="right_hand_middle_finger_middle_joint"/>
    <mechanicalReduction>1.0</mechanicalReduction>
  </transmission>
  <joint name="right_hand_middle_finger_distal_joint" type="revolute">
    <parent link="right_hand_middle_finger_middle_link"/>
    <child link="right_hand_middle_finger_distal_link"/>
    <origin rpy="0 0 -1.57" xyz="0.030 0 0"/>
    <axis xyz="0 0 1"/>
    <limit effort="100" lower="0.087266463" upper="1.134464014" velocity="100"/>
    <!-- lowStop = 5 highStop = 65 -->
    <dynamics damping="0.005"/>
  </joint>
  <transmission name="right_hand_middle_finger_distal_trans" type="pr2_mechanism_model/SimpleTransmission">
    <actuator name="right_hand_middle_finger_distal_motor"/>
    <joint name="right_hand_middle_finger_distal_joint"/>
    <mechanicalReduction>1.0</mechanicalReduction>
  </transmission>
  <joint name="right_hand_fore_finger_base_joint" type="revolute">
    <parent link="right_hand_palm"/>
    <child link="right_hand_fore_finger_base_link"/>
    <origin rpy="-1.570796 -1.536489 -1.570796" xyz="-0.0043 0.040165 0.14545"/>
    <axis xyz="0 0 1"/>
    <limit effort="100" lower="-0.261799388" upper="0.261799388" velocity="100"/>
    <!-- lowStop = -15 , highStop = +15 -->
    <dynamics damping="0.005"/>
  </joint>
  <transmission name="right_hand_fore_finger_base_trans" type="pr2_mechanism_model/SimpleTransmission">
    <actuator name="right_hand_fore_finger_base_motor"/>
    <joint name="right_hand_fore_finger_base_joint"/>
    <mechanicalReduction>1.0</mechanicalReduction>
  </transmission>
  <link name="right_hand_fore_finger_base_link">
    <inertial>
      <origin rpy="0 0 0" xyz="0.004 0 0"/>
      <mass value="0.1"/>
      <inertia ixx="2.24083333333e-05" ixy="0" ixz="0" iyy="1.42833333333e-05" iyz="0" izz="1.85416666667e-05"/>
    </inertial>
    <visual>
      <origin rpy="0 0 0" xyz="0 0 0"/>
      <geometry>
        <mesh filename="package://rosie_description/meshes/hand/finger_base.dae"/>
      </geometry>
      <material name="HandGray"/>
    </visual>
    <collision>
      <origin rpy="0 0 0" xyz="0 0 0"/>
      <geometry>
        <mesh filename="package://rosie_description/meshes/hand/convex/finger_base_convex.stl"/>
      </geometry>
    </collision>
  </link>
  <link name="right_hand_fore_finger_proximal_link">
    <inertial>
      <origin rpy="0 0 0" xyz="0.035 -0.02 0"/>
      <mass value="0.1"/>
      <inertia ixx="6.68333333333e-05" ixy="0" ixz="0" iyy="7.00416666667e-05" iyz="0" izz="2.48083333333e-05"/>
    </inertial>
    <visual>
      <origin rpy="0 0 0" xyz="0 0 0"/>
      <geometry>
        <mesh filename="package://rosie_description/meshes/hand/finger_proximal.dae"/>
      </geometry>
      <material name="HandGray"/>
    </visual>
    <collision>
      <origin rpy="0 0 0" xyz="0 0 0"/>
      <geometry>
        <mesh filename="package://rosie_description/meshes/hand/convex/finger_proximal_convex.stl"/>
      </geometry>
    </collision>
  </link>
  <link name="right_hand_fore_finger_middle_link">
    <inertial>
      <origin rpy="0 0 0" xyz="0.015 -0.01 0"/>
      <mass value="0.1"/>
      <inertia ixx="3.00333333333e-05" ixy="0" ixz="0" iyy="2.90666666667e-05" iyz="0" izz="1.40333333333e-05"/>
    </inertial>
    <visual>
      <origin rpy="0 0 0" xyz="0 0 0"/>
      <geometry>
        <mesh filename="package://rosie_description/meshes/hand/finger_middle.dae"/>
      </geometry>
      <material name="HandGray"/>
    </visual>
    <collision>
      <origin rpy="0 0 0" xyz="0 0 0"/>
      <geometry>
        <mesh filename="package://rosie_description/meshes/hand/convex/finger_middle_convex.stl"/>
      </geometry>
    </collision>
  </link>
  <link name="right_hand_fore_finger_distal_link">
    <inertial>
      <origin rpy="0 0 0" xyz="0 0.014 0"/>
      <mass value="0.1"/>
      <inertia ixx="1.30833333333e-05" ixy="0" ixz="0" iyy="2.78416666667e-05" iyz="0" izz="2.69083333333e-05"/>
    </inertial>
    <visual>
      <origin rpy="0 0 0" xyz="0 0 0"/>
      <geometry>
        <mesh filename="package://rosie_description/meshes/hand/finger_distal.dae"/>
      </geometry>
      <material name="HandGray"/>
    </visual>
    <collision>
      <origin rpy="0 0 0" xyz="0 0 0"/>
      <geometry>
        <mesh filename="package://rosie_description/meshes/hand/convex/finger_distal_convex.stl"/>
      </geometry>
    </collision>
  </link>
  <joint name="right_hand_fore_finger_proximal_joint" type="revolute">
    <parent link="right_hand_fore_finger_base_link"/>
    <child link="right_hand_fore_finger_proximal_link"/>
    <origin rpy="1.570796 0 0" xyz="0 0 0"/>
    <axis xyz="0 0 1"/>
    <limit effort="100" lower="-0.087266463" upper="1.134464014" velocity="100"/>
    <!-- lowStop = -5 highStop = 65 -->
    <dynamics damping="0.005"/>
  </joint>
  <transmission name="right_hand_fore_finger_proximal_trans" type="pr2_mechanism_model/SimpleTransmission">
    <actuator name="right_hand_fore_finger_proximal_motor"/>
    <joint name="right_hand_fore_finger_proximal_joint"/>
    <mechanicalReduction>1.0</mechanicalReduction>
  </transmission>
  <joint name="right_hand_fore_finger_middle_joint" type="revolute">
    <parent link="right_hand_fore_finger_proximal_link"/>
    <child link="right_hand_fore_finger_middle_link"/>
    <origin rpy="0 0 0" xyz="0.0678 0 0"/>
    <axis xyz="0 0 1"/>
    <limit effort="100" lower="0.087266463" upper="1.134464014" velocity="100"/>
    <!-- lowStop = 5 highStop = 65 -->
    <dynamics damping="0.005"/>
  </joint>
  <transmission name="right_hand_fore_finger_middle_trans" type="pr2_mechanism_model/SimpleTransmission">
    <actuator name="right_hand_fore_finger_middle_motor"/>
    <joint name="right_hand_fore_finger_middle_joint"/>
    <mechanicalReduction>1.0</mechanicalReduction>
  </transmission>
  <joint name="right_hand_fore_finger_distal_joint" type="revolute">
    <parent link="right_hand_fore_finger_middle_link"/>
    <child link="right_hand_fore_finger_distal_link"/>
    <origin rpy="0 0 -1.57" xyz="0.030 0 0"/>
    <axis xyz="0 0 1"/>
    <limit effort="100" lower="0.087266463" upper="1.134464014" velocity="100"/>
    <!-- lowStop = 5 highStop = 65 -->
    <dynamics damping="0.005"/>
  </joint>
  <transmission name="right_hand_fore_finger_distal_trans" type="pr2_mechanism_model/SimpleTransmission">
    <actuator name="right_hand_fore_finger_distal_motor"/>
    <joint name="right_hand_fore_finger_distal_joint"/>
    <mechanicalReduction>1.0</mechanicalReduction>
  </transmission>
  <joint name="right_hand_thumb_base_joint" type="revolute">
    <parent link="right_hand_thumb_base"/>
    <child link="right_hand_thumb_base_link"/>
    <origin rpy="0.0 -0.959927 1.570796" xyz="-0.006 0.0869 0.0970"/>
    <axis xyz="0 0 1"/>
    <limit effort="100" lower="-0.261799388" upper="0.261799388" velocity="100"/>
    <!-- lowStop = -15 , highStop = +15 -->
    <dynamics damping="0.005"/>
  </joint>
  <transmission name="right_hand_thumb_base_trans" type="pr2_mechanism_model/SimpleTransmission">
    <actuator name="right_hand_thumb_base_motor"/>
    <joint name="right_hand_thumb_base_joint"/>
    <mechanicalReduction>1.0</mechanicalReduction>
  </transmission>
  <link name="right_hand_thumb_base_link">
    <inertial>
      <origin rpy="0 0 0" xyz="0.004 0 0"/>
      <mass value="0.1"/>
      <inertia ixx="2.24083333333e-05" ixy="0" ixz="0" iyy="1.42833333333e-05" iyz="0" izz="1.85416666667e-05"/>
    </inertial>
    <visual>
      <origin rpy="0 0 0" xyz="0 0 0"/>
      <geometry>
        <mesh filename="package://rosie_description/meshes/hand/finger_base.dae"/>
      </geometry>
      <material name="HandGray"/>
    </visual>
    <collision>
      <origin rpy="0 0 0" xyz="0 0 0"/>
      <geometry>
        <mesh filename="package://rosie_description/meshes/hand/convex/finger_base_convex.stl"/>
      </geometry>
    </collision>
  </link>
  <link name="right_hand_thumb_proximal_link">
    <inertial>
      <origin rpy="0 0 0" xyz="0.035 -0.02 0"/>
      <mass value="0.1"/>
      <inertia ixx="6.68333333333e-05" ixy="0" ixz="0" iyy="7.00416666667e-05" iyz="0" izz="2.48083333333e-05"/>
    </inertial>
    <visual>
      <origin rpy="0 0 0" xyz="0 0 0"/>
      <geometry>
        <mesh filename="package://rosie_description/meshes/hand/finger_proximal.dae"/>
      </geometry>
      <material name="HandGray"/>
    </visual>
    <collision>
      <origin rpy="0 0 0" xyz="0 0 0"/>
      <geometry>
        <mesh filename="package://rosie_description/meshes/hand/convex/finger_proximal_convex.stl"/>
      </geometry>
    </collision>
  </link>
  <link name="right_hand_thumb_middle_link">
    <inertial>
      <origin rpy="0 0 0" xyz="0.015 -0.01 0"/>
      <mass value="0.1"/>
      <inertia ixx="3.00333333333e-05" ixy="0" ixz="0" iyy="2.90666666667e-05" iyz="0" izz="1.40333333333e-05"/>
    </inertial>
    <visual>
      <origin rpy="0 0 0" xyz="0 0 0"/>
      <geometry>
        <mesh filename="package://rosie_description/meshes/hand/finger_middle.dae"/>
      </geometry>
      <material name="HandGray"/>
    </visual>
    <collision>
      <origin rpy="0 0 0" xyz="0 0 0"/>
      <geometry>
        <mesh filename="package://rosie_description/meshes/hand/convex/finger_middle_convex.stl"/>
      </geometry>
    </collision>
  </link>
  <link name="right_hand_thumb_distal_link">
    <inertial>
      <origin rpy="0 0 0" xyz="0 0.014 0"/>
      <mass value="0.1"/>
      <inertia ixx="1.30833333333e-05" ixy="0" ixz="0" iyy="2.78416666667e-05" iyz="0" izz="2.69083333333e-05"/>
    </inertial>
    <visual>
      <origin rpy="0 0 0" xyz="0 0 0"/>
      <geometry>
        <mesh filename="package://rosie_description/meshes/hand/finger_distal.dae"/>
      </geometry>
      <material name="HandGray"/>
    </visual>
    <collision>
      <origin rpy="0 0 0" xyz="0 0 0"/>
      <geometry>
        <mesh filename="package://rosie_description/meshes/hand/convex/finger_distal_convex.stl"/>
      </geometry>
    </collision>
  </link>
  <joint name="right_hand_thumb_proximal_joint" type="revolute">
    <parent link="right_hand_thumb_base_link"/>
    <child link="right_hand_thumb_proximal_link"/>
    <origin rpy="1.570796 0 0" xyz="0 0 0"/>
    <axis xyz="0 0 1"/>
    <limit effort="100" lower="-0.087266463" upper="1.134464014" velocity="100"/>
    <!-- lowStop = -5 highStop = 65 -->
    <dynamics damping="0.005"/>
  </joint>
  <transmission name="right_hand_thumb_proximal_trans" type="pr2_mechanism_model/SimpleTransmission">
    <actuator name="right_hand_thumb_proximal_motor"/>
    <joint name="right_hand_thumb_proximal_joint"/>
    <mechanicalReduction>1.0</mechanicalReduction>
  </transmission>
  <joint name="right_hand_thumb_middle_joint" type="revolute">
    <parent link="right_hand_thumb_proximal_link"/>
    <child link="right_hand_thumb_middle_link"/>
    <origin rpy="0 0 0" xyz="0.0678 0 0"/>
    <axis xyz="0 0 1"/>
    <limit effort="100" lower="0.087266463" upper="1.134464014" velocity="100"/>
    <!-- lowStop = 5 highStop = 65 -->
    <dynamics damping="0.005"/>
  </joint>
  <transmission name="right_hand_thumb_middle_trans" type="pr2_mechanism_model/SimpleTransmission">
    <actuator name="right_hand_thumb_middle_motor"/>
    <joint name="right_hand_thumb_middle_joint"/>
    <mechanicalReduction>1.0</mechanicalReduction>
  </transmission>
  <joint name="right_hand_thumb_distal_joint" type="revolute">
    <parent link="right_hand_thumb_middle_link"/>
    <child link="right_hand_thumb_distal_link"/>
    <origin rpy="0 0 -1.57" xyz="0.030 0 0"/>
    <axis xyz="0 0 1"/>
    <limit effort="100" lower="0.087266463" upper="1.134464014" velocity="100"/>
    <!-- lowStop = 5 highStop = 65 -->
    <dynamics damping="0.005"/>
  </joint>
  <transmission name="right_hand_thumb_distal_trans" type="pr2_mechanism_model/SimpleTransmission">
    <actuator name="right_hand_thumb_distal_motor"/>
    <joint name="right_hand_thumb_distal_joint"/>
    <mechanicalReduction>1.0</mechanicalReduction>
  </transmission>
  <joint name="left_hand_mount_joint" type="fixed">
    <parent link="left_arm_7_link"/>
    <child link="left_hand_palm"/>
    <origin rpy="-1.57079632679 0 3.92699081699" xyz="0.075 -0.075 -0.094"/>
  </joint>
  <link name="left_hand_palm">
    <inertial>
      <origin rpy="0 0 0" xyz="-0.003 0 0.074"/>
      <mass value="0.5"/>
      <inertia ixx="0.00136133333333" ixy="0" ixz="0" iyy="0.000871041666667" iyz="0" izz="0.00175104166667"/>
    </inertial>
    <visual>
      <origin rpy="0 0 0" xyz="0 0 0"/>
      <geometry>
        <mesh filename="package://rosie_description/meshes/hand/left_palm.dae"/>
      </geometry>
      <material name="HandGray"/>
    </visual>
    <collision>
      <origin rpy="0 0 0" xyz="0 0 0"/>
      <geometry>
        <mesh filename="package://rosie_description/meshes/hand/convex/left_palm_convex.stl"/>
      </geometry>
    </collision>
  </link>
  <link name="left_hand_thumb_base">
    <inertial>
      <origin rpy="0 0 0" xyz="-0.003 -0.065 0.051"/>
      <mass value="0.1"/>
      <inertia ixx="0.000102641666667" ixy="0" ixz="0" iyy="8.81666666667e-05" iyz="0" izz="0.000155541666667"/>
    </inertial>
    <visual>
      <origin rpy="0 0 0" xyz="0 0 0"/>
      <geometry>
        <mesh filename="package://rosie_description/meshes/hand/left_thumb_base.dae"/>
      </geometry>
      <material name="HandGray"/>
    </visual>
    <collision>
      <origin rpy="0 0 0" xyz="0 0 0"/>
      <geometry>
        <mesh filename="package://rosie_description/meshes/hand/convex/left_thumb_base_convex.stl"/>
      </geometry>
    </collision>
  </link>
  <joint name="left_hand_thumb_joint" type="revolute">
    <parent link="left_hand_palm"/>
    <child link="left_hand_thumb_base"/>
    <origin rpy="0 0 0" xyz="-0.003 -0.0271 0"/>
    <axis xyz="0 0 1"/>
    <limit effort="100" lower="0" upper="1.570796" velocity="100"/>
    <!-- lowStop = 0 highStop = 90 -->
    <dynamics damping="0.005"/>
  </joint>
  <transmission name="left_hand_thumb_trans" type="pr2_mechanism_model/SimpleTransmission">
    <actuator name="left_hand_thumb_motor"/>
    <joint name="left_hand_thumb_joint"/>
    <mechanicalReduction>1.0</mechanicalReduction>
  </transmission>
  <joint name="left_hand_ring_finger_base_joint" type="revolute">
    <parent link="left_hand_palm"/>
    <child link="left_hand_ring_finger_base_link"/>
    <origin rpy="1.570796 -1.536488 1.570796" xyz="-0.0043 0.040165 0.14543"/>
    <axis xyz="0 0 1"/>
    <limit effort="100" lower="-0.261799388" upper="0.261799388" velocity="100"/>
    <!-- lowStop = -15 , highStop = +15 -->
    <dynamics damping="0.005"/>
  </joint>
  <transmission name="left_hand_ring_finger_base_trans" type="pr2_mechanism_model/SimpleTransmission">
    <actuator name="left_hand_ring_finger_base_motor"/>
    <joint name="left_hand_ring_finger_base_joint"/>
    <mechanicalReduction>1.0</mechanicalReduction>
  </transmission>
  <link name="left_hand_ring_finger_base_link">
    <inertial>
      <origin rpy="0 0 0" xyz="0.004 0 0"/>
      <mass value="0.1"/>
      <inertia ixx="2.24083333333e-05" ixy="0" ixz="0" iyy="1.42833333333e-05" iyz="0" izz="1.85416666667e-05"/>
    </inertial>
    <visual>
      <origin rpy="0 0 0" xyz="0 0 0"/>
      <geometry>
        <mesh filename="package://rosie_description/meshes/hand/finger_base.dae"/>
      </geometry>
      <material name="HandGray"/>
    </visual>
    <collision>
      <origin rpy="0 0 0" xyz="0 0 0"/>
      <geometry>
        <mesh filename="package://rosie_description/meshes/hand/convex/finger_base_convex.stl"/>
      </geometry>
    </collision>
  </link>
  <link name="left_hand_ring_finger_proximal_link">
    <inertial>
      <origin rpy="0 0 0" xyz="0.035 -0.02 0"/>
      <mass value="0.1"/>
      <inertia ixx="6.68333333333e-05" ixy="0" ixz="0" iyy="7.00416666667e-05" iyz="0" izz="2.48083333333e-05"/>
    </inertial>
    <visual>
      <origin rpy="0 0 0" xyz="0 0 0"/>
      <geometry>
        <mesh filename="package://rosie_description/meshes/hand/finger_proximal.dae"/>
      </geometry>
      <material name="HandGray"/>
    </visual>
    <collision>
      <origin rpy="0 0 0" xyz="0 0 0"/>
      <geometry>
        <mesh filename="package://rosie_description/meshes/hand/convex/finger_proximal_convex.stl"/>
      </geometry>
    </collision>
  </link>
  <link name="left_hand_ring_finger_middle_link">
    <inertial>
      <origin rpy="0 0 0" xyz="0.015 -0.01 0"/>
      <mass value="0.1"/>
      <inertia ixx="3.00333333333e-05" ixy="0" ixz="0" iyy="2.90666666667e-05" iyz="0" izz="1.40333333333e-05"/>
    </inertial>
    <visual>
      <origin rpy="0 0 0" xyz="0 0 0"/>
      <geometry>
        <mesh filename="package://rosie_description/meshes/hand/finger_middle.dae"/>
      </geometry>
      <material name="HandGray"/>
    </visual>
    <collision>
      <origin rpy="0 0 0" xyz="0 0 0"/>
      <geometry>
        <mesh filename="package://rosie_description/meshes/hand/convex/finger_middle_convex.stl"/>
      </geometry>
    </collision>
  </link>
  <link name="left_hand_ring_finger_distal_link">
    <inertial>
      <origin rpy="0 0 0" xyz="0 0.014 0"/>
      <mass value="0.1"/>
      <inertia ixx="1.30833333333e-05" ixy="0" ixz="0" iyy="2.78416666667e-05" iyz="0" izz="2.69083333333e-05"/>
    </inertial>
    <visual>
      <origin rpy="0 0 0" xyz="0 0 0"/>
      <geometry>
        <mesh filename="package://rosie_description/meshes/hand/finger_distal.dae"/>
      </geometry>
      <material name="HandGray"/>
    </visual>
    <collision>
      <origin rpy="0 0 0" xyz="0 0 0"/>
      <geometry>
        <mesh filename="package://rosie_description/meshes/hand/convex/finger_distal_convex.stl"/>
      </geometry>
    </collision>
  </link>
  <joint name="left_hand_ring_finger_proximal_joint" type="revolute">
    <parent link="left_hand_ring_finger_base_link"/>
    <child link="left_hand_ring_finger_proximal_link"/>
    <origin rpy="1.570796 0 0" xyz="0 0 0"/>
    <axis xyz="0 0 1"/>
    <limit effort="100" lower="-0.087266463" upper="1.134464014" velocity="100"/>
    <!-- lowStop = -5 highStop = 65 -->
    <dynamics damping="0.005"/>
  </joint>
  <transmission name="left_hand_ring_finger_proximal_trans" type="pr2_mechanism_model/SimpleTransmission">
    <actuator name="left_hand_ring_finger_proximal_motor"/>
    <joint name="left_hand_ring_finger_proximal_joint"/>
    <mechanicalReduction>1.0</mechanicalReduction>
  </transmission>
  <joint name="left_hand_ring_finger_middle_joint" type="revolute">
    <parent link="left_hand_ring_finger_proximal_link"/>
    <child link="left_hand_ring_finger_middle_link"/>
    <origin rpy="0 0 0" xyz="0.0678 0 0"/>
    <axis xyz="0 0 1"/>
    <limit effort="100" lower="0.087266463" upper="1.134464014" velocity="100"/>
    <!-- lowStop = 5 highStop = 65 -->
    <dynamics damping="0.005"/>
  </joint>
  <transmission name="left_hand_ring_finger_middle_trans" type="pr2_mechanism_model/SimpleTransmission">
    <actuator name="left_hand_ring_finger_middle_motor"/>
    <joint name="left_hand_ring_finger_middle_joint"/>
    <mechanicalReduction>1.0</mechanicalReduction>
  </transmission>
  <joint name="left_hand_ring_finger_distal_joint" type="revolute">
    <parent link="left_hand_ring_finger_middle_link"/>
    <child link="left_hand_ring_finger_distal_link"/>
    <origin rpy="0 0 -1.57" xyz="0.030 0 0"/>
    <axis xyz="0 0 1"/>
    <limit effort="100" lower="0.087266463" upper="1.134464014" velocity="100"/>
    <!-- lowStop = 5 highStop = 65 -->
    <dynamics damping="0.005"/>
  </joint>
  <transmission name="left_hand_ring_finger_distal_trans" type="pr2_mechanism_model/SimpleTransmission">
    <actuator name="left_hand_ring_finger_distal_motor"/>
    <joint name="left_hand_ring_finger_distal_joint"/>
    <mechanicalReduction>1.0</mechanicalReduction>
  </transmission>
  <joint name="left_hand_middle_finger_base_joint" type="revolute">
    <parent link="left_hand_palm"/>
    <child link="left_hand_middle_finger_base_link"/>
    <origin rpy="-3.141593 -1.570796 0" xyz="-0.0043 0 0.15015"/>
    <axis xyz="0 0 1"/>
    <limit effort="100" lower="-0.261799388" upper="0.261799388" velocity="100"/>
    <!-- lowStop = -15 , highStop = +15 -->
    <dynamics damping="0.005"/>
  </joint>
  <transmission name="left_hand_middle_finger_base_trans" type="pr2_mechanism_model/SimpleTransmission">
    <actuator name="left_hand_middle_finger_base_motor"/>
    <joint name="left_hand_middle_finger_base_joint"/>
    <mechanicalReduction>1.0</mechanicalReduction>
  </transmission>
  <link name="left_hand_middle_finger_base_link">
    <inertial>
      <origin rpy="0 0 0" xyz="0.004 0 0"/>
      <mass value="0.1"/>
      <inertia ixx="2.24083333333e-05" ixy="0" ixz="0" iyy="1.42833333333e-05" iyz="0" izz="1.85416666667e-05"/>
    </inertial>
    <visual>
      <origin rpy="0 0 0" xyz="0 0 0"/>
      <geometry>
        <mesh filename="package://rosie_description/meshes/hand/finger_base.dae"/>
      </geometry>
      <material name="HandGray"/>
    </visual>
    <collision>
      <origin rpy="0 0 0" xyz="0 0 0"/>
      <geometry>
        <mesh filename="package://rosie_description/meshes/hand/convex/finger_base_convex.stl"/>
      </geometry>
    </collision>
  </link>
  <link name="left_hand_middle_finger_proximal_link">
    <inertial>
      <origin rpy="0 0 0" xyz="0.035 -0.02 0"/>
      <mass value="0.1"/>
      <inertia ixx="6.68333333333e-05" ixy="0" ixz="0" iyy="7.00416666667e-05" iyz="0" izz="2.48083333333e-05"/>
    </inertial>
    <visual>
      <origin rpy="0 0 0" xyz="0 0 0"/>
      <geometry>
        <mesh filename="package://rosie_description/meshes/hand/finger_proximal.dae"/>
      </geometry>
      <material name="HandGray"/>
    </visual>
    <collision>
      <origin rpy="0 0 0" xyz="0 0 0"/>
      <geometry>
        <mesh filename="package://rosie_description/meshes/hand/convex/finger_proximal_convex.stl"/>
      </geometry>
    </collision>
  </link>
  <link name="left_hand_middle_finger_middle_link">
    <inertial>
      <origin rpy="0 0 0" xyz="0.015 -0.01 0"/>
      <mass value="0.1"/>
      <inertia ixx="3.00333333333e-05" ixy="0" ixz="0" iyy="2.90666666667e-05" iyz="0" izz="1.40333333333e-05"/>
    </inertial>
    <visual>
      <origin rpy="0 0 0" xyz="0 0 0"/>
      <geometry>
        <mesh filename="package://rosie_description/meshes/hand/finger_middle.dae"/>
      </geometry>
      <material name="HandGray"/>
    </visual>
    <collision>
      <origin rpy="0 0 0" xyz="0 0 0"/>
      <geometry>
        <mesh filename="package://rosie_description/meshes/hand/convex/finger_middle_convex.stl"/>
      </geometry>
    </collision>
  </link>
  <link name="left_hand_middle_finger_distal_link">
    <inertial>
      <origin rpy="0 0 0" xyz="0 0.014 0"/>
      <mass value="0.1"/>
      <inertia ixx="1.30833333333e-05" ixy="0" ixz="0" iyy="2.78416666667e-05" iyz="0" izz="2.69083333333e-05"/>
    </inertial>
    <visual>
      <origin rpy="0 0 0" xyz="0 0 0"/>
      <geometry>
        <mesh filename="package://rosie_description/meshes/hand/finger_distal.dae"/>
      </geometry>
      <material name="HandGray"/>
    </visual>
    <collision>
      <origin rpy="0 0 0" xyz="0 0 0"/>
      <geometry>
        <mesh filename="package://rosie_description/meshes/hand/convex/finger_distal_convex.stl"/>
      </geometry>
    </collision>
  </link>
  <joint name="left_hand_middle_finger_proximal_joint" type="revolute">
    <parent link="left_hand_middle_finger_base_link"/>
    <child link="left_hand_middle_finger_proximal_link"/>
    <origin rpy="1.570796 0 0" xyz="0 0 0"/>
    <axis xyz="0 0 1"/>
    <limit effort="100" lower="-0.087266463" upper="1.134464014" velocity="100"/>
    <!-- lowStop = -5 highStop = 65 -->
    <dynamics damping="0.005"/>
  </joint>
  <transmission name="left_hand_middle_finger_proximal_trans" type="pr2_mechanism_model/SimpleTransmission">
    <actuator name="left_hand_middle_finger_proximal_motor"/>
    <joint name="left_hand_middle_finger_proximal_joint"/>
    <mechanicalReduction>1.0</mechanicalReduction>
  </transmission>
  <joint name="left_hand_middle_finger_middle_joint" type="revolute">
    <parent link="left_hand_middle_finger_proximal_link"/>
    <child link="left_hand_middle_finger_middle_link"/>
    <origin rpy="0 0 0" xyz="0.0678 0 0"/>
    <axis xyz="0 0 1"/>
    <limit effort="100" lower="0.087266463" upper="1.134464014" velocity="100"/>
    <!-- lowStop = 5 highStop = 65 -->
    <dynamics damping="0.005"/>
  </joint>
  <transmission name="left_hand_middle_finger_middle_trans" type="pr2_mechanism_model/SimpleTransmission">
    <actuator name="left_hand_middle_finger_middle_motor"/>
    <joint name="left_hand_middle_finger_middle_joint"/>
    <mechanicalReduction>1.0</mechanicalReduction>
  </transmission>
  <joint name="left_hand_middle_finger_distal_joint" type="revolute">
    <parent link="left_hand_middle_finger_middle_link"/>
    <child link="left_hand_middle_finger_distal_link"/>
    <origin rpy="0 0 -1.57" xyz="0.030 0 0"/>
    <axis xyz="0 0 1"/>
    <limit effort="100" lower="0.087266463" upper="1.134464014" velocity="100"/>
    <!-- lowStop = 5 highStop = 65 -->
    <dynamics damping="0.005"/>
  </joint>
  <transmission name="left_hand_middle_finger_distal_trans" type="pr2_mechanism_model/SimpleTransmission">
    <actuator name="left_hand_middle_finger_distal_motor"/>
    <joint name="left_hand_middle_finger_distal_joint"/>
    <mechanicalReduction>1.0</mechanicalReduction>
  </transmission>
  <joint name="left_hand_fore_finger_base_joint" type="revolute">
    <parent link="left_hand_palm"/>
    <child link="left_hand_fore_finger_base_link"/>
    <origin rpy="-1.570796 -1.536489 -1.570796" xyz="-0.0043 -0.040165 0.14545"/>
    <axis xyz="0 0 1"/>
    <limit effort="100" lower="-0.261799388" upper="0.261799388" velocity="100"/>
    <!-- lowStop = -15 , highStop = +15 -->
    <dynamics damping="0.005"/>
  </joint>
  <transmission name="left_hand_fore_finger_base_trans" type="pr2_mechanism_model/SimpleTransmission">
    <actuator name="left_hand_fore_finger_base_motor"/>
    <joint name="left_hand_fore_finger_base_joint"/>
    <mechanicalReduction>1.0</mechanicalReduction>
  </transmission>
  <link name="left_hand_fore_finger_base_link">
    <inertial>
      <origin rpy="0 0 0" xyz="0.004 0 0"/>
      <mass value="0.1"/>
      <inertia ixx="2.24083333333e-05" ixy="0" ixz="0" iyy="1.42833333333e-05" iyz="0" izz="1.85416666667e-05"/>
    </inertial>
    <visual>
      <origin rpy="0 0 0" xyz="0 0 0"/>
      <geometry>
        <mesh filename="package://rosie_description/meshes/hand/finger_base.dae"/>
      </geometry>
      <material name="HandGray"/>
    </visual>
    <collision>
      <origin rpy="0 0 0" xyz="0 0 0"/>
      <geometry>
        <mesh filename="package://rosie_description/meshes/hand/convex/finger_base_convex.stl"/>
      </geometry>
    </collision>
  </link>
  <link name="left_hand_fore_finger_proximal_link">
    <inertial>
      <origin rpy="0 0 0" xyz="0.035 -0.02 0"/>
      <mass value="0.1"/>
      <inertia ixx="6.68333333333e-05" ixy="0" ixz="0" iyy="7.00416666667e-05" iyz="0" izz="2.48083333333e-05"/>
    </inertial>
    <visual>
      <origin rpy="0 0 0" xyz="0 0 0"/>
      <geometry>
        <mesh filename="package://rosie_description/meshes/hand/finger_proximal.dae"/>
      </geometry>
      <material name="HandGray"/>
    </visual>
    <collision>
      <origin rpy="0 0 0" xyz="0 0 0"/>
      <geometry>
        <mesh filename="package://rosie_description/meshes/hand/convex/finger_proximal_convex.stl"/>
      </geometry>
    </collision>
  </link>
  <link name="left_hand_fore_finger_middle_link">
    <inertial>
      <origin rpy="0 0 0" xyz="0.015 -0.01 0"/>
      <mass value="0.1"/>
      <inertia ixx="3.00333333333e-05" ixy="0" ixz="0" iyy="2.90666666667e-05" iyz="0" izz="1.40333333333e-05"/>
    </inertial>
    <visual>
      <origin rpy="0 0 0" xyz="0 0 0"/>
      <geometry>
        <mesh filename="package://rosie_description/meshes/hand/finger_middle.dae"/>
      </geometry>
      <material name="HandGray"/>
    </visual>
    <collision>
      <origin rpy="0 0 0" xyz="0 0 0"/>
      <geometry>
        <mesh filename="package://rosie_description/meshes/hand/convex/finger_middle_convex.stl"/>
      </geometry>
    </collision>
  </link>
  <link name="left_hand_fore_finger_distal_link">
    <inertial>
      <origin rpy="0 0 0" xyz="0 0.014 0"/>
      <mass value="0.1"/>
      <inertia ixx="1.30833333333e-05" ixy="0" ixz="0" iyy="2.78416666667e-05" iyz="0" izz="2.69083333333e-05"/>
    </inertial>
    <visual>
      <origin rpy="0 0 0" xyz="0 0 0"/>
      <geometry>
        <mesh filename="package://rosie_description/meshes/hand/finger_distal.dae"/>
      </geometry>
      <material name="HandGray"/>
    </visual>
    <collision>
      <origin rpy="0 0 0" xyz="0 0 0"/>
      <geometry>
        <mesh filename="package://rosie_description/meshes/hand/convex/finger_distal_convex.stl"/>
      </geometry>
    </collision>
  </link>
  <joint name="left_hand_fore_finger_proximal_joint" type="revolute">
    <parent link="left_hand_fore_finger_base_link"/>
    <child link="left_hand_fore_finger_proximal_link"/>
    <origin rpy="1.570796 0 0" xyz="0 0 0"/>
    <axis xyz="0 0 1"/>
    <limit effort="100" lower="-0.087266463" upper="1.134464014" velocity="100"/>
    <!-- lowStop = -5 highStop = 65 -->
    <dynamics damping="0.005"/>
  </joint>
  <transmission name="left_hand_fore_finger_proximal_trans" type="pr2_mechanism_model/SimpleTransmission">
    <actuator name="left_hand_fore_finger_proximal_motor"/>
    <joint name="left_hand_fore_finger_proximal_joint"/>
    <mechanicalReduction>1.0</mechanicalReduction>
  </transmission>
  <joint name="left_hand_fore_finger_middle_joint" type="revolute">
    <parent link="left_hand_fore_finger_proximal_link"/>
    <child link="left_hand_fore_finger_middle_link"/>
    <origin rpy="0 0 0" xyz="0.0678 0 0"/>
    <axis xyz="0 0 1"/>
    <limit effort="100" lower="0.087266463" upper="1.134464014" velocity="100"/>
    <!-- lowStop = 5 highStop = 65 -->
    <dynamics damping="0.005"/>
  </joint>
  <transmission name="left_hand_fore_finger_middle_trans" type="pr2_mechanism_model/SimpleTransmission">
    <actuator name="left_hand_fore_finger_middle_motor"/>
    <joint name="left_hand_fore_finger_middle_joint"/>
    <mechanicalReduction>1.0</mechanicalReduction>
  </transmission>
  <joint name="left_hand_fore_finger_distal_joint" type="revolute">
    <parent link="left_hand_fore_finger_middle_link"/>
    <child link="left_hand_fore_finger_distal_link"/>
    <origin rpy="0 0 -1.57" xyz="0.030 0 0"/>
    <axis xyz="0 0 1"/>
    <limit effort="100" lower="0.087266463" upper="1.134464014" velocity="100"/>
    <!-- lowStop = 5 highStop = 65 -->
    <dynamics damping="0.005"/>
  </joint>
  <transmission name="left_hand_fore_finger_distal_trans" type="pr2_mechanism_model/SimpleTransmission">
    <actuator name="left_hand_fore_finger_distal_motor"/>
    <joint name="left_hand_fore_finger_distal_joint"/>
    <mechanicalReduction>1.0</mechanicalReduction>
  </transmission>
  <joint name="left_hand_thumb_base_joint" type="revolute">
    <parent link="left_hand_thumb_base"/>
    <child link="left_hand_thumb_base_link"/>
    <origin rpy="0.0 -0.959927 -1.570796" xyz="-0.006 -0.0869 0.0970"/>
    <axis xyz="0 0 1"/>
    <limit effort="100" lower="-0.261799388" upper="0.261799388" velocity="100"/>
    <!-- lowStop = -15 , highStop = +15 -->
    <dynamics damping="0.005"/>
  </joint>
  <transmission name="left_hand_thumb_base_trans" type="pr2_mechanism_model/SimpleTransmission">
    <actuator name="left_hand_thumb_base_motor"/>
    <joint name="left_hand_thumb_base_joint"/>
    <mechanicalReduction>1.0</mechanicalReduction>
  </transmission>
  <link name="left_hand_thumb_base_link">
    <inertial>
      <origin rpy="0 0 0" xyz="0.004 0 0"/>
      <mass value="0.1"/>
      <inertia ixx="2.24083333333e-05" ixy="0" ixz="0" iyy="1.42833333333e-05" iyz="0" izz="1.85416666667e-05"/>
    </inertial>
    <visual>
      <origin rpy="0 0 0" xyz="0 0 0"/>
      <geometry>
        <mesh filename="package://rosie_description/meshes/hand/finger_base.dae"/>
      </geometry>
      <material name="HandGray"/>
    </visual>
    <collision>
      <origin rpy="0 0 0" xyz="0 0 0"/>
      <geometry>
        <mesh filename="package://rosie_description/meshes/hand/convex/finger_base_convex.stl"/>
      </geometry>
    </collision>
  </link>
  <link name="left_hand_thumb_proximal_link">
    <inertial>
      <origin rpy="0 0 0" xyz="0.035 -0.02 0"/>
      <mass value="0.1"/>
      <inertia ixx="6.68333333333e-05" ixy="0" ixz="0" iyy="7.00416666667e-05" iyz="0" izz="2.48083333333e-05"/>
    </inertial>
    <visual>
      <origin rpy="0 0 0" xyz="0 0 0"/>
      <geometry>
        <mesh filename="package://rosie_description/meshes/hand/finger_proximal.dae"/>
      </geometry>
      <material name="HandGray"/>
    </visual>
    <collision>
      <origin rpy="0 0 0" xyz="0 0 0"/>
      <geometry>
        <mesh filename="package://rosie_description/meshes/hand/convex/finger_proximal_convex.stl"/>
      </geometry>
    </collision>
  </link>
  <link name="left_hand_thumb_middle_link">
    <inertial>
      <origin rpy="0 0 0" xyz="0.015 -0.01 0"/>
      <mass value="0.1"/>
      <inertia ixx="3.00333333333e-05" ixy="0" ixz="0" iyy="2.90666666667e-05" iyz="0" izz="1.40333333333e-05"/>
    </inertial>
    <visual>
      <origin rpy="0 0 0" xyz="0 0 0"/>
      <geometry>
        <mesh filename="package://rosie_description/meshes/hand/finger_middle.dae"/>
      </geometry>
      <material name="HandGray"/>
    </visual>
    <collision>
      <origin rpy="0 0 0" xyz="0 0 0"/>
      <geometry>
        <mesh filename="package://rosie_description/meshes/hand/convex/finger_middle_convex.stl"/>
      </geometry>
    </collision>
  </link>
  <link name="left_hand_thumb_distal_link">
    <inertial>
      <origin rpy="0 0 0" xyz="0 0.014 0"/>
      <mass value="0.1"/>
      <inertia ixx="1.30833333333e-05" ixy="0" ixz="0" iyy="2.78416666667e-05" iyz="0" izz="2.69083333333e-05"/>
    </inertial>
    <visual>
      <origin rpy="0 0 0" xyz="0 0 0"/>
      <geometry>
        <mesh filename="package://rosie_description/meshes/hand/finger_distal.dae"/>
      </geometry>
      <material name="HandGray"/>
    </visual>
    <collision>
      <origin rpy="0 0 0" xyz="0 0 0"/>
      <geometry>
        <mesh filename="package://rosie_description/meshes/hand/convex/finger_distal_convex.stl"/>
      </geometry>
    </collision>
  </link>
  <joint name="left_hand_thumb_proximal_joint" type="revolute">
    <parent link="left_hand_thumb_base_link"/>
    <child link="left_hand_thumb_proximal_link"/>
    <origin rpy="1.570796 0 0" xyz="0 0 0"/>
    <axis xyz="0 0 1"/>
    <limit effort="100" lower="-0.087266463" upper="1.134464014" velocity="100"/>
    <!-- lowStop = -5 highStop = 65 -->
    <dynamics damping="0.005"/>
  </joint>
  <transmission name="left_hand_thumb_proximal_trans" type="pr2_mechanism_model/SimpleTransmission">
    <actuator name="left_hand_thumb_proximal_motor"/>
    <joint name="left_hand_thumb_proximal_joint"/>
    <mechanicalReduction>1.0</mechanicalReduction>
  </transmission>
  <joint name="left_hand_thumb_middle_joint" type="revolute">
    <parent link="left_hand_thumb_proximal_link"/>
    <child link="left_hand_thumb_middle_link"/>
    <origin rpy="0 0 0" xyz="0.0678 0 0"/>
    <axis xyz="0 0 1"/>
    <limit effort="100" lower="0.087266463" upper="1.134464014" velocity="100"/>
    <!-- lowStop = 5 highStop = 65 -->
    <dynamics damping="0.005"/>
  </joint>
  <transmission name="left_hand_thumb_middle_trans" type="pr2_mechanism_model/SimpleTransmission">
    <actuator name="left_hand_thumb_middle_motor"/>
    <joint name="left_hand_thumb_middle_joint"/>
    <mechanicalReduction>1.0</mechanicalReduction>
  </transmission>
  <joint name="left_hand_thumb_distal_joint" type="revolute">
    <parent link="left_hand_thumb_middle_link"/>
    <child link="left_hand_thumb_distal_link"/>
    <origin rpy="0 0 -1.57" xyz="0.030 0 0"/>
    <axis xyz="0 0 1"/>
    <limit effort="100" lower="0.087266463" upper="1.134464014" velocity="100"/>
    <!-- lowStop = 5 highStop = 65 -->
    <dynamics damping="0.005"/>
  </joint>
  <transmission name="left_hand_thumb_distal_trans" type="pr2_mechanism_model/SimpleTransmission">
    <actuator name="left_hand_thumb_distal_motor"/>
    <joint name="left_hand_thumb_distal_joint"/>
    <mechanicalReduction>1.0</mechanicalReduction>
  </transmission>
</robot>
