<?xml version="1.0" ?>
<!-- =================================================================================== -->
<!-- |    This document was autogenerated by xacro from tulip.xacro                    | -->
<!-- |    EDITING THIS FILE BY HAND IS NOT RECOMMENDED                                 | -->
<!-- =================================================================================== -->
<robot name="tulip" xmlns:body="http://playerstage.sourceforge.net/gazebo/xmlschema/#body" xmlns:controller="http://playerstage.sourceforge.net/gazebo/xmlschema/#controller" xmlns:gazebo="http://playerstage.sourceforge.net/gazebo/xmlschema/#gz" xmlns:geom="http://playerstage.sourceforge.net/gazebo/xmlschema/#geom" xmlns:interface="http://playerstage.sourceforge.net/gazebo/xmlschema/#interface" xmlns:joint="http://playerstage.sourceforge.net/gazebo/xmlschema/#joint" xmlns:model="http://playerstage.sourceforge.net/gazebo/xmlschema/#model" xmlns:physics="http://playerstage.sourceforge.net/gazebo/xmlschema/#physics" xmlns:renderable="http://playerstage.sourceforge.net/gazebo/xmlschema/#renderable" xmlns:rendering="http://playerstage.sourceforge.net/gazebo/xmlschema/#rendering" xmlns:sensor="http://playerstage.sourceforge.net/gazebo/xmlschema/#sensor" xmlns:xacro="http://www.ros.org/wiki/xacro" xmlns:xi="http://www.w3.org/2001/XInclude">
  <!--get parameters generated by matlab from param.m -->
  <!-- somehow I get an error when I do the math with xacro -->
  <!-- mass_total_sum_cad = m0 + 2*(m1+m2+m3+m4+m5+m6 = 26.5015  -->
  <!-- mass_total_sum_rest = 2* (lowerArm_m + upperArm_m) + 23* almost_zero = 2*(0.119+0.119) + 23*0.01 = 0.7060 -->
  <!-- mass_total_measured = 22.5 without head, without batteries, with old Poseidon computer board -->
  <!-- mass_scale * mass_total_sum_cad + mass_total_sum_rest = mass_total_measured -->
  <!-- mass_scale = (mass_total_measured - mass_total_sum_rest)/mass_total_sum_cad -->
  <!--get parameters not present in param.m -->
  <!-- MATH -->
  <!-- dummy variable when it is not allowed to set value to zero -->
  <!-- constant pi -->
  <!-- GENERAL JOINT -->
  <!--http://www.ros.org/wiki/urdf/XML/Joint -->
  <!--damping is the physical damping value of the joint ((N*m*s)/rad  for revolute joints). -->
  <!--friction is the physical static friction value of the joint ( N*m for revolute joints). -->
  <!--tuned to fit experiments-->
  <!--tuned to fit experiments-->
  <!--tuned to fit experiments-->
  <!--tuned to fit experiments-->
  <!-- only used when using pr2_controller_manager, not in our case -->
  <!-- http://www.ros.org/wiki/pr2_controller_manager/safety_limits -->
  <!-- UPPERBODY.XACRO -->
  <!-- depth -->
  <!-- width -->
  <!-- height -->
  <!-- depth -->
  <!-- width -->
  <!-- height -->
  <!-- depth -->
  <!-- width -->
  <!-- height -->
  <!-- roll 10 deg-->
  <!-- depth -->
  <!-- mass -->
  <!-- mass -->
  <!-- inertia around x, guess -->
  <!-- inertia around y, guess -->
  <!-- inertia around z, guess -->
  <!-- depth -->
  <!-- width -->
  <!-- height -->
  <!-- height -->
  <!-- pitch 30 deg -->
  <!-- HEAD.XACRO -->
  <!-- depth -->
  <!-- width -->
  <!-- height -->
  <!-- depth -->
  <!-- height -->
  <!-- height -->
  <!-- zdistance between axis and bottom -->
  <!-- LEG.XACRO -->
  <!-- <xacro:property name="c0y" value="0.075" /> is torso2hipyaw_y -->
  <!-- <xacro:property name="c0z" value="0.17" /> is defined differently -->
  <!-- depth -->
  <!-- width -->
  <!-- depth -->
  <!-- width -->
  <!-- height -->
  <!-- depth -->
  <!-- width -->
  <!-- height -->
  <!-- radius -->
  <!-- copied from BaseState.hpp -->
  <!-- initial base_origin height = foot_dz/2 + l5z   + l4z   + l3z  + torso2hipyaw_z   -->
  <!--                            = 0.0185    + 0.013 + 0.276 + 0.32 + 0.09        =  0.7175-->
  <!-- TRANSMISSION.XACRO -->
  <!-- all left at their default values -->
  <!-- plugins -->
  <gazebo>
    <controller:gazebo_ros_controller_manager name="gazebo_ros_controller_manager" plugin="libgazebo_ros_controller_manager.so">
      <alwaysOn>true</alwaysOn>
      <updateRate>1000.0</updateRate>
    </controller:gazebo_ros_controller_manager>
  </gazebo>
  <!--get link_def & joint_def macros -->
  <!-- *************** LINK definition for PRIMITIVE geometry WITH collision  *****************-->
  <!-- *************** LINK definition for PRIMITIVE geometry WITHOUT collision  *****************-->
  <!--                 not visible in Gazebo, but visible in rviz                                 -->
  <!-- *************** LINK definition for MESH geometry WITH collision *****************-->
  <!--                 mesh without collision would not be visible in Gazebo, but only visible in rviz   -->
  <!-- ***************                TRANSMISSION DEFINITION           *****************-->
  <!-- ***************                JOINT DEFINITION           *****************-->
  <!--get tulip torso macro -->
  <!-- ***************                  TORSO                           *****************-->
  <!--torso is the base_link, with its origin x=center y=center z=bottom -->
  <link name="base_link">
    <inertial>
      <origin rpy="0 0 0" xyz="0 0 0.214"/>
      <mass value="11.8303471803"/>
      <inertia ixx="0.455591" ixy="0.01" ixz="0.01" iyy="0.343455" iyz="0.01" izz="0.117961"/>
    </inertial>
    <visual>
      <!-- in rviz the color is taken from the dae mesh-->
      <origin rpy="0 0 -1.57079632679" xyz="0 0 0"/>
      <geometry>
        <mesh filename="package://tulip_description/meshes/tulip_torso.dae"/>
      </geometry>
    </visual>
    <collision>
      <origin rpy="0 0 0" xyz="0 0 0.214"/>
      <geometry>
        <box size="0.18 0.346 0.428"/>
      </geometry>
      <contact_coefficient k_d="0" k_p="0" mu="0" resitution="0"/>
    </collision>
  </link>
  <gazebo reference="base_link">
    <material>tulip_description/tulip_black</material>
    <turnGravityOff>false</turnGravityOff>
    <selfCollide>false</selfCollide>
  </gazebo>
  <!-- the blue characters of the tue logo -->
  <link name="tuelogo_blue">
    <inertial>
      <origin rpy="0 0 0" xyz="0 0 0"/>
      <mass value="0.01"/>
      <inertia ixx="0.01" ixy="0.01" ixz="0.01" iyy="0.01" iyz="0.01" izz="0.01"/>
    </inertial>
    <visual>
      <!-- in rviz the color is taken from the dae mesh-->
      <origin rpy="0 0 -1.57079632679" xyz="0 0 0"/>
      <geometry>
        <mesh filename="package://tulip_description/meshes/tulip_tuelogo_blue.dae"/>
      </geometry>
    </visual>
    <collision>
      <origin rpy="0 0 0" xyz="0 0 0"/>
      <geometry>
        <box size="0.01 0.01 0.01"/>
      </geometry>
      <contact_coefficient k_d="0" k_p="0" mu="0" resitution="0"/>
    </collision>
  </link>
  <gazebo reference="tuelogo_blue">
    <material>tulip_description/tuelogo_blue</material>
    <turnGravityOff>false</turnGravityOff>
    <selfCollide>false</selfCollide>
  </gazebo>
  <!-- the pink characters of the tue logo -->
  <link name="tuelogo_pink">
    <inertial>
      <origin rpy="0 0 0" xyz="0 0 0"/>
      <mass value="0.01"/>
      <inertia ixx="0.01" ixy="0.01" ixz="0.01" iyy="0.01" iyz="0.01" izz="0.01"/>
    </inertial>
    <visual>
      <!-- in rviz the color is taken from the dae mesh-->
      <origin rpy="0 0 -1.57079632679" xyz="0 0 0"/>
      <geometry>
        <mesh filename="package://tulip_description/meshes/tulip_tuelogo_pink.dae"/>
      </geometry>
    </visual>
    <collision>
      <origin rpy="0 0 0" xyz="0 0 0"/>
      <geometry>
        <box size="0.01 0.01 0.01"/>
      </geometry>
      <contact_coefficient k_d="0" k_p="0" mu="0" resitution="0"/>
    </collision>
  </link>
  <gazebo reference="tuelogo_pink">
    <material>tulip_description/tuelogo_pink</material>
    <turnGravityOff>false</turnGravityOff>
    <selfCollide>false</selfCollide>
  </gazebo>
  <joint name="logofix" type="fixed">
    <parent link="base_link"/>
    <child link="tuelogo_blue"/>
    <origin rpy="0 0 0" xyz="  0 0 0"/>
  </joint>
  <joint name="logofix2" type="fixed">
    <parent link="tuelogo_blue"/>
    <child link="tuelogo_pink"/>
    <origin rpy="0 0 0" xyz="  0 0 0"/>
  </joint>
  <!-- ***************                  HEAD                            *****************-->
  <!-- dynamixel torso2neckYaw -->
  <link name="torso2neckYaw">
    <inertial>
      <origin rpy="1.57079632679 0 0" xyz="0 0 0.02"/>
      <mass value="0.01"/>
      <inertia ixx="0.01" ixy="0.01" ixz="0.01" iyy="0.01" iyz="0.01" izz="0.01"/>
    </inertial>
    <visual>
      <origin rpy="1.57079632679 0 0" xyz="0 0 0.02"/>
      <geometry>
        <box size="0.05 0.04 0.03"/>
      </geometry>
      <material name="rviztulip_description/tulip_black">
        <color rgba="0.25 0.25 0.25 1"/>
      </material>
    </visual>
    <collision>
      <origin rpy="1.57079632679 0 0" xyz="0 0 0.02"/>
      <geometry>
        <box size="0.05 0.04 0.03"/>
      </geometry>
      <contact_coefficient k_d="0" k_p="0" mu="0" resitution="0"/>
    </collision>
  </link>
  <gazebo reference="torso2neckYaw">
    <material>tulip_description/tulip_black</material>
    <!-- materials specified in folder Media/materials/scripts/tulip_description.material -->
    <turnGravityOff>false</turnGravityOff>
    <selfCollide>false</selfCollide>
  </gazebo>
  <!-- dynamixel neckYaw2neckPitch -->
  <link name="neckYaw2neckPitch">
    <inertial>
      <origin rpy="0 0 0" xyz="-0.015 0 0.015"/>
      <mass value="0.01"/>
      <inertia ixx="0.01" ixy="0.01" ixz="0.01" iyy="0.01" iyz="0.01" izz="0.01"/>
    </inertial>
    <visual>
      <origin rpy="0 0 0" xyz="-0.015 0 0.015"/>
      <geometry>
        <box size="0.05 0.04 0.03"/>
      </geometry>
      <material name="rviztulip_description/tulip_black">
        <color rgba="0.25 0.25 0.25 1"/>
      </material>
    </visual>
    <collision>
      <origin rpy="0 0 0" xyz="-0.015 0 0.015"/>
      <geometry>
        <box size="0.05 0.04 0.03"/>
      </geometry>
      <contact_coefficient k_d="0" k_p="0" mu="0" resitution="0"/>
    </collision>
  </link>
  <gazebo reference="neckYaw2neckPitch">
    <material>tulip_description/tulip_black</material>
    <!-- materials specified in folder Media/materials/scripts/tulip_description.material -->
    <turnGravityOff>false</turnGravityOff>
    <selfCollide>false</selfCollide>
  </gazebo>
  <!-- link from neck_pitch joint to head-->
  <link name="neckPitch2head">
    <inertial>
      <origin rpy="0 0 0" xyz="0 0 0.035"/>
      <mass value="0.01"/>
      <inertia ixx="0.01" ixy="0.01" ixz="0.01" iyy="0.01" iyz="0.01" izz="0.01"/>
    </inertial>
    <visual>
      <!-- in rviz the color is taken from the dae mesh-->
      <origin rpy="0 0 -1.57079632679" xyz="0 0 0"/>
      <geometry>
        <mesh filename="package://tulip_description/meshes/tulip_neck.dae"/>
      </geometry>
    </visual>
    <collision>
      <origin rpy="0 0 0" xyz="0 0 0.035"/>
      <geometry>
        <box size="0.03 0.04 0.09"/>
      </geometry>
      <contact_coefficient k_d="0" k_p="0" mu="0" resitution="0"/>
    </collision>
  </link>
  <gazebo reference="neckPitch2head">
    <material>tulip_description/tulip_aluminium</material>
    <turnGravityOff>false</turnGravityOff>
    <selfCollide>false</selfCollide>
  </gazebo>
  <!-- head-->
  <link name="head">
    <inertial>
      <origin rpy="0 0 0" xyz="0 0 0.025 "/>
      <mass value="0.01"/>
      <inertia ixx="0.01" ixy="0.01" ixz="0.01" iyy="0.01" iyz="0.01" izz="0.01"/>
    </inertial>
    <visual>
      <!-- in rviz the color is taken from the dae mesh-->
      <origin rpy="0 0 -1.57079632679" xyz="0 0 0"/>
      <geometry>
        <mesh filename="package://tulip_description/meshes/tulip_head.dae"/>
      </geometry>
    </visual>
    <collision>
      <origin rpy="0 0 0" xyz="0 0 0.025 "/>
      <geometry>
        <box size="0.09 0.15 0.05"/>
      </geometry>
      <contact_coefficient k_d="0" k_p="0" mu="0" resitution="0"/>
    </collision>
  </link>
  <gazebo reference="head">
    <material>tulip_description/tulip_black</material>
    <turnGravityOff>false</turnGravityOff>
    <selfCollide>false</selfCollide>
  </gazebo>
  <!-- xsens -->
  <link name="xsens">
    <inertial>
      <origin rpy="0 0 0" xyz="0 0 0"/>
      <mass value="0.01"/>
      <inertia ixx="0.01" ixy="0.01" ixz="0.01" iyy="0.01" iyz="0.01" izz="0.01"/>
    </inertial>
    <visual>
      <origin rpy="0 0 0" xyz="0 0 0"/>
      <geometry>
        <box size="0.053 0.038 0.022"/>
      </geometry>
      <material name="rviztulip_description/xsens_orange">
        <color rgba="1 0.5 0 1"/>
      </material>
    </visual>
    <collision>
      <origin rpy="0 0 0" xyz="0 0 0"/>
      <geometry>
        <box size="0.053 0.038 0.022"/>
      </geometry>
      <contact_coefficient k_d="0" k_p="0" mu="0" resitution="0"/>
    </collision>
  </link>
  <gazebo reference="xsens">
    <material>tulip_description/xsens_orange</material>
    <!-- materials specified in folder Media/materials/scripts/tulip_description.material -->
    <turnGravityOff>false</turnGravityOff>
    <selfCollide>false</selfCollide>
  </gazebo>
  <gazebo>
    <controller:gazebo_ros_p3d name="xsens_p3d_controller" plugin="libgazebo_ros_p3d.so">
      <alwaysOn>true</alwaysOn>
      <updateRate>100.0</updateRate>
      <bodyName>xsens</bodyName>
      <topicName>xsens_pose_ground_truth</topicName>
      <gaussianNoise>0</gaussianNoise>
      <frameName>map</frameName>
      <xyzOffsets>0 0 0</xyzOffsets>
      <rpyOffsets>0 0 0</rpyOffsets>
      <xyzOffset>0 0 0</xyzOffset>
      <rpyOffset>0 0 0</rpyOffset>
      <interface:position name="xsens_p3d_iface"/>
    </controller:gazebo_ros_p3d>
  </gazebo>
  <joint name="neckDnmxlfix" type="fixed">
    <parent link="base_link"/>
    <child link="torso2neckYaw"/>
    <origin rpy="0 0 0" xyz="0 0 0.428"/>
  </joint>
  <!--
<joint name="xsensfix" type="fixed">
  <parent link="torso2neckYaw"/>
  <child link="xsens"/>
  <origin xyz="${neck2xsens_x} ${-neck2xsens_y - dynamixel_dz/2 - xsens_dy/2} ${xsens_dz/2}" rpy="0 0 0"/>
</joint>
-->
  <!-- when the xsens is connected to the torso with a fixed joint, it returns the state of the base_link-->
  <!-- therefore this fake revolute joint is used to imitate a fixed joint, so xsens correctly returns the state of the xsens link-->
  <joint name="xsensfix" type="revolute">
    <parent link="torso2neckYaw"/>
    <child link="xsens"/>
    <origin rpy="0 0 0" xyz="0.045 -0.07 0.011"/>
    <axis xyz="0 0 1"/>
    <limit effort="0" lower="0" upper="0" velocity="0"/>
  </joint>
  <!-- moveable joint neck yaw from torso2neckYaw dynamixel to neckYaw2neckPitch dynamixel -->
  <joint name="neck_yaw" type="revolute">
    <parent link="torso2neckYaw"/>
    <child link="neckYaw2neckPitch"/>
    <origin rpy="0 0 0" xyz="0.0075 0 0.04"/>
    <axis xyz="0 0 1"/>
    <dynamics damping="20" friction="75.0"/>
    <limit effort="100.0" lower="-3.14159265359" upper="3.14159265359" velocity="100.0"/>
  </joint>
  <transmission name="neck_yaw_transmission" type="pr2_mechanism_model/SimpleTransmission">
    <actuator name="neck_yaw_motor"/>
    <joint name="neck_yaw"/>
    <mechanicalReduction> 1 </mechanicalReduction>
    <motorTorqueConstant> 1 </motorTorqueConstant>
    <pulsesPerRevolution> 90000 </pulsesPerRevolution>
  </transmission>
  <!-- moveable joint neck pitch from neckYaw2neckPitch dynamixel to neckPitch2head -->
  <joint name="neck_pitch" type="revolute">
    <parent link="neckYaw2neckPitch"/>
    <child link="neckPitch2head"/>
    <origin rpy="0 0 0" xyz="0 0 0.015"/>
    <axis xyz="0 1 0"/>
    <dynamics damping="20" friction="75.0"/>
    <limit effort="100.0" lower="-3.14159265359" upper="3.14159265359" velocity="100.0"/>
  </joint>
  <transmission name="neck_pitch_transmission" type="pr2_mechanism_model/SimpleTransmission">
    <actuator name="neck_pitch_motor"/>
    <joint name="neck_pitch"/>
    <mechanicalReduction> 1 </mechanicalReduction>
    <motorTorqueConstant> 1 </motorTorqueConstant>
    <pulsesPerRevolution> 90000 </pulsesPerRevolution>
  </transmission>
  <joint name="neck2headfix" type="fixed">
    <parent link="neckPitch2head"/>
    <child link="head"/>
    <origin rpy="0 0 0" xyz="0 0 0.08"/>
  </joint>
  <!-- CAMERA's -->
  <!-- define a new macro -->
  <link name="right_camera">
    <inertial>
      <origin rpy="0 0 0" xyz="0 0 0"/>
      <mass value="0.01"/>
      <inertia ixx="0.01" ixy="0.01" ixz="0.01" iyy="0.01" iyz="0.01" izz="0.01"/>
    </inertial>
    <visual>
      <origin rpy="0 0 0" xyz="0 0 0"/>
      <geometry>
        <cylinder length="0.01" radius="0.01"/>
      </geometry>
      <material name="rviztulip_description/tulip_black">
        <color rgba="0.25 0.25 0.25 1"/>
      </material>
    </visual>
  </link>
  <gazebo reference="right_camera">
    <material>tulip_description/tulip_black</material>
    <turnGravityOff>false</turnGravityOff>
    <selfCollide>false</selfCollide>
  </gazebo>
  <joint name="right_camerafix" type="fixed">
    <parent link="head"/>
    <child link="right_camera"/>
    <origin rpy="0 0 0" xyz="0.06 -0.052 0.032"/>
  </joint>
  <gazebo reference="right_camera">
    <sensor:camera name="right_camera">
      <imageSize>320 240</imageSize>
      <imageFormat>R8G8B8</imageFormat>
      <hfov>65</hfov>
      <nearClip>0.1</nearClip>
      <farClip>100</farClip>
      <updateRate>60.0</updateRate>
      <controller:gazebo_ros_prosilica name="right_camera_controller" plugin="libgazebo_ros_prosilica.so">
        <alwaysOn>true</alwaysOn>
        <updateRate>60.0</updateRate>
        <imageTopicName>camera/right/image_raw</imageTopicName>
        <cameraInfoTopicName>camera/right/camera_info</cameraInfoTopicName>
        <frameName>right_camera</frameName>
        <CxPrime>0</CxPrime>
        <Cx>0</Cx>
        <Cy>0</Cy>
        <focalLength>0</focalLength>
        <hackBaseline>0</hackBaseline>
        <distortionK1>0</distortionK1>
        <distortionK2>0</distortionK2>
        <distortionK3>0</distortionK3>
        <distortionK4>0</distortionK4>
        <distortionT1>0</distortionT1>
        <distortionT2>0</distortionT2>
        <interface:camera name="right_camera_iface"/>
      </controller:gazebo_ros_prosilica>
    </sensor:camera>
    <turnGravityOff>false</turnGravityOff>
    <material>tulip_description/tulip_black</material>
  </gazebo>
  <link name="left_camera">
    <inertial>
      <origin rpy="0 0 0" xyz="0 0 0"/>
      <mass value="0.01"/>
      <inertia ixx="0.01" ixy="0.01" ixz="0.01" iyy="0.01" iyz="0.01" izz="0.01"/>
    </inertial>
    <visual>
      <origin rpy="0 0 0" xyz="0 0 0"/>
      <geometry>
        <cylinder length="0.01" radius="0.01"/>
      </geometry>
      <material name="rviztulip_description/tulip_black">
        <color rgba="0.25 0.25 0.25 1"/>
      </material>
    </visual>
  </link>
  <gazebo reference="left_camera">
    <material>tulip_description/tulip_black</material>
    <turnGravityOff>false</turnGravityOff>
    <selfCollide>false</selfCollide>
  </gazebo>
  <joint name="left_camerafix" type="fixed">
    <parent link="head"/>
    <child link="left_camera"/>
    <origin rpy="0 0 0" xyz="0.06 0.052 0.032"/>
  </joint>
  <gazebo reference="left_camera">
    <sensor:camera name="left_camera">
      <imageSize>320 240</imageSize>
      <imageFormat>R8G8B8</imageFormat>
      <hfov>65</hfov>
      <nearClip>0.1</nearClip>
      <farClip>100</farClip>
      <updateRate>60.0</updateRate>
      <controller:gazebo_ros_prosilica name="left_camera_controller" plugin="libgazebo_ros_prosilica.so">
        <alwaysOn>true</alwaysOn>
        <updateRate>60.0</updateRate>
        <imageTopicName>camera/left/image_raw</imageTopicName>
        <cameraInfoTopicName>camera/left/camera_info</cameraInfoTopicName>
        <frameName>left_camera</frameName>
        <CxPrime>0</CxPrime>
        <Cx>0</Cx>
        <Cy>0</Cy>
        <focalLength>0</focalLength>
        <hackBaseline>0</hackBaseline>
        <distortionK1>0</distortionK1>
        <distortionK2>0</distortionK2>
        <distortionK3>0</distortionK3>
        <distortionK4>0</distortionK4>
        <distortionT1>0</distortionT1>
        <distortionT2>0</distortionT2>
        <interface:camera name="left_camera_iface"/>
      </controller:gazebo_ros_prosilica>
    </sensor:camera>
    <turnGravityOff>false</turnGravityOff>
    <material>tulip_description/tulip_black</material>
  </gazebo>
  <!-- ***************                  ARM                             *****************-->
  <!-- define a new macro -->
  <!-- dynamixel in the shoulder -->
  <link name="right_shldrDnmxl">
    <inertial>
      <origin rpy="0 0 0" xyz="0 -0.02 0"/>
      <mass value="0.01"/>
      <inertia ixx="0.01" ixy="0.01" ixz="0.01" iyy="0.01" iyz="0.01" izz="0.01"/>
    </inertial>
    <visual>
      <origin rpy="0 0 0" xyz="0 -0.02 0"/>
      <geometry>
        <box size="0.05 0.04 0.03"/>
      </geometry>
      <material name="rviztulip_description/tulip_black">
        <color rgba="25.5 25.5 25.5 1"/>
      </material>
    </visual>
    <collision>
      <origin rpy="0 0 0" xyz="0 -0.02 0"/>
      <geometry>
        <box size="0.05 0.04 0.03"/>
      </geometry>
      <contact_coefficient k_d="0" k_p="0" mu="0" resitution="0"/>
    </collision>
  </link>
  <gazebo reference="right_shldrDnmxl">
    <material>tulip_description/tulip_black</material>
    <!-- materials specified in folder Media/materials/scripts/tulip_description.material -->
    <turnGravityOff>false</turnGravityOff>
    <selfCollide>false</selfCollide>
  </gazebo>
  <!-- upper arm -->
  <link name="right_upperArm">
    <inertial>
      <origin rpy="0 0 0" xyz="0 -0.005 -0.1325"/>
      <mass value="0.119"/>
      <inertia ixx="0.0001" ixy="0.01" ixz="0.01" iyy="0.001" iyz="0.01" izz="0.0001"/>
    </inertial>
    <visual>
      <origin rpy="0 0 0" xyz="0 -0.005 -0.1325"/>
      <geometry>
        <box size="0.02 0.01 0.265"/>
      </geometry>
      <material name="rviztulip_description/tulip_aluminium">
        <color rgba="0.58 0.6 0.612 1"/>
      </material>
    </visual>
    <collision>
      <origin rpy="0 0 0" xyz="0 -0.005 -0.1325"/>
      <geometry>
        <box size="0.02 0.01 0.265"/>
      </geometry>
      <contact_coefficient k_d="0" k_p="0" mu="0" resitution="0"/>
    </collision>
  </link>
  <gazebo reference="right_upperArm">
    <material>tulip_description/tulip_aluminium</material>
    <!-- materials specified in folder Media/materials/scripts/tulip_description.material -->
    <turnGravityOff>false</turnGravityOff>
    <selfCollide>false</selfCollide>
  </gazebo>
  <!-- lower arm -->
  <link name="right_lowerArm">
    <inertial>
      <origin rpy="0 0 0" xyz="0 0 -0.105"/>
      <mass value="0.119"/>
      <inertia ixx="0.0001" ixy="0.01" ixz="0.01" iyy="0.001" iyz="0.01" izz="0.0001"/>
    </inertial>
    <visual>
      <origin rpy="0 0 0" xyz="0 0 -0.105"/>
      <geometry>
        <box size="0.02 0.01 0.21"/>
      </geometry>
      <material name="rviztulip_description/tulip_aluminium">
        <color rgba="0.58 0.6 0.612 1"/>
      </material>
    </visual>
    <collision>
      <origin rpy="0 0 0" xyz="0 0 -0.105"/>
      <geometry>
        <box size="0.02 0.01 0.21"/>
      </geometry>
      <contact_coefficient k_d="0" k_p="0" mu="0" resitution="0"/>
    </collision>
  </link>
  <gazebo reference="right_lowerArm">
    <material>tulip_description/tulip_aluminium</material>
    <!-- materials specified in folder Media/materials/scripts/tulip_description.material -->
    <turnGravityOff>false</turnGravityOff>
    <selfCollide>false</selfCollide>
  </gazebo>
  <!-- fixed joint shoulder-dynamixel to torso -->
  <joint name="right_torso2shldrDnmxl" type="fixed">
    <parent link="base_link"/>
    <child link="right_shldrDnmxl"/>
    <origin rpy="-0.17 0 0" xyz="  0.035 -0.158 0.403"/>
  </joint>
  <!-- moveable joint shoulder from upper arm to shoulder dynamixel -->
  <joint name="right_shoulder_pitch" type="revolute">
    <parent link="right_shldrDnmxl"/>
    <child link="right_upperArm"/>
    <origin rpy="0 0 0" xyz="0.015 -0.04 0"/>
    <axis xyz="0 1 0"/>
    <dynamics damping="75.0" friction="75.0"/>
    <limit effort="100.0" lower="-3.14159265359" upper="3.14159265359" velocity="100.0"/>
  </joint>
  <transmission name="right_shoulder_pitch_transmission" type="pr2_mechanism_model/SimpleTransmission">
    <actuator name="right_shoulder_pitch_motor"/>
    <joint name="right_shoulder_pitch"/>
    <mechanicalReduction> 1 </mechanicalReduction>
    <motorTorqueConstant> 1 </motorTorqueConstant>
    <pulsesPerRevolution> 90000 </pulsesPerRevolution>
  </transmission>
  <!-- fixed joint elbow from lower arm to upper arm -->
  <joint name="right_elbow_roll" type="fixed">
    <parent link="right_upperArm"/>
    <child link="right_lowerArm"/>
    <origin rpy="0 -0.52 0" xyz="0 -0.005 -0.26"/>
  </joint>
  <!-- dynamixel in the shoulder -->
  <link name="left_shldrDnmxl">
    <inertial>
      <origin rpy="0 0 0" xyz="0 0.02 0"/>
      <mass value="0.01"/>
      <inertia ixx="0.01" ixy="0.01" ixz="0.01" iyy="0.01" iyz="0.01" izz="0.01"/>
    </inertial>
    <visual>
      <origin rpy="0 0 0" xyz="0 0.02 0"/>
      <geometry>
        <box size="0.05 0.04 0.03"/>
      </geometry>
      <material name="rviztulip_description/tulip_black">
        <color rgba="25.5 25.5 25.5 1"/>
      </material>
    </visual>
    <collision>
      <origin rpy="0 0 0" xyz="0 0.02 0"/>
      <geometry>
        <box size="0.05 0.04 0.03"/>
      </geometry>
      <contact_coefficient k_d="0" k_p="0" mu="0" resitution="0"/>
    </collision>
  </link>
  <gazebo reference="left_shldrDnmxl">
    <material>tulip_description/tulip_black</material>
    <!-- materials specified in folder Media/materials/scripts/tulip_description.material -->
    <turnGravityOff>false</turnGravityOff>
    <selfCollide>false</selfCollide>
  </gazebo>
  <!-- upper arm -->
  <link name="left_upperArm">
    <inertial>
      <origin rpy="0 0 0" xyz="0 0.005 -0.1325"/>
      <mass value="0.119"/>
      <inertia ixx="0.0001" ixy="0.01" ixz="0.01" iyy="0.001" iyz="0.01" izz="0.0001"/>
    </inertial>
    <visual>
      <origin rpy="0 0 0" xyz="0 0.005 -0.1325"/>
      <geometry>
        <box size="0.02 0.01 0.265"/>
      </geometry>
      <material name="rviztulip_description/tulip_aluminium">
        <color rgba="0.58 0.6 0.612 1"/>
      </material>
    </visual>
    <collision>
      <origin rpy="0 0 0" xyz="0 0.005 -0.1325"/>
      <geometry>
        <box size="0.02 0.01 0.265"/>
      </geometry>
      <contact_coefficient k_d="0" k_p="0" mu="0" resitution="0"/>
    </collision>
  </link>
  <gazebo reference="left_upperArm">
    <material>tulip_description/tulip_aluminium</material>
    <!-- materials specified in folder Media/materials/scripts/tulip_description.material -->
    <turnGravityOff>false</turnGravityOff>
    <selfCollide>false</selfCollide>
  </gazebo>
  <!-- lower arm -->
  <link name="left_lowerArm">
    <inertial>
      <origin rpy="0 0 0" xyz="0 0 -0.105"/>
      <mass value="0.119"/>
      <inertia ixx="0.0001" ixy="0.01" ixz="0.01" iyy="0.001" iyz="0.01" izz="0.0001"/>
    </inertial>
    <visual>
      <origin rpy="0 0 0" xyz="0 0 -0.105"/>
      <geometry>
        <box size="0.02 0.01 0.21"/>
      </geometry>
      <material name="rviztulip_description/tulip_aluminium">
        <color rgba="0.58 0.6 0.612 1"/>
      </material>
    </visual>
    <collision>
      <origin rpy="0 0 0" xyz="0 0 -0.105"/>
      <geometry>
        <box size="0.02 0.01 0.21"/>
      </geometry>
      <contact_coefficient k_d="0" k_p="0" mu="0" resitution="0"/>
    </collision>
  </link>
  <gazebo reference="left_lowerArm">
    <material>tulip_description/tulip_aluminium</material>
    <!-- materials specified in folder Media/materials/scripts/tulip_description.material -->
    <turnGravityOff>false</turnGravityOff>
    <selfCollide>false</selfCollide>
  </gazebo>
  <!-- fixed joint shoulder-dynamixel to torso -->
  <joint name="left_torso2shldrDnmxl" type="fixed">
    <parent link="base_link"/>
    <child link="left_shldrDnmxl"/>
    <origin rpy="0.17 0 0" xyz="  0.035 0.158 0.403"/>
  </joint>
  <!-- moveable joint shoulder from upper arm to shoulder dynamixel -->
  <joint name="left_shoulder_pitch" type="revolute">
    <parent link="left_shldrDnmxl"/>
    <child link="left_upperArm"/>
    <origin rpy="0 0 0" xyz="0.015 0.04 0"/>
    <axis xyz="0 1 0"/>
    <dynamics damping="75.0" friction="75.0"/>
    <limit effort="100.0" lower="-3.14159265359" upper="3.14159265359" velocity="100.0"/>
  </joint>
  <transmission name="left_shoulder_pitch_transmission" type="pr2_mechanism_model/SimpleTransmission">
    <actuator name="left_shoulder_pitch_motor"/>
    <joint name="left_shoulder_pitch"/>
    <mechanicalReduction> 1 </mechanicalReduction>
    <motorTorqueConstant> 1 </motorTorqueConstant>
    <pulsesPerRevolution> 90000 </pulsesPerRevolution>
  </transmission>
  <!-- fixed joint elbow from lower arm to upper arm -->
  <joint name="left_elbow_roll" type="fixed">
    <parent link="left_upperArm"/>
    <child link="left_lowerArm"/>
    <origin rpy="0 -0.52 0" xyz="0 0.005 -0.26"/>
  </joint>
  <!--get tulip leg macro -->
  <!-- ***************                  LEG                            *****************-->
  <!-- define a new macro -->
  <!-- link between hip_roll and hip_yaw -->
  <link name="right_hipRoll2hipYaw">
    <inertial>
      <origin rpy="0 0 0" xyz="0 0 0.045"/>
      <mass value="0.845222167047"/>
      <inertia ixx="3.34784e-05" ixy="0.01" ixz="0.01" iyy="0.00159022" iyz="0.01" izz="0.000937395"/>
    </inertial>
    <visual>
      <!-- in rviz the color is taken from the dae mesh-->
      <origin rpy="0 0 -1.57079632679" xyz="0 0 0"/>
      <geometry>
        <mesh filename="package://tulip_description/meshes/tulip_hip_right.dae"/>
      </geometry>
    </visual>
    <collision>
      <origin rpy="0 0 0" xyz="0 0 0.045"/>
      <geometry>
        <box size="0.11 0.06 0.09"/>
      </geometry>
      <contact_coefficient k_d="0" k_p="0" mu="0" resitution="0"/>
    </collision>
  </link>
  <gazebo reference="right_hipRoll2hipYaw">
    <material>tulip_description/tulip_black</material>
    <turnGravityOff>false</turnGravityOff>
    <selfCollide>false</selfCollide>
  </gazebo>
  <!-- dummylink between hip_pitch and hip_roll -->
  <link name="right_hipPitch2hipRoll">
    <inertial>
      <origin rpy="0 0 0" xyz="0 0 0"/>
      <mass value="0.01"/>
      <inertia ixx="0.01" ixy="0.01" ixz="0.01" iyy="0.01" iyz="0.01" izz="0.01"/>
    </inertial>
    <visual>
      <origin rpy="0 0 0" xyz="0 0 0"/>
      <geometry>
        <box size="0.01 0.01 0.01"/>
      </geometry>
      <material name="rviztulip_description/tulip_black">
        <color rgba="0.196078431373 0.196078431373 0.196078431373 1"/>
      </material>
    </visual>
  </link>
  <gazebo reference="right_hipPitch2hipRoll">
    <material>tulip_description/tulip_black</material>
    <turnGravityOff>false</turnGravityOff>
    <selfCollide>false</selfCollide>
  </gazebo>
  <!-- upperleg between knee and hip -->
  <link name="right_upperleg">
    <inertial>
      <origin rpy="0 0 0" xyz="0 0 -0.16"/>
      <mass value="2.94725373432"/>
      <inertia ixx="0.0245564" ixy="0.01" ixz="0.01" iyy="0.0189823" iyz="0.01" izz="0.0024774"/>
    </inertial>
    <visual>
      <!-- in rviz the color is taken from the dae mesh-->
      <origin rpy="0 0 1.57079632679" xyz="0 0 -0.32"/>
      <geometry>
        <mesh filename="package://tulip_description/meshes/tulip_upperleg_right.dae"/>
      </geometry>
    </visual>
    <collision>
      <origin rpy="0 0 0" xyz="0 0 -0.16"/>
      <geometry>
        <box size="0.11 0.06 0.32"/>
      </geometry>
      <contact_coefficient k_d="0" k_p="0" mu="0" resitution="0"/>
    </collision>
  </link>
  <gazebo reference="right_upperleg">
    <material>tulip_description/tulip_black</material>
    <turnGravityOff>false</turnGravityOff>
    <selfCollide>false</selfCollide>
  </gazebo>
  <!-- lowerleg between ankle and knee -->
  <link name="right_lowerleg">
    <inertial>
      <origin rpy="0 0 0" xyz="0 0 -0.138"/>
      <mass value="0.433622598343"/>
      <inertia ixx="0.00662872" ixy="0.01" ixz="0.01" iyy="0.00616003" iyz="0.01" izz="0.000150653"/>
    </inertial>
    <visual>
      <!-- in rviz the color is taken from the dae mesh-->
      <origin rpy="0 0 -1.57079632679" xyz="0 0 -0.276"/>
      <geometry>
        <mesh filename="package://tulip_description/meshes/tulip_lowerleg_right.dae"/>
      </geometry>
    </visual>
    <collision>
      <origin rpy="0 0 0" xyz="0 0 -0.138"/>
      <geometry>
        <box size="0.04 0.04 0.276"/>
      </geometry>
      <contact_coefficient k_d="0" k_p="0" mu="0" resitution="0"/>
    </collision>
  </link>
  <gazebo reference="right_lowerleg">
    <material>tulip_description/tulip_black</material>
    <turnGravityOff>false</turnGravityOff>
    <selfCollide>false</selfCollide>
  </gazebo>
  <!-- link between ankle_pitch and ankle_roll -->
  <link name="right_ankleRoll2anklePitch">
    <inertial>
      <origin rpy="0 0 0" xyz="0 0 0"/>
      <mass value="0.01"/>
      <inertia ixx="0.01" ixy="0.01" ixz="0.01" iyy="0.01" iyz="0.01" izz="0.01"/>
    </inertial>
    <visual>
      <!-- in rviz the color is taken from the dae mesh-->
      <origin rpy="0 0 -1.57079632679" xyz="0 0 0"/>
      <geometry>
        <mesh filename="package://tulip_description/meshes/tulip_ankle_right.dae"/>
      </geometry>
    </visual>
    <collision>
      <origin rpy="0 0 0" xyz="0 0 0"/>
      <geometry>
        <box size="0.01 0.01 0.01"/>
      </geometry>
      <contact_coefficient k_d="0" k_p="0" mu="0" resitution="0"/>
    </collision>
  </link>
  <gazebo reference="right_ankleRoll2anklePitch">
    <material>tulip_description/tulip_black</material>
    <turnGravityOff>false</turnGravityOff>
    <selfCollide>false</selfCollide>
  </gazebo>
  <!-- foot attached to the ankle -->
  <link name="right_foot">
    <inertial>
      <origin rpy="0 0 0" xyz="0.08775 0 -0.02"/>
      <mass value="0.755741890384"/>
      <inertia ixx="0.000669568" ixy="0.01" ixz="0.01" iyy="0.00262805" iyz="0.01" izz="0.00343154"/>
    </inertial>
    <visual>
      <!-- in rviz the color is taken from the dae mesh-->
      <origin rpy="0 0 0" xyz="0 0 0"/>
      <geometry>
        <mesh filename="package://tulip_description/meshes/tulip_foot_right.dae"/>
      </geometry>
    </visual>
    <collision>
      <origin rpy="0 0 0" xyz="0.058 -0.0125 -0.02"/>
      <geometry>
        <box size="0.235 0.15 0.037"/>
      </geometry>
      <contact_coefficient k_d="0" k_p="0" mu="0" resitution="0"/>
    </collision>
  </link>
  <gazebo reference="right_foot">
    <material>tulip_description/tulip_black</material>
    <turnGravityOff>false</turnGravityOff>
    <selfCollide>false</selfCollide>
  </gazebo>
  <!-- moveable joint hip yaw (z) from hipRoll2hipYaw to torso -->
  <joint name="right_hip_yaw" type="revolute">
    <parent link="base_link"/>
    <child link="right_hipRoll2hipYaw"/>
    <origin rpy="0 0 0" xyz="0.02 -0.075 -0.09"/>
    <axis xyz="0 0 1"/>
    <dynamics damping="75.0" friction="75.0"/>
    <limit effort="100.0" lower="-0.785398163397" upper="0.785398163397" velocity="100.0"/>
  </joint>
  <transmission name="right_hip_yaw_transmission" type="pr2_mechanism_model/SimpleTransmission">
    <actuator name="right_hip_yaw_motor"/>
    <joint name="right_hip_yaw"/>
    <mechanicalReduction> 1 </mechanicalReduction>
    <motorTorqueConstant> 1 </motorTorqueConstant>
    <pulsesPerRevolution> 90000 </pulsesPerRevolution>
  </transmission>
  <!-- moveable joint hip roll (x) from hipPitch2hipRoll to hipRoll2hipYaw -->
  <joint name="right_hip_roll" type="revolute">
    <parent link="right_hipRoll2hipYaw"/>
    <child link="right_hipPitch2hipRoll"/>
    <origin rpy="0 0 0" xyz="0 0 0"/>
    <axis xyz="1 0 0"/>
    <dynamics damping="10" friction="75.0"/>
    <limit effort="100.0" lower="-0.523598775598" upper="0.523598775598" velocity="100.0"/>
  </joint>
  <transmission name="right_hip_roll_transmission" type="pr2_mechanism_model/SimpleTransmission">
    <actuator name="right_hip_roll_motor"/>
    <joint name="right_hip_roll"/>
    <mechanicalReduction> 1 </mechanicalReduction>
    <motorTorqueConstant> 1 </motorTorqueConstant>
    <pulsesPerRevolution> 90000 </pulsesPerRevolution>
  </transmission>
  <!-- moveable joint hip pitch (y) from upperleg to hipPitch2hipRoll -->
  <joint name="right_hip_pitch" type="revolute">
    <parent link="right_hipPitch2hipRoll"/>
    <child link="right_upperleg"/>
    <origin rpy="0 0 0" xyz="0 0 0"/>
    <axis xyz="0 1 0"/>
    <dynamics damping="75.0" friction="75.0"/>
    <limit effort="100.0" lower="-1.1344640138" upper="0.506145483078" velocity="100.0"/>
  </joint>
  <transmission name="right_hip_pitch_transmission" type="pr2_mechanism_model/SimpleTransmission">
    <actuator name="right_hip_pitch_motor"/>
    <joint name="right_hip_pitch"/>
    <mechanicalReduction> 1 </mechanicalReduction>
    <motorTorqueConstant> 1 </motorTorqueConstant>
    <pulsesPerRevolution> 90000 </pulsesPerRevolution>
  </transmission>
  <!-- moveable joint knee pitch (y) from lowerleg to upperleg -->
  <joint name="right_knee_pitch" type="revolute">
    <parent link="right_upperleg"/>
    <child link="right_lowerleg"/>
    <origin rpy="0 0 0" xyz="0 0 -0.32"/>
    <axis xyz="0 1 0"/>
    <dynamics damping="30" friction="75.0"/>
    <limit effort="100.0" lower="0.0" upper="2.18166156499" velocity="100.0"/>
  </joint>
  <transmission name="right_knee_pitch_transmission" type="pr2_mechanism_model/SimpleTransmission">
    <actuator name="right_knee_pitch_motor"/>
    <joint name="right_knee_pitch"/>
    <mechanicalReduction> 1 </mechanicalReduction>
    <motorTorqueConstant> 1 </motorTorqueConstant>
    <pulsesPerRevolution> 90000 </pulsesPerRevolution>
  </transmission>
  <!-- moveable joint ankle pitch (y) from ankleRoll2anklePitch to lowerleg -->
  <joint name="right_ankle_pitch" type="revolute">
    <parent link="right_lowerleg"/>
    <child link="right_ankleRoll2anklePitch"/>
    <origin rpy="0 -0.03 0" xyz="0 0 -0.276"/>
    <axis xyz="0 1 0"/>
    <dynamics damping="40" friction="75.0"/>
    <limit effort="100.0" lower="-0.767944870878" upper="0.698131700798" velocity="100.0"/>
  </joint>
  <transmission name="right_ankle_pitch_transmission" type="pr2_mechanism_model/SimpleTransmission">
    <actuator name="right_ankle_pitch_motor"/>
    <joint name="right_ankle_pitch"/>
    <mechanicalReduction> 1 </mechanicalReduction>
    <motorTorqueConstant> 1 </motorTorqueConstant>
    <pulsesPerRevolution> 90000 </pulsesPerRevolution>
  </transmission>
  <!-- moveable joint ankle roll (x) from foot to ankleRoll2anklePitch -->
  <joint name="right_ankle_roll" type="revolute">
    <parent link="right_ankleRoll2anklePitch"/>
    <child link="right_foot"/>
    <origin rpy="0 0 0" xyz="0 0 -0.013"/>
    <axis xyz="1 0 0"/>
    <dynamics damping="30" friction="75.0"/>
    <limit effort="100.0" lower="-0.349065850399" upper="0.349065850399" velocity="100.0"/>
  </joint>
  <transmission name="right_ankle_roll_transmission" type="pr2_mechanism_model/SimpleTransmission">
    <actuator name="right_ankle_roll_motor"/>
    <joint name="right_ankle_roll"/>
    <mechanicalReduction> 1 </mechanicalReduction>
    <motorTorqueConstant> 1 </motorTorqueConstant>
    <pulsesPerRevolution> 90000 </pulsesPerRevolution>
  </transmission>
  <!-- link between hip_roll and hip_yaw -->
  <link name="left_hipRoll2hipYaw">
    <inertial>
      <origin rpy="0 0 0" xyz="0 0 0.045"/>
      <mass value="0.845222167047"/>
      <inertia ixx="3.34784e-05" ixy="0.01" ixz="0.01" iyy="0.00159022" iyz="0.01" izz="0.000937395"/>
    </inertial>
    <visual>
      <!-- in rviz the color is taken from the dae mesh-->
      <origin rpy="0 0 -1.57079632679" xyz="0 0 0"/>
      <geometry>
        <mesh filename="package://tulip_description/meshes/tulip_hip_left.dae"/>
      </geometry>
    </visual>
    <collision>
      <origin rpy="0 0 0" xyz="0 0 0.045"/>
      <geometry>
        <box size="0.11 0.06 0.09"/>
      </geometry>
      <contact_coefficient k_d="0" k_p="0" mu="0" resitution="0"/>
    </collision>
  </link>
  <gazebo reference="left_hipRoll2hipYaw">
    <material>tulip_description/tulip_black</material>
    <turnGravityOff>false</turnGravityOff>
    <selfCollide>false</selfCollide>
  </gazebo>
  <!-- dummylink between hip_pitch and hip_roll -->
  <link name="left_hipPitch2hipRoll">
    <inertial>
      <origin rpy="0 0 0" xyz="0 0 0"/>
      <mass value="0.01"/>
      <inertia ixx="0.01" ixy="0.01" ixz="0.01" iyy="0.01" iyz="0.01" izz="0.01"/>
    </inertial>
    <visual>
      <origin rpy="0 0 0" xyz="0 0 0"/>
      <geometry>
        <box size="0.01 0.01 0.01"/>
      </geometry>
      <material name="rviztulip_description/tulip_black">
        <color rgba="0.196078431373 0.196078431373 0.196078431373 1"/>
      </material>
    </visual>
  </link>
  <gazebo reference="left_hipPitch2hipRoll">
    <material>tulip_description/tulip_black</material>
    <turnGravityOff>false</turnGravityOff>
    <selfCollide>false</selfCollide>
  </gazebo>
  <!-- upperleg between knee and hip -->
  <link name="left_upperleg">
    <inertial>
      <origin rpy="0 0 0" xyz="0 0 -0.16"/>
      <mass value="2.94725373432"/>
      <inertia ixx="0.0245564" ixy="0.01" ixz="0.01" iyy="0.0189823" iyz="0.01" izz="0.0024774"/>
    </inertial>
    <visual>
      <!-- in rviz the color is taken from the dae mesh-->
      <origin rpy="0 0 1.57079632679" xyz="0 0 -0.32"/>
      <geometry>
        <mesh filename="package://tulip_description/meshes/tulip_upperleg_left.dae"/>
      </geometry>
    </visual>
    <collision>
      <origin rpy="0 0 0" xyz="0 0 -0.16"/>
      <geometry>
        <box size="0.11 0.06 0.32"/>
      </geometry>
      <contact_coefficient k_d="0" k_p="0" mu="0" resitution="0"/>
    </collision>
  </link>
  <gazebo reference="left_upperleg">
    <material>tulip_description/tulip_black</material>
    <turnGravityOff>false</turnGravityOff>
    <selfCollide>false</selfCollide>
  </gazebo>
  <!-- lowerleg between ankle and knee -->
  <link name="left_lowerleg">
    <inertial>
      <origin rpy="0 0 0" xyz="0 0 -0.138"/>
      <mass value="0.433622598343"/>
      <inertia ixx="0.00662872" ixy="0.01" ixz="0.01" iyy="0.00616003" iyz="0.01" izz="0.000150653"/>
    </inertial>
    <visual>
      <!-- in rviz the color is taken from the dae mesh-->
      <origin rpy="0 0 -1.57079632679" xyz="0 0 -0.276"/>
      <geometry>
        <mesh filename="package://tulip_description/meshes/tulip_lowerleg_left.dae"/>
      </geometry>
    </visual>
    <collision>
      <origin rpy="0 0 0" xyz="0 0 -0.138"/>
      <geometry>
        <box size="0.04 0.04 0.276"/>
      </geometry>
      <contact_coefficient k_d="0" k_p="0" mu="0" resitution="0"/>
    </collision>
  </link>
  <gazebo reference="left_lowerleg">
    <material>tulip_description/tulip_black</material>
    <turnGravityOff>false</turnGravityOff>
    <selfCollide>false</selfCollide>
  </gazebo>
  <!-- link between ankle_pitch and ankle_roll -->
  <link name="left_ankleRoll2anklePitch">
    <inertial>
      <origin rpy="0 0 0" xyz="0 0 0"/>
      <mass value="0.01"/>
      <inertia ixx="0.01" ixy="0.01" ixz="0.01" iyy="0.01" iyz="0.01" izz="0.01"/>
    </inertial>
    <visual>
      <!-- in rviz the color is taken from the dae mesh-->
      <origin rpy="0 0 -1.57079632679" xyz="0 0 0"/>
      <geometry>
        <mesh filename="package://tulip_description/meshes/tulip_ankle_left.dae"/>
      </geometry>
    </visual>
    <collision>
      <origin rpy="0 0 0" xyz="0 0 0"/>
      <geometry>
        <box size="0.01 0.01 0.01"/>
      </geometry>
      <contact_coefficient k_d="0" k_p="0" mu="0" resitution="0"/>
    </collision>
  </link>
  <gazebo reference="left_ankleRoll2anklePitch">
    <material>tulip_description/tulip_black</material>
    <turnGravityOff>false</turnGravityOff>
    <selfCollide>false</selfCollide>
  </gazebo>
  <!-- foot attached to the ankle -->
  <link name="left_foot">
    <inertial>
      <origin rpy="0 0 0" xyz="0.08775 0 -0.02"/>
      <mass value="0.755741890384"/>
      <inertia ixx="0.000669568" ixy="0.01" ixz="0.01" iyy="0.00262805" iyz="0.01" izz="0.00343154"/>
    </inertial>
    <visual>
      <!-- in rviz the color is taken from the dae mesh-->
      <origin rpy="0 0 0" xyz="0 0 0"/>
      <geometry>
        <mesh filename="package://tulip_description/meshes/tulip_foot_left.dae"/>
      </geometry>
    </visual>
    <collision>
      <origin rpy="0 0 0" xyz="0.058 0.0125 -0.02"/>
      <geometry>
        <box size="0.235 0.15 0.037"/>
      </geometry>
      <contact_coefficient k_d="0" k_p="0" mu="0" resitution="0"/>
    </collision>
  </link>
  <gazebo reference="left_foot">
    <material>tulip_description/tulip_black</material>
    <turnGravityOff>false</turnGravityOff>
    <selfCollide>false</selfCollide>
  </gazebo>
  <!-- moveable joint hip yaw (z) from hipRoll2hipYaw to torso -->
  <joint name="left_hip_yaw" type="revolute">
    <parent link="base_link"/>
    <child link="left_hipRoll2hipYaw"/>
    <origin rpy="0 0 0" xyz="0.02 0.075 -0.09"/>
    <axis xyz="0 0 1"/>
    <dynamics damping="75.0" friction="75.0"/>
    <limit effort="100.0" lower="-0.785398163397" upper="0.785398163397" velocity="100.0"/>
  </joint>
  <transmission name="left_hip_yaw_transmission" type="pr2_mechanism_model/SimpleTransmission">
    <actuator name="left_hip_yaw_motor"/>
    <joint name="left_hip_yaw"/>
    <mechanicalReduction> 1 </mechanicalReduction>
    <motorTorqueConstant> 1 </motorTorqueConstant>
    <pulsesPerRevolution> 90000 </pulsesPerRevolution>
  </transmission>
  <!-- moveable joint hip roll (x) from hipPitch2hipRoll to hipRoll2hipYaw -->
  <joint name="left_hip_roll" type="revolute">
    <parent link="left_hipRoll2hipYaw"/>
    <child link="left_hipPitch2hipRoll"/>
    <origin rpy="0 0 0" xyz="0 0 0"/>
    <axis xyz="1 0 0"/>
    <dynamics damping="10" friction="75.0"/>
    <limit effort="100.0" lower="-0.523598775598" upper="0.523598775598" velocity="100.0"/>
  </joint>
  <transmission name="left_hip_roll_transmission" type="pr2_mechanism_model/SimpleTransmission">
    <actuator name="left_hip_roll_motor"/>
    <joint name="left_hip_roll"/>
    <mechanicalReduction> 1 </mechanicalReduction>
    <motorTorqueConstant> 1 </motorTorqueConstant>
    <pulsesPerRevolution> 90000 </pulsesPerRevolution>
  </transmission>
  <!-- moveable joint hip pitch (y) from upperleg to hipPitch2hipRoll -->
  <joint name="left_hip_pitch" type="revolute">
    <parent link="left_hipPitch2hipRoll"/>
    <child link="left_upperleg"/>
    <origin rpy="0 0 0" xyz="0 0 0"/>
    <axis xyz="0 1 0"/>
    <dynamics damping="75.0" friction="75.0"/>
    <limit effort="100.0" lower="-1.1344640138" upper="0.506145483078" velocity="100.0"/>
  </joint>
  <transmission name="left_hip_pitch_transmission" type="pr2_mechanism_model/SimpleTransmission">
    <actuator name="left_hip_pitch_motor"/>
    <joint name="left_hip_pitch"/>
    <mechanicalReduction> 1 </mechanicalReduction>
    <motorTorqueConstant> 1 </motorTorqueConstant>
    <pulsesPerRevolution> 90000 </pulsesPerRevolution>
  </transmission>
  <!-- moveable joint knee pitch (y) from lowerleg to upperleg -->
  <joint name="left_knee_pitch" type="revolute">
    <parent link="left_upperleg"/>
    <child link="left_lowerleg"/>
    <origin rpy="0 0 0" xyz="0 0 -0.32"/>
    <axis xyz="0 1 0"/>
    <dynamics damping="30" friction="75.0"/>
    <limit effort="100.0" lower="0.0" upper="2.18166156499" velocity="100.0"/>
  </joint>
  <transmission name="left_knee_pitch_transmission" type="pr2_mechanism_model/SimpleTransmission">
    <actuator name="left_knee_pitch_motor"/>
    <joint name="left_knee_pitch"/>
    <mechanicalReduction> 1 </mechanicalReduction>
    <motorTorqueConstant> 1 </motorTorqueConstant>
    <pulsesPerRevolution> 90000 </pulsesPerRevolution>
  </transmission>
  <!-- moveable joint ankle pitch (y) from ankleRoll2anklePitch to lowerleg -->
  <joint name="left_ankle_pitch" type="revolute">
    <parent link="left_lowerleg"/>
    <child link="left_ankleRoll2anklePitch"/>
    <origin rpy="0 -0.03 0" xyz="0 0 -0.276"/>
    <axis xyz="0 1 0"/>
    <dynamics damping="40" friction="75.0"/>
    <limit effort="100.0" lower="-0.767944870878" upper="0.698131700798" velocity="100.0"/>
  </joint>
  <transmission name="left_ankle_pitch_transmission" type="pr2_mechanism_model/SimpleTransmission">
    <actuator name="left_ankle_pitch_motor"/>
    <joint name="left_ankle_pitch"/>
    <mechanicalReduction> 1 </mechanicalReduction>
    <motorTorqueConstant> 1 </motorTorqueConstant>
    <pulsesPerRevolution> 90000 </pulsesPerRevolution>
  </transmission>
  <!-- moveable joint ankle roll (x) from foot to ankleRoll2anklePitch -->
  <joint name="left_ankle_roll" type="revolute">
    <parent link="left_ankleRoll2anklePitch"/>
    <child link="left_foot"/>
    <origin rpy="0 0 0" xyz="0 0 -0.013"/>
    <axis xyz="1 0 0"/>
    <dynamics damping="30" friction="75.0"/>
    <limit effort="100.0" lower="-0.349065850399" upper="0.349065850399" velocity="100.0"/>
  </joint>
  <transmission name="left_ankle_roll_transmission" type="pr2_mechanism_model/SimpleTransmission">
    <actuator name="left_ankle_roll_motor"/>
    <joint name="left_ankle_roll"/>
    <mechanicalReduction> 1 </mechanicalReduction>
    <motorTorqueConstant> 1 </motorTorqueConstant>
    <pulsesPerRevolution> 90000 </pulsesPerRevolution>
  </transmission>
  <!-- ***************                  FOOT SENSORS                            *****************-->
  <!-- prf=prefix, rfl=reflect -->
  <link name="left_toe_outer_foot_sensor">
    <inertial>
      <origin rpy="0 0 0" xyz="0 0 0"/>
      <mass value="0.01"/>
      <inertia ixx="0.01" ixy="0.01" ixz="0.01" iyy="0.01" iyz="0.01" izz="0.01"/>
    </inertial>
    <visual>
      <origin rpy="0 0 0" xyz="0 0 0"/>
      <geometry>
        <sphere radius="0.005"/>
      </geometry>
      <material name="rviztulip_description/tulip_black">
        <color rgba="0.1 0.1 0.1 1"/>
      </material>
    </visual>
    <collision>
      <origin rpy="0 0 0" xyz="0 0 0"/>
      <geometry>
        <sphere radius="0.005"/>
      </geometry>
      <contact_coefficient k_d="0" k_p="0" mu="0" resitution="0"/>
    </collision>
  </link>
  <gazebo reference="left_toe_outer_foot_sensor">
    <material>tulip_description/tulip_black</material>
    <!-- materials specified in folder Media/materials/scripts/tulip_description.material -->
    <turnGravityOff>false</turnGravityOff>
    <selfCollide>false</selfCollide>
  </gazebo>
  <joint name="left_toe_outer_footsensfix" type="fixed">
    <parent link="left_foot"/>
    <child link="left_toe_outer_foot_sensor"/>
    <origin rpy="0 0 0" xyz="0.1615 0.0735 -0.037"/>
  </joint>
  <gazebo reference="left_toe_outer_foot_sensor">
    <selfCollide>false</selfCollide>
    <material value="tulip_description/tulip_black"/>
    <sensor:contact name="left_toe_outer_foot_sensor">
      <geom>left_toe_outer_foot_sensor_geom</geom>
      <updateRate>1000.0</updateRate>
      <controller:gazebo_ros_bumper name="left_toe_outer_foot_sensor_controller" plugin="libgazebo_ros_bumper.so">
        <alwaysOn>true</alwaysOn>
        <updateRate>1000.0</updateRate>
        <bumperTopicName>left_toe_outer_foot_sensor</bumperTopicName>
        <frameName>left_toe_outer_foot_sensor</frameName>
        <interface:bumper name="left_toe_outer_foot_sensor_iface"/>
      </controller:gazebo_ros_bumper>
    </sensor:contact>
  </gazebo>
  <!-- prf=prefix, rfl=reflect -->
  <link name="left_toe_inner_foot_sensor">
    <inertial>
      <origin rpy="0 0 0" xyz="0 0 0"/>
      <mass value="0.01"/>
      <inertia ixx="0.01" ixy="0.01" ixz="0.01" iyy="0.01" iyz="0.01" izz="0.01"/>
    </inertial>
    <visual>
      <origin rpy="0 0 0" xyz="0 0 0"/>
      <geometry>
        <sphere radius="0.005"/>
      </geometry>
      <material name="rviztulip_description/tulip_black">
        <color rgba="0.1 0.1 0.1 1"/>
      </material>
    </visual>
    <collision>
      <origin rpy="0 0 0" xyz="0 0 0"/>
      <geometry>
        <sphere radius="0.005"/>
      </geometry>
      <contact_coefficient k_d="0" k_p="0" mu="0" resitution="0"/>
    </collision>
  </link>
  <gazebo reference="left_toe_inner_foot_sensor">
    <material>tulip_description/tulip_black</material>
    <!-- materials specified in folder Media/materials/scripts/tulip_description.material -->
    <turnGravityOff>false</turnGravityOff>
    <selfCollide>false</selfCollide>
  </gazebo>
  <joint name="left_toe_inner_footsensfix" type="fixed">
    <parent link="left_foot"/>
    <child link="left_toe_inner_foot_sensor"/>
    <origin rpy="0 0 0" xyz="0.1615 -0.0485 -0.037"/>
  </joint>
  <gazebo reference="left_toe_inner_foot_sensor">
    <selfCollide>false</selfCollide>
    <material value="tulip_description/tulip_black"/>
    <sensor:contact name="left_toe_inner_foot_sensor">
      <geom>left_toe_inner_foot_sensor_geom</geom>
      <updateRate>1000.0</updateRate>
      <controller:gazebo_ros_bumper name="left_toe_inner_foot_sensor_controller" plugin="libgazebo_ros_bumper.so">
        <alwaysOn>true</alwaysOn>
        <updateRate>1000.0</updateRate>
        <bumperTopicName>left_toe_inner_foot_sensor</bumperTopicName>
        <frameName>left_toe_inner_foot_sensor</frameName>
        <interface:bumper name="left_toe_inner_foot_sensor_iface"/>
      </controller:gazebo_ros_bumper>
    </sensor:contact>
  </gazebo>
  <!-- prf=prefix, rfl=reflect -->
  <link name="left_heel_inner_foot_sensor">
    <inertial>
      <origin rpy="0 0 0" xyz="0 0 0"/>
      <mass value="0.01"/>
      <inertia ixx="0.01" ixy="0.01" ixz="0.01" iyy="0.01" iyz="0.01" izz="0.01"/>
    </inertial>
    <visual>
      <origin rpy="0 0 0" xyz="0 0 0"/>
      <geometry>
        <sphere radius="0.005"/>
      </geometry>
      <material name="rviztulip_description/tulip_black">
        <color rgba="0.1 0.1 0.1 1"/>
      </material>
    </visual>
    <collision>
      <origin rpy="0 0 0" xyz="0 0 0"/>
      <geometry>
        <sphere radius="0.005"/>
      </geometry>
      <contact_coefficient k_d="0" k_p="0" mu="0" resitution="0"/>
    </collision>
  </link>
  <gazebo reference="left_heel_inner_foot_sensor">
    <material>tulip_description/tulip_black</material>
    <!-- materials specified in folder Media/materials/scripts/tulip_description.material -->
    <turnGravityOff>false</turnGravityOff>
    <selfCollide>false</selfCollide>
  </gazebo>
  <joint name="left_heel_inner_footsensfix" type="fixed">
    <parent link="left_foot"/>
    <child link="left_heel_inner_foot_sensor"/>
    <origin rpy="0 0 0" xyz="-0.0455 -0.0485 -0.037"/>
  </joint>
  <gazebo reference="left_heel_inner_foot_sensor">
    <selfCollide>false</selfCollide>
    <material value="tulip_description/tulip_black"/>
    <sensor:contact name="left_heel_inner_foot_sensor">
      <geom>left_heel_inner_foot_sensor_geom</geom>
      <updateRate>1000.0</updateRate>
      <controller:gazebo_ros_bumper name="left_heel_inner_foot_sensor_controller" plugin="libgazebo_ros_bumper.so">
        <alwaysOn>true</alwaysOn>
        <updateRate>1000.0</updateRate>
        <bumperTopicName>left_heel_inner_foot_sensor</bumperTopicName>
        <frameName>left_heel_inner_foot_sensor</frameName>
        <interface:bumper name="left_heel_inner_foot_sensor_iface"/>
      </controller:gazebo_ros_bumper>
    </sensor:contact>
  </gazebo>
  <!-- prf=prefix, rfl=reflect -->
  <link name="left_heel_outer_foot_sensor">
    <inertial>
      <origin rpy="0 0 0" xyz="0 0 0"/>
      <mass value="0.01"/>
      <inertia ixx="0.01" ixy="0.01" ixz="0.01" iyy="0.01" iyz="0.01" izz="0.01"/>
    </inertial>
    <visual>
      <origin rpy="0 0 0" xyz="0 0 0"/>
      <geometry>
        <sphere radius="0.005"/>
      </geometry>
      <material name="rviztulip_description/tulip_black">
        <color rgba="0.1 0.1 0.1 1"/>
      </material>
    </visual>
    <collision>
      <origin rpy="0 0 0" xyz="0 0 0"/>
      <geometry>
        <sphere radius="0.005"/>
      </geometry>
      <contact_coefficient k_d="0" k_p="0" mu="0" resitution="0"/>
    </collision>
  </link>
  <gazebo reference="left_heel_outer_foot_sensor">
    <material>tulip_description/tulip_black</material>
    <!-- materials specified in folder Media/materials/scripts/tulip_description.material -->
    <turnGravityOff>false</turnGravityOff>
    <selfCollide>false</selfCollide>
  </gazebo>
  <joint name="left_heel_outer_footsensfix" type="fixed">
    <parent link="left_foot"/>
    <child link="left_heel_outer_foot_sensor"/>
    <origin rpy="0 0 0" xyz="-0.0455 0.0735 -0.037"/>
  </joint>
  <gazebo reference="left_heel_outer_foot_sensor">
    <selfCollide>false</selfCollide>
    <material value="tulip_description/tulip_black"/>
    <sensor:contact name="left_heel_outer_foot_sensor">
      <geom>left_heel_outer_foot_sensor_geom</geom>
      <updateRate>1000.0</updateRate>
      <controller:gazebo_ros_bumper name="left_heel_outer_foot_sensor_controller" plugin="libgazebo_ros_bumper.so">
        <alwaysOn>true</alwaysOn>
        <updateRate>1000.0</updateRate>
        <bumperTopicName>left_heel_outer_foot_sensor</bumperTopicName>
        <frameName>left_heel_outer_foot_sensor</frameName>
        <interface:bumper name="left_heel_outer_foot_sensor_iface"/>
      </controller:gazebo_ros_bumper>
    </sensor:contact>
  </gazebo>
  <!-- prf=prefix, rfl=reflect -->
  <link name="right_toe_outer_foot_sensor">
    <inertial>
      <origin rpy="0 0 0" xyz="0 0 0"/>
      <mass value="0.01"/>
      <inertia ixx="0.01" ixy="0.01" ixz="0.01" iyy="0.01" iyz="0.01" izz="0.01"/>
    </inertial>
    <visual>
      <origin rpy="0 0 0" xyz="0 0 0"/>
      <geometry>
        <sphere radius="0.005"/>
      </geometry>
      <material name="rviztulip_description/tulip_black">
        <color rgba="0.1 0.1 0.1 1"/>
      </material>
    </visual>
    <collision>
      <origin rpy="0 0 0" xyz="0 0 0"/>
      <geometry>
        <sphere radius="0.005"/>
      </geometry>
      <contact_coefficient k_d="0" k_p="0" mu="0" resitution="0"/>
    </collision>
  </link>
  <gazebo reference="right_toe_outer_foot_sensor">
    <material>tulip_description/tulip_black</material>
    <!-- materials specified in folder Media/materials/scripts/tulip_description.material -->
    <turnGravityOff>false</turnGravityOff>
    <selfCollide>false</selfCollide>
  </gazebo>
  <joint name="right_toe_outer_footsensfix" type="fixed">
    <parent link="right_foot"/>
    <child link="right_toe_outer_foot_sensor"/>
    <origin rpy="0 0 0" xyz="0.1615 -0.0735 -0.037"/>
  </joint>
  <gazebo reference="right_toe_outer_foot_sensor">
    <selfCollide>false</selfCollide>
    <material value="tulip_description/tulip_black"/>
    <sensor:contact name="right_toe_outer_foot_sensor">
      <geom>right_toe_outer_foot_sensor_geom</geom>
      <updateRate>1000.0</updateRate>
      <controller:gazebo_ros_bumper name="right_toe_outer_foot_sensor_controller" plugin="libgazebo_ros_bumper.so">
        <alwaysOn>true</alwaysOn>
        <updateRate>1000.0</updateRate>
        <bumperTopicName>right_toe_outer_foot_sensor</bumperTopicName>
        <frameName>right_toe_outer_foot_sensor</frameName>
        <interface:bumper name="right_toe_outer_foot_sensor_iface"/>
      </controller:gazebo_ros_bumper>
    </sensor:contact>
  </gazebo>
  <!-- prf=prefix, rfl=reflect -->
  <link name="right_toe_inner_foot_sensor">
    <inertial>
      <origin rpy="0 0 0" xyz="0 0 0"/>
      <mass value="0.01"/>
      <inertia ixx="0.01" ixy="0.01" ixz="0.01" iyy="0.01" iyz="0.01" izz="0.01"/>
    </inertial>
    <visual>
      <origin rpy="0 0 0" xyz="0 0 0"/>
      <geometry>
        <sphere radius="0.005"/>
      </geometry>
      <material name="rviztulip_description/tulip_black">
        <color rgba="0.1 0.1 0.1 1"/>
      </material>
    </visual>
    <collision>
      <origin rpy="0 0 0" xyz="0 0 0"/>
      <geometry>
        <sphere radius="0.005"/>
      </geometry>
      <contact_coefficient k_d="0" k_p="0" mu="0" resitution="0"/>
    </collision>
  </link>
  <gazebo reference="right_toe_inner_foot_sensor">
    <material>tulip_description/tulip_black</material>
    <!-- materials specified in folder Media/materials/scripts/tulip_description.material -->
    <turnGravityOff>false</turnGravityOff>
    <selfCollide>false</selfCollide>
  </gazebo>
  <joint name="right_toe_inner_footsensfix" type="fixed">
    <parent link="right_foot"/>
    <child link="right_toe_inner_foot_sensor"/>
    <origin rpy="0 0 0" xyz="0.1615 0.0485 -0.037"/>
  </joint>
  <gazebo reference="right_toe_inner_foot_sensor">
    <selfCollide>false</selfCollide>
    <material value="tulip_description/tulip_black"/>
    <sensor:contact name="right_toe_inner_foot_sensor">
      <geom>right_toe_inner_foot_sensor_geom</geom>
      <updateRate>1000.0</updateRate>
      <controller:gazebo_ros_bumper name="right_toe_inner_foot_sensor_controller" plugin="libgazebo_ros_bumper.so">
        <alwaysOn>true</alwaysOn>
        <updateRate>1000.0</updateRate>
        <bumperTopicName>right_toe_inner_foot_sensor</bumperTopicName>
        <frameName>right_toe_inner_foot_sensor</frameName>
        <interface:bumper name="right_toe_inner_foot_sensor_iface"/>
      </controller:gazebo_ros_bumper>
    </sensor:contact>
  </gazebo>
  <!-- prf=prefix, rfl=reflect -->
  <link name="right_heel_inner_foot_sensor">
    <inertial>
      <origin rpy="0 0 0" xyz="0 0 0"/>
      <mass value="0.01"/>
      <inertia ixx="0.01" ixy="0.01" ixz="0.01" iyy="0.01" iyz="0.01" izz="0.01"/>
    </inertial>
    <visual>
      <origin rpy="0 0 0" xyz="0 0 0"/>
      <geometry>
        <sphere radius="0.005"/>
      </geometry>
      <material name="rviztulip_description/tulip_black">
        <color rgba="0.1 0.1 0.1 1"/>
      </material>
    </visual>
    <collision>
      <origin rpy="0 0 0" xyz="0 0 0"/>
      <geometry>
        <sphere radius="0.005"/>
      </geometry>
      <contact_coefficient k_d="0" k_p="0" mu="0" resitution="0"/>
    </collision>
  </link>
  <gazebo reference="right_heel_inner_foot_sensor">
    <material>tulip_description/tulip_black</material>
    <!-- materials specified in folder Media/materials/scripts/tulip_description.material -->
    <turnGravityOff>false</turnGravityOff>
    <selfCollide>false</selfCollide>
  </gazebo>
  <joint name="right_heel_inner_footsensfix" type="fixed">
    <parent link="right_foot"/>
    <child link="right_heel_inner_foot_sensor"/>
    <origin rpy="0 0 0" xyz="-0.0455 0.0485 -0.037"/>
  </joint>
  <gazebo reference="right_heel_inner_foot_sensor">
    <selfCollide>false</selfCollide>
    <material value="tulip_description/tulip_black"/>
    <sensor:contact name="right_heel_inner_foot_sensor">
      <geom>right_heel_inner_foot_sensor_geom</geom>
      <updateRate>1000.0</updateRate>
      <controller:gazebo_ros_bumper name="right_heel_inner_foot_sensor_controller" plugin="libgazebo_ros_bumper.so">
        <alwaysOn>true</alwaysOn>
        <updateRate>1000.0</updateRate>
        <bumperTopicName>right_heel_inner_foot_sensor</bumperTopicName>
        <frameName>right_heel_inner_foot_sensor</frameName>
        <interface:bumper name="right_heel_inner_foot_sensor_iface"/>
      </controller:gazebo_ros_bumper>
    </sensor:contact>
  </gazebo>
  <!-- prf=prefix, rfl=reflect -->
  <link name="right_heel_outer_foot_sensor">
    <inertial>
      <origin rpy="0 0 0" xyz="0 0 0"/>
      <mass value="0.01"/>
      <inertia ixx="0.01" ixy="0.01" ixz="0.01" iyy="0.01" iyz="0.01" izz="0.01"/>
    </inertial>
    <visual>
      <origin rpy="0 0 0" xyz="0 0 0"/>
      <geometry>
        <sphere radius="0.005"/>
      </geometry>
      <material name="rviztulip_description/tulip_black">
        <color rgba="0.1 0.1 0.1 1"/>
      </material>
    </visual>
    <collision>
      <origin rpy="0 0 0" xyz="0 0 0"/>
      <geometry>
        <sphere radius="0.005"/>
      </geometry>
      <contact_coefficient k_d="0" k_p="0" mu="0" resitution="0"/>
    </collision>
  </link>
  <gazebo reference="right_heel_outer_foot_sensor">
    <material>tulip_description/tulip_black</material>
    <!-- materials specified in folder Media/materials/scripts/tulip_description.material -->
    <turnGravityOff>false</turnGravityOff>
    <selfCollide>false</selfCollide>
  </gazebo>
  <joint name="right_heel_outer_footsensfix" type="fixed">
    <parent link="right_foot"/>
    <child link="right_heel_outer_foot_sensor"/>
    <origin rpy="0 0 0" xyz="-0.0455 -0.0735 -0.037"/>
  </joint>
  <gazebo reference="right_heel_outer_foot_sensor">
    <selfCollide>false</selfCollide>
    <material value="tulip_description/tulip_black"/>
    <sensor:contact name="right_heel_outer_foot_sensor">
      <geom>right_heel_outer_foot_sensor_geom</geom>
      <updateRate>1000.0</updateRate>
      <controller:gazebo_ros_bumper name="right_heel_outer_foot_sensor_controller" plugin="libgazebo_ros_bumper.so">
        <alwaysOn>true</alwaysOn>
        <updateRate>1000.0</updateRate>
        <bumperTopicName>right_heel_outer_foot_sensor</bumperTopicName>
        <frameName>right_heel_outer_foot_sensor</frameName>
        <interface:bumper name="right_heel_outer_foot_sensor_iface"/>
      </controller:gazebo_ros_bumper>
    </sensor:contact>
  </gazebo>
</robot>
